2017-03-23 19:58:33,984 INFO org.apache.hadoop.yarn.server.resourcemanager.ResourceManager: STARTUP_MSG: 
/************************************************************
STARTUP_MSG: Starting ResourceManager
STARTUP_MSG:   host = 240008d2487e/172.18.0.2
STARTUP_MSG:   args = []
STARTUP_MSG:   version = 2.7.1
STARTUP_MSG:   build = https://git-wip-us.apache.org/repos/asf/hadoop.git -r 15ecc87ccf4a0228f35af08fc56de536e6ce657a; compiled by 'jenkins' on 2015-06-29T06:04Z
STARTUP_MSG:   java = 1.7.0_71
************************************************************/
2017-03-23 19:58:33,996 INFO org.apache.hadoop.yarn.server.resourcemanager.ResourceManager: registered UNIX signal handlers for [TERM, HUP, INT]
2017-03-23 19:58:34,457 INFO org.apache.hadoop.conf.Configuration: found resource core-site.xml at file:/usr/local/hadoop-2.7.1/etc/hadoop/core-site.xml
2017-03-23 19:58:34,622 WARN org.apache.hadoop.util.NativeCodeLoader: Unable to load native-hadoop library for your platform... using builtin-java classes where applicable
2017-03-23 19:58:34,668 INFO org.apache.hadoop.security.Groups: clearing userToGroupsMap cache
2017-03-23 19:58:34,793 INFO org.apache.hadoop.conf.Configuration: found resource yarn-site.xml at file:/usr/local/hadoop-2.7.1/etc/hadoop/yarn-site.xml
2017-03-23 19:58:35,080 INFO org.apache.hadoop.yarn.event.AsyncDispatcher: Registering class org.apache.hadoop.yarn.server.resourcemanager.RMFatalEventType for class org.apache.hadoop.yarn.server.resourcemanager.ResourceManager$RMFatalEventDispatcher
2017-03-23 19:58:35,332 INFO org.apache.hadoop.yarn.server.resourcemanager.security.NMTokenSecretManagerInRM: NMTokenKeyRollingInterval: 86400000ms and NMTokenKeyActivationDelay: 900000ms
2017-03-23 19:58:35,337 INFO org.apache.hadoop.yarn.server.resourcemanager.security.RMContainerTokenSecretManager: ContainerTokenKeyRollingInterval: 86400000ms and ContainerTokenKeyActivationDelay: 900000ms
2017-03-23 19:58:35,342 INFO org.apache.hadoop.yarn.server.resourcemanager.security.AMRMTokenSecretManager: AMRMTokenKeyRollingInterval: 86400000ms and AMRMTokenKeyActivationDelay: 900000 ms
2017-03-23 19:58:35,381 INFO org.apache.hadoop.yarn.event.AsyncDispatcher: Registering class org.apache.hadoop.yarn.server.resourcemanager.recovery.RMStateStoreEventType for class org.apache.hadoop.yarn.server.resourcemanager.recovery.RMStateStore$ForwardingEventHandler
2017-03-23 19:58:35,387 INFO org.apache.hadoop.yarn.event.AsyncDispatcher: Registering class org.apache.hadoop.yarn.server.resourcemanager.NodesListManagerEventType for class org.apache.hadoop.yarn.server.resourcemanager.NodesListManager
2017-03-23 19:58:35,387 INFO org.apache.hadoop.yarn.server.resourcemanager.ResourceManager: Using Scheduler: org.apache.hadoop.yarn.server.resourcemanager.scheduler.capacity.CapacityScheduler
2017-03-23 19:58:35,409 INFO org.apache.hadoop.yarn.event.AsyncDispatcher: Registering class org.apache.hadoop.yarn.server.resourcemanager.scheduler.event.SchedulerEventType for class org.apache.hadoop.yarn.server.resourcemanager.ResourceManager$SchedulerEventDispatcher
2017-03-23 19:58:35,410 INFO org.apache.hadoop.yarn.event.AsyncDispatcher: Registering class org.apache.hadoop.yarn.server.resourcemanager.rmapp.RMAppEventType for class org.apache.hadoop.yarn.server.resourcemanager.ResourceManager$ApplicationEventDispatcher
2017-03-23 19:58:35,411 INFO org.apache.hadoop.yarn.event.AsyncDispatcher: Registering class org.apache.hadoop.yarn.server.resourcemanager.rmapp.attempt.RMAppAttemptEventType for class org.apache.hadoop.yarn.server.resourcemanager.ResourceManager$ApplicationAttemptEventDispatcher
2017-03-23 19:58:35,412 INFO org.apache.hadoop.yarn.event.AsyncDispatcher: Registering class org.apache.hadoop.yarn.server.resourcemanager.rmnode.RMNodeEventType for class org.apache.hadoop.yarn.server.resourcemanager.ResourceManager$NodeEventDispatcher
2017-03-23 19:58:35,499 INFO org.apache.hadoop.metrics2.impl.MetricsConfig: loaded properties from hadoop-metrics2.properties
2017-03-23 19:58:35,580 INFO org.apache.hadoop.metrics2.impl.MetricsSystemImpl: Scheduled snapshot period at 10 second(s).
2017-03-23 19:58:35,580 INFO org.apache.hadoop.metrics2.impl.MetricsSystemImpl: ResourceManager metrics system started
2017-03-23 19:58:35,601 INFO org.apache.hadoop.yarn.event.AsyncDispatcher: Registering class org.apache.hadoop.yarn.server.resourcemanager.RMAppManagerEventType for class org.apache.hadoop.yarn.server.resourcemanager.RMAppManager
2017-03-23 19:58:35,613 INFO org.apache.hadoop.yarn.event.AsyncDispatcher: Registering class org.apache.hadoop.yarn.server.resourcemanager.amlauncher.AMLauncherEventType for class org.apache.hadoop.yarn.server.resourcemanager.amlauncher.ApplicationMasterLauncher
2017-03-23 19:58:35,617 INFO org.apache.hadoop.yarn.server.resourcemanager.RMNMInfo: Registered RMNMInfo MBean
2017-03-23 19:58:35,620 INFO org.apache.hadoop.yarn.security.YarnAuthorizationProvider: org.apache.hadoop.yarn.security.ConfiguredYarnAuthorizer is instiantiated.
2017-03-23 19:58:35,621 INFO org.apache.hadoop.yarn.server.resourcemanager.metrics.SystemMetricsPublisher: YARN system metrics publishing service is not enabled
2017-03-23 19:58:35,622 INFO org.apache.hadoop.util.HostsFileReader: Refreshing hosts (include/exclude) list
2017-03-23 19:58:35,628 INFO org.apache.hadoop.conf.Configuration: found resource capacity-scheduler.xml at file:/usr/local/hadoop-2.7.1/etc/hadoop/capacity-scheduler.xml
2017-03-23 19:58:35,717 INFO org.apache.hadoop.yarn.server.resourcemanager.scheduler.capacity.CapacitySchedulerConfiguration: max alloc mb per queue for root is undefined
2017-03-23 19:58:35,717 INFO org.apache.hadoop.yarn.server.resourcemanager.scheduler.capacity.CapacitySchedulerConfiguration: max alloc vcore per queue for root is undefined
2017-03-23 19:58:35,725 INFO org.apache.hadoop.yarn.server.resourcemanager.scheduler.capacity.ParentQueue: root, capacity=1.0, asboluteCapacity=1.0, maxCapacity=1.0, asboluteMaxCapacity=1.0, state=RUNNING, acls=ADMINISTER_QUEUE:*SUBMIT_APP:*, labels=*,
, reservationsContinueLooking=true
2017-03-23 19:58:35,725 INFO org.apache.hadoop.yarn.server.resourcemanager.scheduler.capacity.ParentQueue: Initialized parent-queue root name=root, fullname=root
2017-03-23 19:58:35,743 INFO org.apache.hadoop.yarn.server.resourcemanager.scheduler.capacity.CapacitySchedulerConfiguration: max alloc mb per queue for root.default is undefined
2017-03-23 19:58:35,743 INFO org.apache.hadoop.yarn.server.resourcemanager.scheduler.capacity.CapacitySchedulerConfiguration: max alloc vcore per queue for root.default is undefined
2017-03-23 19:58:35,745 INFO org.apache.hadoop.yarn.server.resourcemanager.scheduler.capacity.LeafQueue: Initializing default
capacity = 1.0 [= (float) configuredCapacity / 100 ]
asboluteCapacity = 1.0 [= parentAbsoluteCapacity * capacity ]
maxCapacity = 1.0 [= configuredMaxCapacity ]
absoluteMaxCapacity = 1.0 [= 1.0 maximumCapacity undefined, (parentAbsoluteMaxCapacity * maximumCapacity) / 100 otherwise ]
userLimit = 100 [= configuredUserLimit ]
userLimitFactor = 1.0 [= configuredUserLimitFactor ]
maxApplications = 10000 [= configuredMaximumSystemApplicationsPerQueue or (int)(configuredMaximumSystemApplications * absoluteCapacity)]
maxApplicationsPerUser = 10000 [= (int)(maxApplications * (userLimit / 100.0f) * userLimitFactor) ]
usedCapacity = 0.0 [= usedResourcesMemory / (clusterResourceMemory * absoluteCapacity)]
absoluteUsedCapacity = 0.0 [= usedResourcesMemory / clusterResourceMemory]
maxAMResourcePerQueuePercent = 0.1 [= configuredMaximumAMResourcePercent ]
minimumAllocationFactor = 0.875 [= (float)(maximumAllocationMemory - minimumAllocationMemory) / maximumAllocationMemory ]
maximumAllocation = <memory:8192, vCores:32> [= configuredMaxAllocation ]
numContainers = 0 [= currentNumContainers ]
state = RUNNING [= configuredState ]
acls = ADMINISTER_QUEUE:*SUBMIT_APP:* [= configuredAcls ]
nodeLocalityDelay = 40
labels=*,
nodeLocalityDelay = 40
reservationsContinueLooking = true
preemptionDisabled = true

2017-03-23 19:58:35,745 INFO org.apache.hadoop.yarn.server.resourcemanager.scheduler.capacity.CapacityScheduler: Initialized queue: default: capacity=1.0, absoluteCapacity=1.0, usedResources=<memory:0, vCores:0>, usedCapacity=0.0, absoluteUsedCapacity=0.0, numApps=0, numContainers=0
2017-03-23 19:58:35,745 INFO org.apache.hadoop.yarn.server.resourcemanager.scheduler.capacity.CapacityScheduler: Initialized queue: root: numChildQueue= 1, capacity=1.0, absoluteCapacity=1.0, usedResources=<memory:0, vCores:0>usedCapacity=0.0, numApps=0, numContainers=0
2017-03-23 19:58:35,746 INFO org.apache.hadoop.yarn.server.resourcemanager.scheduler.capacity.CapacityScheduler: Initialized root queue root: numChildQueue= 1, capacity=1.0, absoluteCapacity=1.0, usedResources=<memory:0, vCores:0>usedCapacity=0.0, numApps=0, numContainers=0
2017-03-23 19:58:35,746 INFO org.apache.hadoop.yarn.server.resourcemanager.scheduler.capacity.CapacityScheduler: Initialized queue mappings, override: false
2017-03-23 19:58:35,747 INFO org.apache.hadoop.yarn.server.resourcemanager.scheduler.capacity.CapacityScheduler: Initialized CapacityScheduler with calculator=class org.apache.hadoop.yarn.util.resource.DefaultResourceCalculator, minimumAllocation=<<memory:1024, vCores:1>>, maximumAllocation=<<memory:8192, vCores:32>>, asynchronousScheduling=false, asyncScheduleInterval=5ms
2017-03-23 19:58:35,758 INFO org.apache.hadoop.yarn.server.resourcemanager.ResourceManager: Transitioning to active state
2017-03-23 19:58:35,803 INFO org.apache.hadoop.yarn.server.resourcemanager.recovery.RMStateStore: Updating AMRMToken
2017-03-23 19:58:35,803 INFO org.apache.hadoop.yarn.server.resourcemanager.security.RMContainerTokenSecretManager: Rolling master-key for container-tokens
2017-03-23 19:58:35,803 INFO org.apache.hadoop.yarn.server.resourcemanager.security.NMTokenSecretManagerInRM: Rolling master-key for nm-tokens
2017-03-23 19:58:35,804 INFO org.apache.hadoop.security.token.delegation.AbstractDelegationTokenSecretManager: Updating the current master key for generating delegation tokens
2017-03-23 19:58:35,804 INFO org.apache.hadoop.yarn.server.resourcemanager.security.RMDelegationTokenSecretManager: storing master key with keyID 1
2017-03-23 19:58:35,805 INFO org.apache.hadoop.yarn.server.resourcemanager.recovery.RMStateStore: Storing RMDTMasterKey.
2017-03-23 19:58:35,806 INFO org.apache.hadoop.security.token.delegation.AbstractDelegationTokenSecretManager: Starting expired delegation token remover thread, tokenRemoverScanInterval=60 min(s)
2017-03-23 19:58:35,806 INFO org.apache.hadoop.security.token.delegation.AbstractDelegationTokenSecretManager: Updating the current master key for generating delegation tokens
2017-03-23 19:58:35,806 INFO org.apache.hadoop.yarn.server.resourcemanager.security.RMDelegationTokenSecretManager: storing master key with keyID 2
2017-03-23 19:58:35,806 INFO org.apache.hadoop.yarn.server.resourcemanager.recovery.RMStateStore: Storing RMDTMasterKey.
2017-03-23 19:58:35,809 INFO org.apache.hadoop.yarn.event.AsyncDispatcher: Registering class org.apache.hadoop.yarn.nodelabels.event.NodeLabelsStoreEventType for class org.apache.hadoop.yarn.nodelabels.CommonNodeLabelsManager$ForwardingEventHandler
2017-03-23 19:58:35,849 INFO org.apache.hadoop.ipc.CallQueueManager: Using callQueue class java.util.concurrent.LinkedBlockingQueue
2017-03-23 19:58:35,865 INFO org.apache.hadoop.ipc.Server: Starting Socket Reader #1 for port 8031
2017-03-23 19:58:35,888 INFO org.apache.hadoop.yarn.factories.impl.pb.RpcServerFactoryPBImpl: Adding protocol org.apache.hadoop.yarn.server.api.ResourceTrackerPB to the server
2017-03-23 19:58:35,889 INFO org.apache.hadoop.ipc.Server: IPC Server Responder: starting
2017-03-23 19:58:35,889 INFO org.apache.hadoop.ipc.Server: IPC Server listener on 8031: starting
2017-03-23 19:58:35,918 INFO org.apache.hadoop.ipc.CallQueueManager: Using callQueue class java.util.concurrent.LinkedBlockingQueue
2017-03-23 19:58:35,929 INFO org.apache.hadoop.ipc.Server: Starting Socket Reader #1 for port 8030
2017-03-23 19:58:35,944 INFO org.apache.hadoop.yarn.factories.impl.pb.RpcServerFactoryPBImpl: Adding protocol org.apache.hadoop.yarn.api.ApplicationMasterProtocolPB to the server
2017-03-23 19:58:35,945 INFO org.apache.hadoop.ipc.Server: IPC Server Responder: starting
2017-03-23 19:58:35,945 INFO org.apache.hadoop.ipc.Server: IPC Server listener on 8030: starting
2017-03-23 19:58:36,047 INFO org.apache.hadoop.ipc.CallQueueManager: Using callQueue class java.util.concurrent.LinkedBlockingQueue
2017-03-23 19:58:36,048 INFO org.apache.hadoop.ipc.Server: Starting Socket Reader #1 for port 8032
2017-03-23 19:58:36,053 INFO org.apache.hadoop.yarn.factories.impl.pb.RpcServerFactoryPBImpl: Adding protocol org.apache.hadoop.yarn.api.ApplicationClientProtocolPB to the server
2017-03-23 19:58:36,054 INFO org.apache.hadoop.ipc.Server: IPC Server Responder: starting
2017-03-23 19:58:36,054 INFO org.apache.hadoop.ipc.Server: IPC Server listener on 8032: starting
2017-03-23 19:58:36,062 INFO org.apache.hadoop.yarn.server.resourcemanager.ResourceManager: Transitioned to active state
2017-03-23 19:58:36,174 INFO org.mortbay.log: Logging to org.slf4j.impl.Log4jLoggerAdapter(org.mortbay.log) via org.mortbay.log.Slf4jLog
2017-03-23 19:58:36,184 INFO org.apache.hadoop.security.authentication.server.AuthenticationFilter: Unable to initialize FileSignerSecretProvider, falling back to use random secrets.
2017-03-23 19:58:36,192 INFO org.apache.hadoop.http.HttpRequestLog: Http request log for http.requests.resourcemanager is not defined
2017-03-23 19:58:36,203 INFO org.apache.hadoop.http.HttpServer2: Added global filter 'safety' (class=org.apache.hadoop.http.HttpServer2$QuotingInputFilter)
2017-03-23 19:58:36,209 INFO org.apache.hadoop.http.HttpServer2: Added filter RMAuthenticationFilter (class=org.apache.hadoop.yarn.server.security.http.RMAuthenticationFilter) to context cluster
2017-03-23 19:58:36,209 INFO org.apache.hadoop.http.HttpServer2: Added filter RMAuthenticationFilter (class=org.apache.hadoop.yarn.server.security.http.RMAuthenticationFilter) to context static
2017-03-23 19:58:36,209 INFO org.apache.hadoop.http.HttpServer2: Added filter RMAuthenticationFilter (class=org.apache.hadoop.yarn.server.security.http.RMAuthenticationFilter) to context logs
2017-03-23 19:58:36,210 INFO org.apache.hadoop.http.HttpServer2: Added filter static_user_filter (class=org.apache.hadoop.http.lib.StaticUserWebFilter$StaticUserFilter) to context cluster
2017-03-23 19:58:36,210 INFO org.apache.hadoop.http.HttpServer2: Added filter static_user_filter (class=org.apache.hadoop.http.lib.StaticUserWebFilter$StaticUserFilter) to context static
2017-03-23 19:58:36,210 INFO org.apache.hadoop.http.HttpServer2: Added filter static_user_filter (class=org.apache.hadoop.http.lib.StaticUserWebFilter$StaticUserFilter) to context logs
2017-03-23 19:58:36,215 INFO org.apache.hadoop.http.HttpServer2: adding path spec: /cluster/*
2017-03-23 19:58:36,216 INFO org.apache.hadoop.http.HttpServer2: adding path spec: /ws/*
2017-03-23 19:58:36,229 INFO org.apache.hadoop.http.HttpServer2: Jetty bound to port 8088
2017-03-23 19:58:36,229 INFO org.mortbay.log: jetty-6.1.26
2017-03-23 19:58:36,268 INFO org.mortbay.log: Extract jar:file:/usr/local/hadoop-2.7.1/share/hadoop/yarn/hadoop-yarn-common-2.7.1.jar!/webapps/cluster to /tmp/Jetty_0_0_0_0_8088_cluster____u0rgz3/webapp
2017-03-23 19:58:36,578 INFO org.apache.hadoop.security.token.delegation.AbstractDelegationTokenSecretManager: Updating the current master key for generating delegation tokens
2017-03-23 19:58:36,579 INFO org.apache.hadoop.security.token.delegation.AbstractDelegationTokenSecretManager: Starting expired delegation token remover thread, tokenRemoverScanInterval=60 min(s)
2017-03-23 19:58:36,579 INFO org.apache.hadoop.security.token.delegation.AbstractDelegationTokenSecretManager: Updating the current master key for generating delegation tokens
2017-03-23 19:58:36,590 INFO org.mortbay.log: Started HttpServer2$SelectChannelConnectorWithSafeStartup@0.0.0.0:8088
2017-03-23 19:58:36,591 INFO org.apache.hadoop.yarn.webapp.WebApps: Web app /cluster started at 8088
2017-03-23 19:58:37,099 INFO org.apache.hadoop.yarn.webapp.WebApps: Registered webapp guice modules
2017-03-23 19:58:37,133 INFO org.apache.hadoop.ipc.CallQueueManager: Using callQueue class java.util.concurrent.LinkedBlockingQueue
2017-03-23 19:58:37,134 INFO org.apache.hadoop.ipc.Server: Starting Socket Reader #1 for port 8033
2017-03-23 19:58:37,138 INFO org.apache.hadoop.yarn.factories.impl.pb.RpcServerFactoryPBImpl: Adding protocol org.apache.hadoop.yarn.server.api.ResourceManagerAdministrationProtocolPB to the server
2017-03-23 19:58:37,138 INFO org.apache.hadoop.ipc.Server: IPC Server Responder: starting
2017-03-23 19:58:37,139 INFO org.apache.hadoop.ipc.Server: IPC Server listener on 8033: starting
2017-03-23 19:58:38,530 INFO org.apache.hadoop.yarn.util.RackResolver: Resolved 240008d2487e to /default-rack
2017-03-23 19:58:38,533 INFO org.apache.hadoop.yarn.server.resourcemanager.ResourceTrackerService: NodeManager from node 240008d2487e(cmPort: 44869 httpPort: 8042) registered with capability: <memory:8192, vCores:8>, assigned nodeId 240008d2487e:44869
2017-03-23 19:58:38,536 INFO org.apache.hadoop.yarn.server.resourcemanager.rmnode.RMNodeImpl: 240008d2487e:44869 Node Transitioned from NEW to RUNNING
2017-03-23 19:58:38,542 INFO org.apache.hadoop.yarn.server.resourcemanager.scheduler.capacity.CapacityScheduler: Added node 240008d2487e:44869 clusterResource: <memory:8192, vCores:8>
2017-03-23 20:08:35,628 INFO org.apache.hadoop.yarn.server.resourcemanager.scheduler.AbstractYarnScheduler: Release request cache is cleaned up
2017-03-23 20:13:33,107 INFO org.apache.hadoop.yarn.server.resourcemanager.ClientRMService: Allocated new applicationId: 1
2017-03-23 20:15:05,641 INFO org.apache.hadoop.yarn.server.resourcemanager.ClientRMService: Allocated new applicationId: 2
2017-03-23 20:15:07,249 INFO org.apache.hadoop.yarn.server.resourcemanager.ClientRMService: Application with id 2 submitted by user root
2017-03-23 20:15:07,249 INFO org.apache.hadoop.yarn.server.resourcemanager.rmapp.RMAppImpl: Storing application with id application_1490313515759_0002
2017-03-23 20:15:07,251 INFO org.apache.hadoop.yarn.server.resourcemanager.RMAuditLogger: USER=root	IP=172.18.0.2	OPERATION=Submit Application Request	TARGET=ClientRMService	RESULT=SUCCESS	APPID=application_1490313515759_0002
2017-03-23 20:15:07,264 INFO org.apache.hadoop.yarn.server.resourcemanager.rmapp.RMAppImpl: application_1490313515759_0002 State change from NEW to NEW_SAVING
2017-03-23 20:15:07,264 INFO org.apache.hadoop.yarn.server.resourcemanager.recovery.RMStateStore: Storing info for app: application_1490313515759_0002
2017-03-23 20:15:07,265 INFO org.apache.hadoop.yarn.server.resourcemanager.rmapp.RMAppImpl: application_1490313515759_0002 State change from NEW_SAVING to SUBMITTED
2017-03-23 20:15:07,267 INFO org.apache.hadoop.yarn.server.resourcemanager.scheduler.capacity.ParentQueue: Application added - appId: application_1490313515759_0002 user: root leaf-queue of parent: root #applications: 1
2017-03-23 20:15:07,268 INFO org.apache.hadoop.yarn.server.resourcemanager.scheduler.capacity.CapacityScheduler: Accepted application application_1490313515759_0002 from user: root, in queue: default
2017-03-23 20:15:07,279 INFO org.apache.hadoop.yarn.server.resourcemanager.rmapp.RMAppImpl: application_1490313515759_0002 State change from SUBMITTED to ACCEPTED
2017-03-23 20:15:07,316 INFO org.apache.hadoop.yarn.server.resourcemanager.ApplicationMasterService: Registering app attempt : appattempt_1490313515759_0002_000001
2017-03-23 20:15:07,317 INFO org.apache.hadoop.yarn.server.resourcemanager.rmapp.attempt.RMAppAttemptImpl: appattempt_1490313515759_0002_000001 State change from NEW to SUBMITTED
2017-03-23 20:15:07,333 WARN org.apache.hadoop.yarn.server.resourcemanager.scheduler.capacity.LeafQueue: maximum-am-resource-percent is insufficient to start a single application in queue, it is likely set too low. skipping enforcement to allow at least one application to start
2017-03-23 20:15:07,333 WARN org.apache.hadoop.yarn.server.resourcemanager.scheduler.capacity.LeafQueue: maximum-am-resource-percent is insufficient to start a single application in queue for user, it is likely set too low. skipping enforcement to allow at least one application to start
2017-03-23 20:15:07,333 INFO org.apache.hadoop.yarn.server.resourcemanager.scheduler.capacity.LeafQueue: Application application_1490313515759_0002 from user: root activated in queue: default
2017-03-23 20:15:07,333 INFO org.apache.hadoop.yarn.server.resourcemanager.scheduler.capacity.LeafQueue: Application added - appId: application_1490313515759_0002 user: org.apache.hadoop.yarn.server.resourcemanager.scheduler.capacity.LeafQueue$User@3da0b822, leaf-queue: default #user-pending-applications: 0 #user-active-applications: 1 #queue-pending-applications: 0 #queue-active-applications: 1
2017-03-23 20:15:07,334 INFO org.apache.hadoop.yarn.server.resourcemanager.scheduler.capacity.CapacityScheduler: Added Application Attempt appattempt_1490313515759_0002_000001 to scheduler from user root in queue default
2017-03-23 20:15:07,337 INFO org.apache.hadoop.yarn.server.resourcemanager.rmapp.attempt.RMAppAttemptImpl: appattempt_1490313515759_0002_000001 State change from SUBMITTED to SCHEDULED
2017-03-23 20:15:08,351 INFO org.apache.hadoop.yarn.server.resourcemanager.rmcontainer.RMContainerImpl: container_1490313515759_0002_01_000001 Container Transitioned from NEW to ALLOCATED
2017-03-23 20:15:08,351 INFO org.apache.hadoop.yarn.server.resourcemanager.RMAuditLogger: USER=root	OPERATION=AM Allocated Container	TARGET=SchedulerApp	RESULT=SUCCESS	APPID=application_1490313515759_0002	CONTAINERID=container_1490313515759_0002_01_000001
2017-03-23 20:15:08,352 INFO org.apache.hadoop.yarn.server.resourcemanager.scheduler.SchedulerNode: Assigned container container_1490313515759_0002_01_000001 of capacity <memory:2048, vCores:1> on host 240008d2487e:44869, which has 1 containers, <memory:2048, vCores:1> used and <memory:6144, vCores:7> available after allocation
2017-03-23 20:15:08,353 INFO org.apache.hadoop.yarn.server.resourcemanager.scheduler.capacity.LeafQueue: assignedContainer application attempt=appattempt_1490313515759_0002_000001 container=Container: [ContainerId: container_1490313515759_0002_01_000001, NodeId: 240008d2487e:44869, NodeHttpAddress: 240008d2487e:8042, Resource: <memory:2048, vCores:1>, Priority: 0, Token: null, ] queue=default: capacity=1.0, absoluteCapacity=1.0, usedResources=<memory:0, vCores:0>, usedCapacity=0.0, absoluteUsedCapacity=0.0, numApps=1, numContainers=0 clusterResource=<memory:8192, vCores:8>
2017-03-23 20:15:08,353 INFO org.apache.hadoop.yarn.server.resourcemanager.scheduler.capacity.ParentQueue: Re-sorting assigned queue: root.default stats: default: capacity=1.0, absoluteCapacity=1.0, usedResources=<memory:2048, vCores:1>, usedCapacity=0.25, absoluteUsedCapacity=0.25, numApps=1, numContainers=1
2017-03-23 20:15:08,353 INFO org.apache.hadoop.yarn.server.resourcemanager.scheduler.capacity.ParentQueue: assignedContainer queue=root usedCapacity=0.25 absoluteUsedCapacity=0.25 used=<memory:2048, vCores:1> cluster=<memory:8192, vCores:8>
2017-03-23 20:15:08,374 INFO org.apache.hadoop.yarn.server.resourcemanager.security.NMTokenSecretManagerInRM: Sending NMToken for nodeId : 240008d2487e:44869 for container : container_1490313515759_0002_01_000001
2017-03-23 20:15:08,387 INFO org.apache.hadoop.yarn.server.resourcemanager.rmcontainer.RMContainerImpl: container_1490313515759_0002_01_000001 Container Transitioned from ALLOCATED to ACQUIRED
2017-03-23 20:15:08,387 INFO org.apache.hadoop.yarn.server.resourcemanager.security.NMTokenSecretManagerInRM: Clear node set for appattempt_1490313515759_0002_000001
2017-03-23 20:15:08,391 INFO org.apache.hadoop.yarn.server.resourcemanager.rmapp.attempt.RMAppAttemptImpl: Storing attempt: AppId: application_1490313515759_0002 AttemptId: appattempt_1490313515759_0002_000001 MasterContainer: Container: [ContainerId: container_1490313515759_0002_01_000001, NodeId: 240008d2487e:44869, NodeHttpAddress: 240008d2487e:8042, Resource: <memory:2048, vCores:1>, Priority: 0, Token: Token { kind: ContainerToken, service: 172.18.0.2:44869 }, ]
2017-03-23 20:15:08,407 INFO org.apache.hadoop.yarn.server.resourcemanager.rmapp.attempt.RMAppAttemptImpl: appattempt_1490313515759_0002_000001 State change from SCHEDULED to ALLOCATED_SAVING
2017-03-23 20:15:08,408 INFO org.apache.hadoop.yarn.server.resourcemanager.rmapp.attempt.RMAppAttemptImpl: appattempt_1490313515759_0002_000001 State change from ALLOCATED_SAVING to ALLOCATED
2017-03-23 20:15:08,412 INFO org.apache.hadoop.yarn.server.resourcemanager.amlauncher.AMLauncher: Launching masterappattempt_1490313515759_0002_000001
2017-03-23 20:15:08,449 INFO org.apache.hadoop.yarn.server.resourcemanager.amlauncher.AMLauncher: Setting up container Container: [ContainerId: container_1490313515759_0002_01_000001, NodeId: 240008d2487e:44869, NodeHttpAddress: 240008d2487e:8042, Resource: <memory:2048, vCores:1>, Priority: 0, Token: Token { kind: ContainerToken, service: 172.18.0.2:44869 }, ] for AM appattempt_1490313515759_0002_000001
2017-03-23 20:15:08,450 INFO org.apache.hadoop.yarn.server.resourcemanager.amlauncher.AMLauncher: Command to launch container container_1490313515759_0002_01_000001 : $JAVA_HOME/bin/java -Dlog4j.configuration=container-log4j.properties -Dyarn.app.container.log.dir=<LOG_DIR> -Dyarn.app.container.log.filesize=0 -Dhadoop.root.logger=INFO,CLA -Dhadoop.root.logfile=syslog  -Xmx1024m org.apache.hadoop.mapreduce.v2.app.MRAppMaster 1><LOG_DIR>/stdout 2><LOG_DIR>/stderr 
2017-03-23 20:15:08,451 INFO org.apache.hadoop.yarn.server.resourcemanager.security.AMRMTokenSecretManager: Create AMRMToken for ApplicationAttempt: appattempt_1490313515759_0002_000001
2017-03-23 20:15:08,455 INFO org.apache.hadoop.yarn.server.resourcemanager.security.AMRMTokenSecretManager: Creating password for appattempt_1490313515759_0002_000001
2017-03-23 20:15:08,863 INFO org.apache.hadoop.yarn.server.resourcemanager.amlauncher.AMLauncher: Done launching container Container: [ContainerId: container_1490313515759_0002_01_000001, NodeId: 240008d2487e:44869, NodeHttpAddress: 240008d2487e:8042, Resource: <memory:2048, vCores:1>, Priority: 0, Token: Token { kind: ContainerToken, service: 172.18.0.2:44869 }, ] for AM appattempt_1490313515759_0002_000001
2017-03-23 20:15:08,863 INFO org.apache.hadoop.yarn.server.resourcemanager.rmapp.attempt.RMAppAttemptImpl: appattempt_1490313515759_0002_000001 State change from ALLOCATED to LAUNCHED
2017-03-23 20:15:09,336 INFO org.apache.hadoop.yarn.server.resourcemanager.rmcontainer.RMContainerImpl: container_1490313515759_0002_01_000001 Container Transitioned from ACQUIRED to RUNNING
2017-03-23 20:15:14,891 INFO SecurityLogger.org.apache.hadoop.ipc.Server: Auth successful for appattempt_1490313515759_0002_000001 (auth:SIMPLE)
2017-03-23 20:15:14,901 INFO org.apache.hadoop.yarn.server.resourcemanager.ApplicationMasterService: AM registration appattempt_1490313515759_0002_000001
2017-03-23 20:15:14,902 INFO org.apache.hadoop.yarn.server.resourcemanager.RMAuditLogger: USER=root	IP=172.18.0.2	OPERATION=Register App Master	TARGET=ApplicationMasterService	RESULT=SUCCESS	APPID=application_1490313515759_0002	APPATTEMPTID=appattempt_1490313515759_0002_000001
2017-03-23 20:15:14,902 INFO org.apache.hadoop.yarn.server.resourcemanager.rmapp.attempt.RMAppAttemptImpl: appattempt_1490313515759_0002_000001 State change from LAUNCHED to RUNNING
2017-03-23 20:15:14,902 INFO org.apache.hadoop.yarn.server.resourcemanager.rmapp.RMAppImpl: application_1490313515759_0002 State change from ACCEPTED to RUNNING
2017-03-23 20:15:16,355 INFO org.apache.hadoop.yarn.server.resourcemanager.rmcontainer.RMContainerImpl: container_1490313515759_0002_01_000002 Container Transitioned from NEW to ALLOCATED
2017-03-23 20:15:16,355 INFO org.apache.hadoop.yarn.server.resourcemanager.RMAuditLogger: USER=root	OPERATION=AM Allocated Container	TARGET=SchedulerApp	RESULT=SUCCESS	APPID=application_1490313515759_0002	CONTAINERID=container_1490313515759_0002_01_000002
2017-03-23 20:15:16,355 INFO org.apache.hadoop.yarn.server.resourcemanager.scheduler.SchedulerNode: Assigned container container_1490313515759_0002_01_000002 of capacity <memory:1024, vCores:1> on host 240008d2487e:44869, which has 2 containers, <memory:3072, vCores:2> used and <memory:5120, vCores:6> available after allocation
2017-03-23 20:15:16,356 INFO org.apache.hadoop.yarn.server.resourcemanager.scheduler.capacity.LeafQueue: assignedContainer application attempt=appattempt_1490313515759_0002_000001 container=Container: [ContainerId: container_1490313515759_0002_01_000002, NodeId: 240008d2487e:44869, NodeHttpAddress: 240008d2487e:8042, Resource: <memory:1024, vCores:1>, Priority: 20, Token: null, ] queue=default: capacity=1.0, absoluteCapacity=1.0, usedResources=<memory:2048, vCores:1>, usedCapacity=0.25, absoluteUsedCapacity=0.25, numApps=1, numContainers=1 clusterResource=<memory:8192, vCores:8>
2017-03-23 20:15:16,356 INFO org.apache.hadoop.yarn.server.resourcemanager.scheduler.capacity.ParentQueue: Re-sorting assigned queue: root.default stats: default: capacity=1.0, absoluteCapacity=1.0, usedResources=<memory:3072, vCores:2>, usedCapacity=0.375, absoluteUsedCapacity=0.375, numApps=1, numContainers=2
2017-03-23 20:15:16,356 INFO org.apache.hadoop.yarn.server.resourcemanager.scheduler.capacity.ParentQueue: assignedContainer queue=root usedCapacity=0.375 absoluteUsedCapacity=0.375 used=<memory:3072, vCores:2> cluster=<memory:8192, vCores:8>
2017-03-23 20:15:16,357 INFO org.apache.hadoop.yarn.server.resourcemanager.rmcontainer.RMContainerImpl: container_1490313515759_0002_01_000003 Container Transitioned from NEW to ALLOCATED
2017-03-23 20:15:16,357 INFO org.apache.hadoop.yarn.server.resourcemanager.RMAuditLogger: USER=root	OPERATION=AM Allocated Container	TARGET=SchedulerApp	RESULT=SUCCESS	APPID=application_1490313515759_0002	CONTAINERID=container_1490313515759_0002_01_000003
2017-03-23 20:15:16,357 INFO org.apache.hadoop.yarn.server.resourcemanager.scheduler.SchedulerNode: Assigned container container_1490313515759_0002_01_000003 of capacity <memory:1024, vCores:1> on host 240008d2487e:44869, which has 3 containers, <memory:4096, vCores:3> used and <memory:4096, vCores:5> available after allocation
2017-03-23 20:15:16,357 INFO org.apache.hadoop.yarn.server.resourcemanager.scheduler.capacity.LeafQueue: assignedContainer application attempt=appattempt_1490313515759_0002_000001 container=Container: [ContainerId: container_1490313515759_0002_01_000003, NodeId: 240008d2487e:44869, NodeHttpAddress: 240008d2487e:8042, Resource: <memory:1024, vCores:1>, Priority: 20, Token: null, ] queue=default: capacity=1.0, absoluteCapacity=1.0, usedResources=<memory:3072, vCores:2>, usedCapacity=0.375, absoluteUsedCapacity=0.375, numApps=1, numContainers=2 clusterResource=<memory:8192, vCores:8>
2017-03-23 20:15:16,357 INFO org.apache.hadoop.yarn.server.resourcemanager.scheduler.capacity.ParentQueue: Re-sorting assigned queue: root.default stats: default: capacity=1.0, absoluteCapacity=1.0, usedResources=<memory:4096, vCores:3>, usedCapacity=0.5, absoluteUsedCapacity=0.5, numApps=1, numContainers=3
2017-03-23 20:15:16,357 INFO org.apache.hadoop.yarn.server.resourcemanager.scheduler.capacity.ParentQueue: assignedContainer queue=root usedCapacity=0.5 absoluteUsedCapacity=0.5 used=<memory:4096, vCores:3> cluster=<memory:8192, vCores:8>
2017-03-23 20:15:17,026 INFO org.apache.hadoop.yarn.server.resourcemanager.security.NMTokenSecretManagerInRM: Sending NMToken for nodeId : 240008d2487e:44869 for container : container_1490313515759_0002_01_000002
2017-03-23 20:15:17,027 INFO org.apache.hadoop.yarn.server.resourcemanager.rmcontainer.RMContainerImpl: container_1490313515759_0002_01_000002 Container Transitioned from ALLOCATED to ACQUIRED
2017-03-23 20:15:17,029 INFO org.apache.hadoop.yarn.server.resourcemanager.rmcontainer.RMContainerImpl: container_1490313515759_0002_01_000003 Container Transitioned from ALLOCATED to ACQUIRED
2017-03-23 20:15:17,358 INFO org.apache.hadoop.yarn.server.resourcemanager.rmcontainer.RMContainerImpl: container_1490313515759_0002_01_000002 Container Transitioned from ACQUIRED to RUNNING
2017-03-23 20:15:17,358 INFO org.apache.hadoop.yarn.server.resourcemanager.rmcontainer.RMContainerImpl: container_1490313515759_0002_01_000003 Container Transitioned from ACQUIRED to RUNNING
2017-03-23 20:15:18,047 INFO org.apache.hadoop.yarn.server.resourcemanager.scheduler.AppSchedulingInfo: checking for deactivate of application :application_1490313515759_0002
2017-03-23 20:15:33,005 INFO org.apache.hadoop.yarn.server.resourcemanager.rmcontainer.RMContainerImpl: container_1490313515759_0002_01_000002 Container Transitioned from RUNNING to COMPLETED
2017-03-23 20:15:33,006 INFO org.apache.hadoop.yarn.server.resourcemanager.scheduler.common.fica.FiCaSchedulerApp: Completed container: container_1490313515759_0002_01_000002 in state: COMPLETED event:FINISHED
2017-03-23 20:15:33,006 INFO org.apache.hadoop.yarn.server.resourcemanager.RMAuditLogger: USER=root	OPERATION=AM Released Container	TARGET=SchedulerApp	RESULT=SUCCESS	APPID=application_1490313515759_0002	CONTAINERID=container_1490313515759_0002_01_000002
2017-03-23 20:15:33,006 INFO org.apache.hadoop.yarn.server.resourcemanager.scheduler.SchedulerNode: Released container container_1490313515759_0002_01_000002 of capacity <memory:1024, vCores:1> on host 240008d2487e:44869, which currently has 2 containers, <memory:3072, vCores:2> used and <memory:5120, vCores:6> available, release resources=true
2017-03-23 20:15:33,006 INFO org.apache.hadoop.yarn.server.resourcemanager.scheduler.capacity.LeafQueue: default used=<memory:3072, vCores:2> numContainers=2 user=root user-resources=<memory:3072, vCores:2>
2017-03-23 20:15:33,007 INFO org.apache.hadoop.yarn.server.resourcemanager.scheduler.capacity.LeafQueue: completedContainer container=Container: [ContainerId: container_1490313515759_0002_01_000002, NodeId: 240008d2487e:44869, NodeHttpAddress: 240008d2487e:8042, Resource: <memory:1024, vCores:1>, Priority: 20, Token: Token { kind: ContainerToken, service: 172.18.0.2:44869 }, ] queue=default: capacity=1.0, absoluteCapacity=1.0, usedResources=<memory:3072, vCores:2>, usedCapacity=0.375, absoluteUsedCapacity=0.375, numApps=1, numContainers=2 cluster=<memory:8192, vCores:8>
2017-03-23 20:15:33,007 INFO org.apache.hadoop.yarn.server.resourcemanager.scheduler.capacity.ParentQueue: completedContainer queue=root usedCapacity=0.375 absoluteUsedCapacity=0.375 used=<memory:3072, vCores:2> cluster=<memory:8192, vCores:8>
2017-03-23 20:15:33,007 INFO org.apache.hadoop.yarn.server.resourcemanager.scheduler.capacity.ParentQueue: Re-sorting completed queue: root.default stats: default: capacity=1.0, absoluteCapacity=1.0, usedResources=<memory:3072, vCores:2>, usedCapacity=0.375, absoluteUsedCapacity=0.375, numApps=1, numContainers=2
2017-03-23 20:15:33,007 INFO org.apache.hadoop.yarn.server.resourcemanager.scheduler.capacity.CapacityScheduler: Application attempt appattempt_1490313515759_0002_000001 released container container_1490313515759_0002_01_000002 on node: host: 240008d2487e:44869 #containers=2 available=<memory:5120, vCores:6> used=<memory:3072, vCores:2> with event: FINISHED
2017-03-23 20:15:34,008 INFO org.apache.hadoop.yarn.server.resourcemanager.rmcontainer.RMContainerImpl: container_1490313515759_0002_01_000003 Container Transitioned from RUNNING to COMPLETED
2017-03-23 20:15:34,008 INFO org.apache.hadoop.yarn.server.resourcemanager.scheduler.common.fica.FiCaSchedulerApp: Completed container: container_1490313515759_0002_01_000003 in state: COMPLETED event:FINISHED
2017-03-23 20:15:34,008 INFO org.apache.hadoop.yarn.server.resourcemanager.RMAuditLogger: USER=root	OPERATION=AM Released Container	TARGET=SchedulerApp	RESULT=SUCCESS	APPID=application_1490313515759_0002	CONTAINERID=container_1490313515759_0002_01_000003
2017-03-23 20:15:34,008 INFO org.apache.hadoop.yarn.server.resourcemanager.scheduler.SchedulerNode: Released container container_1490313515759_0002_01_000003 of capacity <memory:1024, vCores:1> on host 240008d2487e:44869, which currently has 1 containers, <memory:2048, vCores:1> used and <memory:6144, vCores:7> available, release resources=true
2017-03-23 20:15:34,008 INFO org.apache.hadoop.yarn.server.resourcemanager.scheduler.capacity.LeafQueue: default used=<memory:2048, vCores:1> numContainers=1 user=root user-resources=<memory:2048, vCores:1>
2017-03-23 20:15:34,009 INFO org.apache.hadoop.yarn.server.resourcemanager.scheduler.capacity.LeafQueue: completedContainer container=Container: [ContainerId: container_1490313515759_0002_01_000003, NodeId: 240008d2487e:44869, NodeHttpAddress: 240008d2487e:8042, Resource: <memory:1024, vCores:1>, Priority: 20, Token: Token { kind: ContainerToken, service: 172.18.0.2:44869 }, ] queue=default: capacity=1.0, absoluteCapacity=1.0, usedResources=<memory:2048, vCores:1>, usedCapacity=0.25, absoluteUsedCapacity=0.25, numApps=1, numContainers=1 cluster=<memory:8192, vCores:8>
2017-03-23 20:15:34,009 INFO org.apache.hadoop.yarn.server.resourcemanager.scheduler.capacity.ParentQueue: completedContainer queue=root usedCapacity=0.25 absoluteUsedCapacity=0.25 used=<memory:2048, vCores:1> cluster=<memory:8192, vCores:8>
2017-03-23 20:15:34,009 INFO org.apache.hadoop.yarn.server.resourcemanager.scheduler.capacity.ParentQueue: Re-sorting completed queue: root.default stats: default: capacity=1.0, absoluteCapacity=1.0, usedResources=<memory:2048, vCores:1>, usedCapacity=0.25, absoluteUsedCapacity=0.25, numApps=1, numContainers=1
2017-03-23 20:15:34,009 INFO org.apache.hadoop.yarn.server.resourcemanager.scheduler.capacity.CapacityScheduler: Application attempt appattempt_1490313515759_0002_000001 released container container_1490313515759_0002_01_000003 on node: host: 240008d2487e:44869 #containers=1 available=<memory:6144, vCores:7> used=<memory:2048, vCores:1> with event: FINISHED
2017-03-23 20:15:35,011 INFO org.apache.hadoop.yarn.server.resourcemanager.rmcontainer.RMContainerImpl: container_1490313515759_0002_01_000004 Container Transitioned from NEW to ALLOCATED
2017-03-23 20:15:35,012 INFO org.apache.hadoop.yarn.server.resourcemanager.RMAuditLogger: USER=root	OPERATION=AM Allocated Container	TARGET=SchedulerApp	RESULT=SUCCESS	APPID=application_1490313515759_0002	CONTAINERID=container_1490313515759_0002_01_000004
2017-03-23 20:15:35,012 INFO org.apache.hadoop.yarn.server.resourcemanager.scheduler.SchedulerNode: Assigned container container_1490313515759_0002_01_000004 of capacity <memory:1024, vCores:1> on host 240008d2487e:44869, which has 2 containers, <memory:3072, vCores:2> used and <memory:5120, vCores:6> available after allocation
2017-03-23 20:15:35,012 INFO org.apache.hadoop.yarn.server.resourcemanager.scheduler.capacity.LeafQueue: assignedContainer application attempt=appattempt_1490313515759_0002_000001 container=Container: [ContainerId: container_1490313515759_0002_01_000004, NodeId: 240008d2487e:44869, NodeHttpAddress: 240008d2487e:8042, Resource: <memory:1024, vCores:1>, Priority: 10, Token: null, ] queue=default: capacity=1.0, absoluteCapacity=1.0, usedResources=<memory:2048, vCores:1>, usedCapacity=0.25, absoluteUsedCapacity=0.25, numApps=1, numContainers=1 clusterResource=<memory:8192, vCores:8>
2017-03-23 20:15:35,012 INFO org.apache.hadoop.yarn.server.resourcemanager.scheduler.capacity.ParentQueue: Re-sorting assigned queue: root.default stats: default: capacity=1.0, absoluteCapacity=1.0, usedResources=<memory:3072, vCores:2>, usedCapacity=0.375, absoluteUsedCapacity=0.375, numApps=1, numContainers=2
2017-03-23 20:15:35,012 INFO org.apache.hadoop.yarn.server.resourcemanager.scheduler.capacity.ParentQueue: assignedContainer queue=root usedCapacity=0.375 absoluteUsedCapacity=0.375 used=<memory:3072, vCores:2> cluster=<memory:8192, vCores:8>
2017-03-23 20:15:35,124 INFO org.apache.hadoop.yarn.server.resourcemanager.rmcontainer.RMContainerImpl: container_1490313515759_0002_01_000004 Container Transitioned from ALLOCATED to ACQUIRED
2017-03-23 20:15:36,015 INFO org.apache.hadoop.yarn.server.resourcemanager.rmcontainer.RMContainerImpl: container_1490313515759_0002_01_000004 Container Transitioned from ACQUIRED to RUNNING
2017-03-23 20:15:36,129 INFO org.apache.hadoop.yarn.server.resourcemanager.scheduler.AppSchedulingInfo: checking for deactivate of application :application_1490313515759_0002
2017-03-23 20:15:52,023 INFO org.apache.hadoop.yarn.server.resourcemanager.rmapp.attempt.RMAppAttemptImpl: Updating application attempt appattempt_1490313515759_0002_000001 with final state: FINISHING, and exit status: -1000
2017-03-23 20:15:52,024 INFO org.apache.hadoop.yarn.server.resourcemanager.rmapp.attempt.RMAppAttemptImpl: appattempt_1490313515759_0002_000001 State change from RUNNING to FINAL_SAVING
2017-03-23 20:15:52,024 INFO org.apache.hadoop.yarn.server.resourcemanager.rmapp.RMAppImpl: Updating application application_1490313515759_0002 with final state: FINISHING
2017-03-23 20:15:52,024 INFO org.apache.hadoop.yarn.server.resourcemanager.rmapp.RMAppImpl: application_1490313515759_0002 State change from RUNNING to FINAL_SAVING
2017-03-23 20:15:52,025 INFO org.apache.hadoop.yarn.server.resourcemanager.recovery.RMStateStore: Updating info for app: application_1490313515759_0002
2017-03-23 20:15:52,025 INFO org.apache.hadoop.yarn.server.resourcemanager.rmapp.attempt.RMAppAttemptImpl: appattempt_1490313515759_0002_000001 State change from FINAL_SAVING to FINISHING
2017-03-23 20:15:52,025 INFO org.apache.hadoop.yarn.server.resourcemanager.rmapp.RMAppImpl: application_1490313515759_0002 State change from FINAL_SAVING to FINISHING
2017-03-23 20:15:52,649 INFO org.apache.hadoop.yarn.server.resourcemanager.rmcontainer.RMContainerImpl: container_1490313515759_0002_01_000004 Container Transitioned from RUNNING to COMPLETED
2017-03-23 20:15:52,649 INFO org.apache.hadoop.yarn.server.resourcemanager.scheduler.common.fica.FiCaSchedulerApp: Completed container: container_1490313515759_0002_01_000004 in state: COMPLETED event:FINISHED
2017-03-23 20:15:52,649 INFO org.apache.hadoop.yarn.server.resourcemanager.RMAuditLogger: USER=root	OPERATION=AM Released Container	TARGET=SchedulerApp	RESULT=SUCCESS	APPID=application_1490313515759_0002	CONTAINERID=container_1490313515759_0002_01_000004
2017-03-23 20:15:52,650 INFO org.apache.hadoop.yarn.server.resourcemanager.scheduler.SchedulerNode: Released container container_1490313515759_0002_01_000004 of capacity <memory:1024, vCores:1> on host 240008d2487e:44869, which currently has 1 containers, <memory:2048, vCores:1> used and <memory:6144, vCores:7> available, release resources=true
2017-03-23 20:15:52,650 INFO org.apache.hadoop.yarn.server.resourcemanager.scheduler.capacity.LeafQueue: default used=<memory:2048, vCores:1> numContainers=1 user=root user-resources=<memory:2048, vCores:1>
2017-03-23 20:15:52,650 INFO org.apache.hadoop.yarn.server.resourcemanager.scheduler.capacity.LeafQueue: completedContainer container=Container: [ContainerId: container_1490313515759_0002_01_000004, NodeId: 240008d2487e:44869, NodeHttpAddress: 240008d2487e:8042, Resource: <memory:1024, vCores:1>, Priority: 10, Token: Token { kind: ContainerToken, service: 172.18.0.2:44869 }, ] queue=default: capacity=1.0, absoluteCapacity=1.0, usedResources=<memory:2048, vCores:1>, usedCapacity=0.25, absoluteUsedCapacity=0.25, numApps=1, numContainers=1 cluster=<memory:8192, vCores:8>
2017-03-23 20:15:52,650 INFO org.apache.hadoop.yarn.server.resourcemanager.scheduler.capacity.ParentQueue: completedContainer queue=root usedCapacity=0.25 absoluteUsedCapacity=0.25 used=<memory:2048, vCores:1> cluster=<memory:8192, vCores:8>
2017-03-23 20:15:52,651 INFO org.apache.hadoop.yarn.server.resourcemanager.scheduler.capacity.ParentQueue: Re-sorting completed queue: root.default stats: default: capacity=1.0, absoluteCapacity=1.0, usedResources=<memory:2048, vCores:1>, usedCapacity=0.25, absoluteUsedCapacity=0.25, numApps=1, numContainers=1
2017-03-23 20:15:52,651 INFO org.apache.hadoop.yarn.server.resourcemanager.scheduler.capacity.CapacityScheduler: Application attempt appattempt_1490313515759_0002_000001 released container container_1490313515759_0002_01_000004 on node: host: 240008d2487e:44869 #containers=1 available=<memory:6144, vCores:7> used=<memory:2048, vCores:1> with event: FINISHED
2017-03-23 20:15:53,030 INFO org.apache.hadoop.yarn.server.resourcemanager.ApplicationMasterService: application_1490313515759_0002 unregistered successfully. 
2017-03-23 20:15:58,666 INFO org.apache.hadoop.yarn.server.resourcemanager.rmcontainer.RMContainerImpl: container_1490313515759_0002_01_000001 Container Transitioned from RUNNING to COMPLETED
2017-03-23 20:15:58,667 INFO org.apache.hadoop.yarn.server.resourcemanager.ApplicationMasterService: Unregistering app attempt : appattempt_1490313515759_0002_000001
2017-03-23 20:15:58,667 INFO org.apache.hadoop.yarn.server.resourcemanager.scheduler.common.fica.FiCaSchedulerApp: Completed container: container_1490313515759_0002_01_000001 in state: COMPLETED event:FINISHED
2017-03-23 20:15:58,667 INFO org.apache.hadoop.yarn.server.resourcemanager.RMAuditLogger: USER=root	OPERATION=AM Released Container	TARGET=SchedulerApp	RESULT=SUCCESS	APPID=application_1490313515759_0002	CONTAINERID=container_1490313515759_0002_01_000001
2017-03-23 20:15:58,667 INFO org.apache.hadoop.yarn.server.resourcemanager.scheduler.SchedulerNode: Released container container_1490313515759_0002_01_000001 of capacity <memory:2048, vCores:1> on host 240008d2487e:44869, which currently has 0 containers, <memory:0, vCores:0> used and <memory:8192, vCores:8> available, release resources=true
2017-03-23 20:15:58,667 INFO org.apache.hadoop.yarn.server.resourcemanager.scheduler.capacity.LeafQueue: default used=<memory:0, vCores:0> numContainers=0 user=root user-resources=<memory:0, vCores:0>
2017-03-23 20:15:58,667 INFO org.apache.hadoop.yarn.server.resourcemanager.scheduler.capacity.LeafQueue: completedContainer container=Container: [ContainerId: container_1490313515759_0002_01_000001, NodeId: 240008d2487e:44869, NodeHttpAddress: 240008d2487e:8042, Resource: <memory:2048, vCores:1>, Priority: 0, Token: Token { kind: ContainerToken, service: 172.18.0.2:44869 }, ] queue=default: capacity=1.0, absoluteCapacity=1.0, usedResources=<memory:0, vCores:0>, usedCapacity=0.0, absoluteUsedCapacity=0.0, numApps=1, numContainers=0 cluster=<memory:8192, vCores:8>
2017-03-23 20:15:58,667 INFO org.apache.hadoop.yarn.server.resourcemanager.scheduler.capacity.ParentQueue: completedContainer queue=root usedCapacity=0.0 absoluteUsedCapacity=0.0 used=<memory:0, vCores:0> cluster=<memory:8192, vCores:8>
2017-03-23 20:15:58,667 INFO org.apache.hadoop.yarn.server.resourcemanager.scheduler.capacity.ParentQueue: Re-sorting completed queue: root.default stats: default: capacity=1.0, absoluteCapacity=1.0, usedResources=<memory:0, vCores:0>, usedCapacity=0.0, absoluteUsedCapacity=0.0, numApps=1, numContainers=0
2017-03-23 20:15:58,668 INFO org.apache.hadoop.yarn.server.resourcemanager.scheduler.capacity.CapacityScheduler: Application attempt appattempt_1490313515759_0002_000001 released container container_1490313515759_0002_01_000001 on node: host: 240008d2487e:44869 #containers=0 available=<memory:8192, vCores:8> used=<memory:0, vCores:0> with event: FINISHED
2017-03-23 20:15:58,668 INFO org.apache.hadoop.yarn.server.resourcemanager.security.AMRMTokenSecretManager: Application finished, removing password for appattempt_1490313515759_0002_000001
2017-03-23 20:15:58,668 INFO org.apache.hadoop.yarn.server.resourcemanager.rmapp.attempt.RMAppAttemptImpl: appattempt_1490313515759_0002_000001 State change from FINISHING to FINISHED
2017-03-23 20:15:58,670 INFO org.apache.hadoop.yarn.server.resourcemanager.rmapp.RMAppImpl: application_1490313515759_0002 State change from FINISHING to FINISHED
2017-03-23 20:15:58,671 INFO org.apache.hadoop.yarn.server.resourcemanager.scheduler.capacity.CapacityScheduler: Application Attempt appattempt_1490313515759_0002_000001 is done. finalState=FINISHED
2017-03-23 20:15:58,671 INFO org.apache.hadoop.yarn.server.resourcemanager.scheduler.AppSchedulingInfo: Application application_1490313515759_0002 requests cleared
2017-03-23 20:15:58,671 INFO org.apache.hadoop.yarn.server.resourcemanager.scheduler.capacity.LeafQueue: Application removed - appId: application_1490313515759_0002 user: root queue: default #user-pending-applications: 0 #user-active-applications: 0 #queue-pending-applications: 0 #queue-active-applications: 0
2017-03-23 20:15:58,671 INFO org.apache.hadoop.yarn.server.resourcemanager.scheduler.capacity.ParentQueue: Application removed - appId: application_1490313515759_0002 user: root leaf-queue of parent: root #applications: 0
2017-03-23 20:15:58,671 INFO org.apache.hadoop.yarn.server.resourcemanager.amlauncher.AMLauncher: Cleaning master appattempt_1490313515759_0002_000001
2017-03-23 20:15:58,672 INFO org.apache.hadoop.yarn.server.resourcemanager.RMAuditLogger: USER=root	OPERATION=Application Finished - Succeeded	TARGET=RMAppManager	RESULT=SUCCESS	APPID=application_1490313515759_0002
2017-03-23 20:15:58,674 INFO org.apache.hadoop.yarn.server.resourcemanager.RMAppManager$ApplicationSummary: appId=application_1490313515759_0002,name=streamjob3111274204557162267.jar,user=root,queue=default,state=FINISHED,trackingUrl=http://240008d2487e:8088/proxy/application_1490313515759_0002/,appMasterHost=240008d2487e,startTime=1490314507248,finishTime=1490314552024,finalStatus=SUCCEEDED,memorySeconds=156232,vcoreSeconds=100,preemptedAMContainers=0,preemptedNonAMContainers=0,preemptedResources=<memory:0\, vCores:0>,applicationType=MAPREDUCE
2017-03-23 20:15:59,698 INFO org.apache.hadoop.yarn.server.resourcemanager.scheduler.capacity.CapacityScheduler: Null container completed...
2017-03-23 20:26:21,095 INFO org.apache.hadoop.yarn.server.resourcemanager.ClientRMService: Allocated new applicationId: 3
2017-03-23 20:26:22,591 INFO org.apache.hadoop.yarn.server.resourcemanager.ClientRMService: Application with id 3 submitted by user root
2017-03-23 20:26:22,591 INFO org.apache.hadoop.yarn.server.resourcemanager.RMAuditLogger: USER=root	IP=172.18.0.2	OPERATION=Submit Application Request	TARGET=ClientRMService	RESULT=SUCCESS	APPID=application_1490313515759_0003
2017-03-23 20:26:22,591 INFO org.apache.hadoop.yarn.server.resourcemanager.rmapp.RMAppImpl: Storing application with id application_1490313515759_0003
2017-03-23 20:26:22,592 INFO org.apache.hadoop.yarn.server.resourcemanager.rmapp.RMAppImpl: application_1490313515759_0003 State change from NEW to NEW_SAVING
2017-03-23 20:26:22,592 INFO org.apache.hadoop.yarn.server.resourcemanager.recovery.RMStateStore: Storing info for app: application_1490313515759_0003
2017-03-23 20:26:22,592 INFO org.apache.hadoop.yarn.server.resourcemanager.rmapp.RMAppImpl: application_1490313515759_0003 State change from NEW_SAVING to SUBMITTED
2017-03-23 20:26:22,593 INFO org.apache.hadoop.yarn.server.resourcemanager.scheduler.capacity.ParentQueue: Application added - appId: application_1490313515759_0003 user: root leaf-queue of parent: root #applications: 1
2017-03-23 20:26:22,593 INFO org.apache.hadoop.yarn.server.resourcemanager.scheduler.capacity.CapacityScheduler: Accepted application application_1490313515759_0003 from user: root, in queue: default
2017-03-23 20:26:22,594 INFO org.apache.hadoop.yarn.server.resourcemanager.rmapp.RMAppImpl: application_1490313515759_0003 State change from SUBMITTED to ACCEPTED
2017-03-23 20:26:22,594 INFO org.apache.hadoop.yarn.server.resourcemanager.ApplicationMasterService: Registering app attempt : appattempt_1490313515759_0003_000001
2017-03-23 20:26:22,594 INFO org.apache.hadoop.yarn.server.resourcemanager.rmapp.attempt.RMAppAttemptImpl: appattempt_1490313515759_0003_000001 State change from NEW to SUBMITTED
2017-03-23 20:26:22,594 WARN org.apache.hadoop.yarn.server.resourcemanager.scheduler.capacity.LeafQueue: maximum-am-resource-percent is insufficient to start a single application in queue, it is likely set too low. skipping enforcement to allow at least one application to start
2017-03-23 20:26:22,594 WARN org.apache.hadoop.yarn.server.resourcemanager.scheduler.capacity.LeafQueue: maximum-am-resource-percent is insufficient to start a single application in queue for user, it is likely set too low. skipping enforcement to allow at least one application to start
2017-03-23 20:26:22,594 INFO org.apache.hadoop.yarn.server.resourcemanager.scheduler.capacity.LeafQueue: Application application_1490313515759_0003 from user: root activated in queue: default
2017-03-23 20:26:22,594 INFO org.apache.hadoop.yarn.server.resourcemanager.scheduler.capacity.LeafQueue: Application added - appId: application_1490313515759_0003 user: org.apache.hadoop.yarn.server.resourcemanager.scheduler.capacity.LeafQueue$User@62343903, leaf-queue: default #user-pending-applications: 0 #user-active-applications: 1 #queue-pending-applications: 0 #queue-active-applications: 1
2017-03-23 20:26:22,595 INFO org.apache.hadoop.yarn.server.resourcemanager.scheduler.capacity.CapacityScheduler: Added Application Attempt appattempt_1490313515759_0003_000001 to scheduler from user root in queue default
2017-03-23 20:26:22,595 INFO org.apache.hadoop.yarn.server.resourcemanager.rmapp.attempt.RMAppAttemptImpl: appattempt_1490313515759_0003_000001 State change from SUBMITTED to SCHEDULED
2017-03-23 20:26:23,276 INFO org.apache.hadoop.yarn.server.resourcemanager.rmcontainer.RMContainerImpl: container_1490313515759_0003_01_000001 Container Transitioned from NEW to ALLOCATED
2017-03-23 20:26:23,277 INFO org.apache.hadoop.yarn.server.resourcemanager.RMAuditLogger: USER=root	OPERATION=AM Allocated Container	TARGET=SchedulerApp	RESULT=SUCCESS	APPID=application_1490313515759_0003	CONTAINERID=container_1490313515759_0003_01_000001
2017-03-23 20:26:23,277 INFO org.apache.hadoop.yarn.server.resourcemanager.scheduler.SchedulerNode: Assigned container container_1490313515759_0003_01_000001 of capacity <memory:2048, vCores:1> on host 240008d2487e:44869, which has 1 containers, <memory:2048, vCores:1> used and <memory:6144, vCores:7> available after allocation
2017-03-23 20:26:23,277 INFO org.apache.hadoop.yarn.server.resourcemanager.scheduler.capacity.LeafQueue: assignedContainer application attempt=appattempt_1490313515759_0003_000001 container=Container: [ContainerId: container_1490313515759_0003_01_000001, NodeId: 240008d2487e:44869, NodeHttpAddress: 240008d2487e:8042, Resource: <memory:2048, vCores:1>, Priority: 0, Token: null, ] queue=default: capacity=1.0, absoluteCapacity=1.0, usedResources=<memory:0, vCores:0>, usedCapacity=0.0, absoluteUsedCapacity=0.0, numApps=1, numContainers=0 clusterResource=<memory:8192, vCores:8>
2017-03-23 20:26:23,277 INFO org.apache.hadoop.yarn.server.resourcemanager.scheduler.capacity.ParentQueue: Re-sorting assigned queue: root.default stats: default: capacity=1.0, absoluteCapacity=1.0, usedResources=<memory:2048, vCores:1>, usedCapacity=0.25, absoluteUsedCapacity=0.25, numApps=1, numContainers=1
2017-03-23 20:26:23,277 INFO org.apache.hadoop.yarn.server.resourcemanager.scheduler.capacity.ParentQueue: assignedContainer queue=root usedCapacity=0.25 absoluteUsedCapacity=0.25 used=<memory:2048, vCores:1> cluster=<memory:8192, vCores:8>
2017-03-23 20:26:23,279 INFO org.apache.hadoop.yarn.server.resourcemanager.security.NMTokenSecretManagerInRM: Sending NMToken for nodeId : 240008d2487e:44869 for container : container_1490313515759_0003_01_000001
2017-03-23 20:26:23,280 INFO org.apache.hadoop.yarn.server.resourcemanager.rmcontainer.RMContainerImpl: container_1490313515759_0003_01_000001 Container Transitioned from ALLOCATED to ACQUIRED
2017-03-23 20:26:23,281 INFO org.apache.hadoop.yarn.server.resourcemanager.security.NMTokenSecretManagerInRM: Clear node set for appattempt_1490313515759_0003_000001
2017-03-23 20:26:23,281 INFO org.apache.hadoop.yarn.server.resourcemanager.rmapp.attempt.RMAppAttemptImpl: Storing attempt: AppId: application_1490313515759_0003 AttemptId: appattempt_1490313515759_0003_000001 MasterContainer: Container: [ContainerId: container_1490313515759_0003_01_000001, NodeId: 240008d2487e:44869, NodeHttpAddress: 240008d2487e:8042, Resource: <memory:2048, vCores:1>, Priority: 0, Token: Token { kind: ContainerToken, service: 172.18.0.2:44869 }, ]
2017-03-23 20:26:23,281 INFO org.apache.hadoop.yarn.server.resourcemanager.rmapp.attempt.RMAppAttemptImpl: appattempt_1490313515759_0003_000001 State change from SCHEDULED to ALLOCATED_SAVING
2017-03-23 20:26:23,281 INFO org.apache.hadoop.yarn.server.resourcemanager.rmapp.attempt.RMAppAttemptImpl: appattempt_1490313515759_0003_000001 State change from ALLOCATED_SAVING to ALLOCATED
2017-03-23 20:26:23,282 INFO org.apache.hadoop.yarn.server.resourcemanager.amlauncher.AMLauncher: Launching masterappattempt_1490313515759_0003_000001
2017-03-23 20:26:23,285 INFO org.apache.hadoop.yarn.server.resourcemanager.amlauncher.AMLauncher: Setting up container Container: [ContainerId: container_1490313515759_0003_01_000001, NodeId: 240008d2487e:44869, NodeHttpAddress: 240008d2487e:8042, Resource: <memory:2048, vCores:1>, Priority: 0, Token: Token { kind: ContainerToken, service: 172.18.0.2:44869 }, ] for AM appattempt_1490313515759_0003_000001
2017-03-23 20:26:23,285 INFO org.apache.hadoop.yarn.server.resourcemanager.amlauncher.AMLauncher: Command to launch container container_1490313515759_0003_01_000001 : $JAVA_HOME/bin/java -Dlog4j.configuration=container-log4j.properties -Dyarn.app.container.log.dir=<LOG_DIR> -Dyarn.app.container.log.filesize=0 -Dhadoop.root.logger=INFO,CLA -Dhadoop.root.logfile=syslog  -Xmx1024m org.apache.hadoop.mapreduce.v2.app.MRAppMaster 1><LOG_DIR>/stdout 2><LOG_DIR>/stderr 
2017-03-23 20:26:23,285 INFO org.apache.hadoop.yarn.server.resourcemanager.security.AMRMTokenSecretManager: Create AMRMToken for ApplicationAttempt: appattempt_1490313515759_0003_000001
2017-03-23 20:26:23,285 INFO org.apache.hadoop.yarn.server.resourcemanager.security.AMRMTokenSecretManager: Creating password for appattempt_1490313515759_0003_000001
2017-03-23 20:26:23,298 INFO org.apache.hadoop.yarn.server.resourcemanager.amlauncher.AMLauncher: Done launching container Container: [ContainerId: container_1490313515759_0003_01_000001, NodeId: 240008d2487e:44869, NodeHttpAddress: 240008d2487e:8042, Resource: <memory:2048, vCores:1>, Priority: 0, Token: Token { kind: ContainerToken, service: 172.18.0.2:44869 }, ] for AM appattempt_1490313515759_0003_000001
2017-03-23 20:26:23,299 INFO org.apache.hadoop.yarn.server.resourcemanager.rmapp.attempt.RMAppAttemptImpl: appattempt_1490313515759_0003_000001 State change from ALLOCATED to LAUNCHED
2017-03-23 20:26:24,279 INFO org.apache.hadoop.yarn.server.resourcemanager.rmcontainer.RMContainerImpl: container_1490313515759_0003_01_000001 Container Transitioned from ACQUIRED to RUNNING
2017-03-23 20:26:28,335 INFO SecurityLogger.org.apache.hadoop.ipc.Server: Auth successful for appattempt_1490313515759_0003_000001 (auth:SIMPLE)
2017-03-23 20:26:28,340 INFO org.apache.hadoop.yarn.server.resourcemanager.ApplicationMasterService: AM registration appattempt_1490313515759_0003_000001
2017-03-23 20:26:28,340 INFO org.apache.hadoop.yarn.server.resourcemanager.RMAuditLogger: USER=root	IP=172.18.0.2	OPERATION=Register App Master	TARGET=ApplicationMasterService	RESULT=SUCCESS	APPID=application_1490313515759_0003	APPATTEMPTID=appattempt_1490313515759_0003_000001
2017-03-23 20:26:28,340 INFO org.apache.hadoop.yarn.server.resourcemanager.rmapp.attempt.RMAppAttemptImpl: appattempt_1490313515759_0003_000001 State change from LAUNCHED to RUNNING
2017-03-23 20:26:28,340 INFO org.apache.hadoop.yarn.server.resourcemanager.rmapp.RMAppImpl: application_1490313515759_0003 State change from ACCEPTED to RUNNING
2017-03-23 20:26:30,295 INFO org.apache.hadoop.yarn.server.resourcemanager.rmcontainer.RMContainerImpl: container_1490313515759_0003_01_000002 Container Transitioned from NEW to ALLOCATED
2017-03-23 20:26:30,295 INFO org.apache.hadoop.yarn.server.resourcemanager.RMAuditLogger: USER=root	OPERATION=AM Allocated Container	TARGET=SchedulerApp	RESULT=SUCCESS	APPID=application_1490313515759_0003	CONTAINERID=container_1490313515759_0003_01_000002
2017-03-23 20:26:30,296 INFO org.apache.hadoop.yarn.server.resourcemanager.scheduler.SchedulerNode: Assigned container container_1490313515759_0003_01_000002 of capacity <memory:1024, vCores:1> on host 240008d2487e:44869, which has 2 containers, <memory:3072, vCores:2> used and <memory:5120, vCores:6> available after allocation
2017-03-23 20:26:30,296 INFO org.apache.hadoop.yarn.server.resourcemanager.scheduler.capacity.LeafQueue: assignedContainer application attempt=appattempt_1490313515759_0003_000001 container=Container: [ContainerId: container_1490313515759_0003_01_000002, NodeId: 240008d2487e:44869, NodeHttpAddress: 240008d2487e:8042, Resource: <memory:1024, vCores:1>, Priority: 20, Token: null, ] queue=default: capacity=1.0, absoluteCapacity=1.0, usedResources=<memory:2048, vCores:1>, usedCapacity=0.25, absoluteUsedCapacity=0.25, numApps=1, numContainers=1 clusterResource=<memory:8192, vCores:8>
2017-03-23 20:26:30,296 INFO org.apache.hadoop.yarn.server.resourcemanager.scheduler.capacity.ParentQueue: Re-sorting assigned queue: root.default stats: default: capacity=1.0, absoluteCapacity=1.0, usedResources=<memory:3072, vCores:2>, usedCapacity=0.375, absoluteUsedCapacity=0.375, numApps=1, numContainers=2
2017-03-23 20:26:30,296 INFO org.apache.hadoop.yarn.server.resourcemanager.scheduler.capacity.ParentQueue: assignedContainer queue=root usedCapacity=0.375 absoluteUsedCapacity=0.375 used=<memory:3072, vCores:2> cluster=<memory:8192, vCores:8>
2017-03-23 20:26:30,296 INFO org.apache.hadoop.yarn.server.resourcemanager.rmcontainer.RMContainerImpl: container_1490313515759_0003_01_000003 Container Transitioned from NEW to ALLOCATED
2017-03-23 20:26:30,297 INFO org.apache.hadoop.yarn.server.resourcemanager.RMAuditLogger: USER=root	OPERATION=AM Allocated Container	TARGET=SchedulerApp	RESULT=SUCCESS	APPID=application_1490313515759_0003	CONTAINERID=container_1490313515759_0003_01_000003
2017-03-23 20:26:30,297 INFO org.apache.hadoop.yarn.server.resourcemanager.scheduler.SchedulerNode: Assigned container container_1490313515759_0003_01_000003 of capacity <memory:1024, vCores:1> on host 240008d2487e:44869, which has 3 containers, <memory:4096, vCores:3> used and <memory:4096, vCores:5> available after allocation
2017-03-23 20:26:30,297 INFO org.apache.hadoop.yarn.server.resourcemanager.scheduler.capacity.LeafQueue: assignedContainer application attempt=appattempt_1490313515759_0003_000001 container=Container: [ContainerId: container_1490313515759_0003_01_000003, NodeId: 240008d2487e:44869, NodeHttpAddress: 240008d2487e:8042, Resource: <memory:1024, vCores:1>, Priority: 20, Token: null, ] queue=default: capacity=1.0, absoluteCapacity=1.0, usedResources=<memory:3072, vCores:2>, usedCapacity=0.375, absoluteUsedCapacity=0.375, numApps=1, numContainers=2 clusterResource=<memory:8192, vCores:8>
2017-03-23 20:26:30,297 INFO org.apache.hadoop.yarn.server.resourcemanager.scheduler.capacity.ParentQueue: Re-sorting assigned queue: root.default stats: default: capacity=1.0, absoluteCapacity=1.0, usedResources=<memory:4096, vCores:3>, usedCapacity=0.5, absoluteUsedCapacity=0.5, numApps=1, numContainers=3
2017-03-23 20:26:30,297 INFO org.apache.hadoop.yarn.server.resourcemanager.scheduler.capacity.ParentQueue: assignedContainer queue=root usedCapacity=0.5 absoluteUsedCapacity=0.5 used=<memory:4096, vCores:3> cluster=<memory:8192, vCores:8>
2017-03-23 20:26:30,444 INFO org.apache.hadoop.yarn.server.resourcemanager.security.NMTokenSecretManagerInRM: Sending NMToken for nodeId : 240008d2487e:44869 for container : container_1490313515759_0003_01_000002
2017-03-23 20:26:30,445 INFO org.apache.hadoop.yarn.server.resourcemanager.rmcontainer.RMContainerImpl: container_1490313515759_0003_01_000002 Container Transitioned from ALLOCATED to ACQUIRED
2017-03-23 20:26:30,447 INFO org.apache.hadoop.yarn.server.resourcemanager.rmcontainer.RMContainerImpl: container_1490313515759_0003_01_000003 Container Transitioned from ALLOCATED to ACQUIRED
2017-03-23 20:26:31,298 INFO org.apache.hadoop.yarn.server.resourcemanager.rmcontainer.RMContainerImpl: container_1490313515759_0003_01_000002 Container Transitioned from ACQUIRED to RUNNING
2017-03-23 20:26:31,298 INFO org.apache.hadoop.yarn.server.resourcemanager.rmcontainer.RMContainerImpl: container_1490313515759_0003_01_000003 Container Transitioned from ACQUIRED to RUNNING
2017-03-23 20:26:31,463 INFO org.apache.hadoop.yarn.server.resourcemanager.scheduler.AppSchedulingInfo: checking for deactivate of application :application_1490313515759_0003
2017-03-23 20:26:46,286 INFO org.apache.hadoop.yarn.server.resourcemanager.rmcontainer.RMContainerImpl: container_1490313515759_0003_01_000002 Container Transitioned from RUNNING to COMPLETED
2017-03-23 20:26:46,286 INFO org.apache.hadoop.yarn.server.resourcemanager.scheduler.common.fica.FiCaSchedulerApp: Completed container: container_1490313515759_0003_01_000002 in state: COMPLETED event:FINISHED
2017-03-23 20:26:46,286 INFO org.apache.hadoop.yarn.server.resourcemanager.RMAuditLogger: USER=root	OPERATION=AM Released Container	TARGET=SchedulerApp	RESULT=SUCCESS	APPID=application_1490313515759_0003	CONTAINERID=container_1490313515759_0003_01_000002
2017-03-23 20:26:46,286 INFO org.apache.hadoop.yarn.server.resourcemanager.scheduler.SchedulerNode: Released container container_1490313515759_0003_01_000002 of capacity <memory:1024, vCores:1> on host 240008d2487e:44869, which currently has 2 containers, <memory:3072, vCores:2> used and <memory:5120, vCores:6> available, release resources=true
2017-03-23 20:26:46,286 INFO org.apache.hadoop.yarn.server.resourcemanager.scheduler.capacity.LeafQueue: default used=<memory:3072, vCores:2> numContainers=2 user=root user-resources=<memory:3072, vCores:2>
2017-03-23 20:26:46,286 INFO org.apache.hadoop.yarn.server.resourcemanager.scheduler.capacity.LeafQueue: completedContainer container=Container: [ContainerId: container_1490313515759_0003_01_000002, NodeId: 240008d2487e:44869, NodeHttpAddress: 240008d2487e:8042, Resource: <memory:1024, vCores:1>, Priority: 20, Token: Token { kind: ContainerToken, service: 172.18.0.2:44869 }, ] queue=default: capacity=1.0, absoluteCapacity=1.0, usedResources=<memory:3072, vCores:2>, usedCapacity=0.375, absoluteUsedCapacity=0.375, numApps=1, numContainers=2 cluster=<memory:8192, vCores:8>
2017-03-23 20:26:46,287 INFO org.apache.hadoop.yarn.server.resourcemanager.scheduler.capacity.ParentQueue: completedContainer queue=root usedCapacity=0.375 absoluteUsedCapacity=0.375 used=<memory:3072, vCores:2> cluster=<memory:8192, vCores:8>
2017-03-23 20:26:46,287 INFO org.apache.hadoop.yarn.server.resourcemanager.scheduler.capacity.ParentQueue: Re-sorting completed queue: root.default stats: default: capacity=1.0, absoluteCapacity=1.0, usedResources=<memory:3072, vCores:2>, usedCapacity=0.375, absoluteUsedCapacity=0.375, numApps=1, numContainers=2
2017-03-23 20:26:46,287 INFO org.apache.hadoop.yarn.server.resourcemanager.scheduler.capacity.CapacityScheduler: Application attempt appattempt_1490313515759_0003_000001 released container container_1490313515759_0003_01_000002 on node: host: 240008d2487e:44869 #containers=2 available=<memory:5120, vCores:6> used=<memory:3072, vCores:2> with event: FINISHED
2017-03-23 20:26:47,288 INFO org.apache.hadoop.yarn.server.resourcemanager.rmcontainer.RMContainerImpl: container_1490313515759_0003_01_000003 Container Transitioned from RUNNING to COMPLETED
2017-03-23 20:26:47,289 INFO org.apache.hadoop.yarn.server.resourcemanager.scheduler.common.fica.FiCaSchedulerApp: Completed container: container_1490313515759_0003_01_000003 in state: COMPLETED event:FINISHED
2017-03-23 20:26:47,289 INFO org.apache.hadoop.yarn.server.resourcemanager.RMAuditLogger: USER=root	OPERATION=AM Released Container	TARGET=SchedulerApp	RESULT=SUCCESS	APPID=application_1490313515759_0003	CONTAINERID=container_1490313515759_0003_01_000003
2017-03-23 20:26:47,289 INFO org.apache.hadoop.yarn.server.resourcemanager.scheduler.SchedulerNode: Released container container_1490313515759_0003_01_000003 of capacity <memory:1024, vCores:1> on host 240008d2487e:44869, which currently has 1 containers, <memory:2048, vCores:1> used and <memory:6144, vCores:7> available, release resources=true
2017-03-23 20:26:47,289 INFO org.apache.hadoop.yarn.server.resourcemanager.scheduler.capacity.LeafQueue: default used=<memory:2048, vCores:1> numContainers=1 user=root user-resources=<memory:2048, vCores:1>
2017-03-23 20:26:47,290 INFO org.apache.hadoop.yarn.server.resourcemanager.scheduler.capacity.LeafQueue: completedContainer container=Container: [ContainerId: container_1490313515759_0003_01_000003, NodeId: 240008d2487e:44869, NodeHttpAddress: 240008d2487e:8042, Resource: <memory:1024, vCores:1>, Priority: 20, Token: Token { kind: ContainerToken, service: 172.18.0.2:44869 }, ] queue=default: capacity=1.0, absoluteCapacity=1.0, usedResources=<memory:2048, vCores:1>, usedCapacity=0.25, absoluteUsedCapacity=0.25, numApps=1, numContainers=1 cluster=<memory:8192, vCores:8>
2017-03-23 20:26:47,290 INFO org.apache.hadoop.yarn.server.resourcemanager.scheduler.capacity.ParentQueue: completedContainer queue=root usedCapacity=0.25 absoluteUsedCapacity=0.25 used=<memory:2048, vCores:1> cluster=<memory:8192, vCores:8>
2017-03-23 20:26:47,290 INFO org.apache.hadoop.yarn.server.resourcemanager.scheduler.capacity.ParentQueue: Re-sorting completed queue: root.default stats: default: capacity=1.0, absoluteCapacity=1.0, usedResources=<memory:2048, vCores:1>, usedCapacity=0.25, absoluteUsedCapacity=0.25, numApps=1, numContainers=1
2017-03-23 20:26:47,290 INFO org.apache.hadoop.yarn.server.resourcemanager.scheduler.capacity.CapacityScheduler: Application attempt appattempt_1490313515759_0003_000001 released container container_1490313515759_0003_01_000003 on node: host: 240008d2487e:44869 #containers=1 available=<memory:6144, vCores:7> used=<memory:2048, vCores:1> with event: FINISHED
2017-03-23 20:26:48,291 INFO org.apache.hadoop.yarn.server.resourcemanager.rmcontainer.RMContainerImpl: container_1490313515759_0003_01_000004 Container Transitioned from NEW to ALLOCATED
2017-03-23 20:26:48,292 INFO org.apache.hadoop.yarn.server.resourcemanager.RMAuditLogger: USER=root	OPERATION=AM Allocated Container	TARGET=SchedulerApp	RESULT=SUCCESS	APPID=application_1490313515759_0003	CONTAINERID=container_1490313515759_0003_01_000004
2017-03-23 20:26:48,292 INFO org.apache.hadoop.yarn.server.resourcemanager.scheduler.SchedulerNode: Assigned container container_1490313515759_0003_01_000004 of capacity <memory:1024, vCores:1> on host 240008d2487e:44869, which has 2 containers, <memory:3072, vCores:2> used and <memory:5120, vCores:6> available after allocation
2017-03-23 20:26:48,292 INFO org.apache.hadoop.yarn.server.resourcemanager.scheduler.capacity.LeafQueue: assignedContainer application attempt=appattempt_1490313515759_0003_000001 container=Container: [ContainerId: container_1490313515759_0003_01_000004, NodeId: 240008d2487e:44869, NodeHttpAddress: 240008d2487e:8042, Resource: <memory:1024, vCores:1>, Priority: 10, Token: null, ] queue=default: capacity=1.0, absoluteCapacity=1.0, usedResources=<memory:2048, vCores:1>, usedCapacity=0.25, absoluteUsedCapacity=0.25, numApps=1, numContainers=1 clusterResource=<memory:8192, vCores:8>
2017-03-23 20:26:48,292 INFO org.apache.hadoop.yarn.server.resourcemanager.scheduler.capacity.ParentQueue: Re-sorting assigned queue: root.default stats: default: capacity=1.0, absoluteCapacity=1.0, usedResources=<memory:3072, vCores:2>, usedCapacity=0.375, absoluteUsedCapacity=0.375, numApps=1, numContainers=2
2017-03-23 20:26:48,292 INFO org.apache.hadoop.yarn.server.resourcemanager.scheduler.capacity.ParentQueue: assignedContainer queue=root usedCapacity=0.375 absoluteUsedCapacity=0.375 used=<memory:3072, vCores:2> cluster=<memory:8192, vCores:8>
2017-03-23 20:26:48,546 INFO org.apache.hadoop.yarn.server.resourcemanager.rmcontainer.RMContainerImpl: container_1490313515759_0003_01_000004 Container Transitioned from ALLOCATED to ACQUIRED
2017-03-23 20:26:49,294 INFO org.apache.hadoop.yarn.server.resourcemanager.rmcontainer.RMContainerImpl: container_1490313515759_0003_01_000004 Container Transitioned from ACQUIRED to RUNNING
2017-03-23 20:26:49,551 INFO org.apache.hadoop.yarn.server.resourcemanager.scheduler.AppSchedulingInfo: checking for deactivate of application :application_1490313515759_0003
2017-03-23 20:27:06,751 INFO org.apache.hadoop.yarn.server.resourcemanager.rmapp.attempt.RMAppAttemptImpl: Updating application attempt appattempt_1490313515759_0003_000001 with final state: FINISHING, and exit status: -1000
2017-03-23 20:27:06,751 INFO org.apache.hadoop.yarn.server.resourcemanager.rmapp.attempt.RMAppAttemptImpl: appattempt_1490313515759_0003_000001 State change from RUNNING to FINAL_SAVING
2017-03-23 20:27:06,751 INFO org.apache.hadoop.yarn.server.resourcemanager.rmapp.RMAppImpl: Updating application application_1490313515759_0003 with final state: FINISHING
2017-03-23 20:27:06,751 INFO org.apache.hadoop.yarn.server.resourcemanager.rmapp.RMAppImpl: application_1490313515759_0003 State change from RUNNING to FINAL_SAVING
2017-03-23 20:27:06,751 INFO org.apache.hadoop.yarn.server.resourcemanager.recovery.RMStateStore: Updating info for app: application_1490313515759_0003
2017-03-23 20:27:06,751 INFO org.apache.hadoop.yarn.server.resourcemanager.rmapp.attempt.RMAppAttemptImpl: appattempt_1490313515759_0003_000001 State change from FINAL_SAVING to FINISHING
2017-03-23 20:27:06,752 INFO org.apache.hadoop.yarn.server.resourcemanager.rmapp.RMAppImpl: application_1490313515759_0003 State change from FINAL_SAVING to FINISHING
2017-03-23 20:27:07,366 INFO org.apache.hadoop.yarn.server.resourcemanager.rmcontainer.RMContainerImpl: container_1490313515759_0003_01_000004 Container Transitioned from RUNNING to COMPLETED
2017-03-23 20:27:07,366 INFO org.apache.hadoop.yarn.server.resourcemanager.scheduler.common.fica.FiCaSchedulerApp: Completed container: container_1490313515759_0003_01_000004 in state: COMPLETED event:FINISHED
2017-03-23 20:27:07,366 INFO org.apache.hadoop.yarn.server.resourcemanager.RMAuditLogger: USER=root	OPERATION=AM Released Container	TARGET=SchedulerApp	RESULT=SUCCESS	APPID=application_1490313515759_0003	CONTAINERID=container_1490313515759_0003_01_000004
2017-03-23 20:27:07,366 INFO org.apache.hadoop.yarn.server.resourcemanager.scheduler.SchedulerNode: Released container container_1490313515759_0003_01_000004 of capacity <memory:1024, vCores:1> on host 240008d2487e:44869, which currently has 1 containers, <memory:2048, vCores:1> used and <memory:6144, vCores:7> available, release resources=true
2017-03-23 20:27:07,367 INFO org.apache.hadoop.yarn.server.resourcemanager.scheduler.capacity.LeafQueue: default used=<memory:2048, vCores:1> numContainers=1 user=root user-resources=<memory:2048, vCores:1>
2017-03-23 20:27:07,367 INFO org.apache.hadoop.yarn.server.resourcemanager.scheduler.capacity.LeafQueue: completedContainer container=Container: [ContainerId: container_1490313515759_0003_01_000004, NodeId: 240008d2487e:44869, NodeHttpAddress: 240008d2487e:8042, Resource: <memory:1024, vCores:1>, Priority: 10, Token: Token { kind: ContainerToken, service: 172.18.0.2:44869 }, ] queue=default: capacity=1.0, absoluteCapacity=1.0, usedResources=<memory:2048, vCores:1>, usedCapacity=0.25, absoluteUsedCapacity=0.25, numApps=1, numContainers=1 cluster=<memory:8192, vCores:8>
2017-03-23 20:27:07,367 INFO org.apache.hadoop.yarn.server.resourcemanager.scheduler.capacity.ParentQueue: completedContainer queue=root usedCapacity=0.25 absoluteUsedCapacity=0.25 used=<memory:2048, vCores:1> cluster=<memory:8192, vCores:8>
2017-03-23 20:27:07,367 INFO org.apache.hadoop.yarn.server.resourcemanager.scheduler.capacity.ParentQueue: Re-sorting completed queue: root.default stats: default: capacity=1.0, absoluteCapacity=1.0, usedResources=<memory:2048, vCores:1>, usedCapacity=0.25, absoluteUsedCapacity=0.25, numApps=1, numContainers=1
2017-03-23 20:27:07,367 INFO org.apache.hadoop.yarn.server.resourcemanager.scheduler.capacity.CapacityScheduler: Application attempt appattempt_1490313515759_0003_000001 released container container_1490313515759_0003_01_000004 on node: host: 240008d2487e:44869 #containers=1 available=<memory:6144, vCores:7> used=<memory:2048, vCores:1> with event: FINISHED
2017-03-23 20:27:07,755 INFO org.apache.hadoop.yarn.server.resourcemanager.ApplicationMasterService: application_1490313515759_0003 unregistered successfully. 
2017-03-23 20:27:13,383 INFO org.apache.hadoop.yarn.server.resourcemanager.rmcontainer.RMContainerImpl: container_1490313515759_0003_01_000001 Container Transitioned from RUNNING to COMPLETED
2017-03-23 20:27:13,383 INFO org.apache.hadoop.yarn.server.resourcemanager.ApplicationMasterService: Unregistering app attempt : appattempt_1490313515759_0003_000001
2017-03-23 20:27:13,383 INFO org.apache.hadoop.yarn.server.resourcemanager.scheduler.common.fica.FiCaSchedulerApp: Completed container: container_1490313515759_0003_01_000001 in state: COMPLETED event:FINISHED
2017-03-23 20:27:13,383 INFO org.apache.hadoop.yarn.server.resourcemanager.security.AMRMTokenSecretManager: Application finished, removing password for appattempt_1490313515759_0003_000001
2017-03-23 20:27:13,383 INFO org.apache.hadoop.yarn.server.resourcemanager.RMAuditLogger: USER=root	OPERATION=AM Released Container	TARGET=SchedulerApp	RESULT=SUCCESS	APPID=application_1490313515759_0003	CONTAINERID=container_1490313515759_0003_01_000001
2017-03-23 20:27:13,383 INFO org.apache.hadoop.yarn.server.resourcemanager.rmapp.attempt.RMAppAttemptImpl: appattempt_1490313515759_0003_000001 State change from FINISHING to FINISHED
2017-03-23 20:27:13,383 INFO org.apache.hadoop.yarn.server.resourcemanager.scheduler.SchedulerNode: Released container container_1490313515759_0003_01_000001 of capacity <memory:2048, vCores:1> on host 240008d2487e:44869, which currently has 0 containers, <memory:0, vCores:0> used and <memory:8192, vCores:8> available, release resources=true
2017-03-23 20:27:13,384 INFO org.apache.hadoop.yarn.server.resourcemanager.rmapp.RMAppImpl: application_1490313515759_0003 State change from FINISHING to FINISHED
2017-03-23 20:27:13,384 INFO org.apache.hadoop.yarn.server.resourcemanager.scheduler.capacity.LeafQueue: default used=<memory:0, vCores:0> numContainers=0 user=root user-resources=<memory:0, vCores:0>
2017-03-23 20:27:13,384 INFO org.apache.hadoop.yarn.server.resourcemanager.RMAuditLogger: USER=root	OPERATION=Application Finished - Succeeded	TARGET=RMAppManager	RESULT=SUCCESS	APPID=application_1490313515759_0003
2017-03-23 20:27:13,384 INFO org.apache.hadoop.yarn.server.resourcemanager.scheduler.capacity.LeafQueue: completedContainer container=Container: [ContainerId: container_1490313515759_0003_01_000001, NodeId: 240008d2487e:44869, NodeHttpAddress: 240008d2487e:8042, Resource: <memory:2048, vCores:1>, Priority: 0, Token: Token { kind: ContainerToken, service: 172.18.0.2:44869 }, ] queue=default: capacity=1.0, absoluteCapacity=1.0, usedResources=<memory:0, vCores:0>, usedCapacity=0.0, absoluteUsedCapacity=0.0, numApps=1, numContainers=0 cluster=<memory:8192, vCores:8>
2017-03-23 20:27:13,384 INFO org.apache.hadoop.yarn.server.resourcemanager.scheduler.capacity.ParentQueue: completedContainer queue=root usedCapacity=0.0 absoluteUsedCapacity=0.0 used=<memory:0, vCores:0> cluster=<memory:8192, vCores:8>
2017-03-23 20:27:13,384 INFO org.apache.hadoop.yarn.server.resourcemanager.scheduler.capacity.ParentQueue: Re-sorting completed queue: root.default stats: default: capacity=1.0, absoluteCapacity=1.0, usedResources=<memory:0, vCores:0>, usedCapacity=0.0, absoluteUsedCapacity=0.0, numApps=1, numContainers=0
2017-03-23 20:27:13,384 INFO org.apache.hadoop.yarn.server.resourcemanager.scheduler.capacity.CapacityScheduler: Application attempt appattempt_1490313515759_0003_000001 released container container_1490313515759_0003_01_000001 on node: host: 240008d2487e:44869 #containers=0 available=<memory:8192, vCores:8> used=<memory:0, vCores:0> with event: FINISHED
2017-03-23 20:27:13,384 INFO org.apache.hadoop.yarn.server.resourcemanager.scheduler.capacity.CapacityScheduler: Application Attempt appattempt_1490313515759_0003_000001 is done. finalState=FINISHED
2017-03-23 20:27:13,384 INFO org.apache.hadoop.yarn.server.resourcemanager.RMAppManager$ApplicationSummary: appId=application_1490313515759_0003,name=streamjob2314843683112097359.jar,user=root,queue=default,state=FINISHED,trackingUrl=http://240008d2487e:8088/proxy/application_1490313515759_0003/,appMasterHost=240008d2487e,startTime=1490315182591,finishTime=1490315226751,finalStatus=SUCCEEDED,memorySeconds=155924,vcoreSeconds=100,preemptedAMContainers=0,preemptedNonAMContainers=0,preemptedResources=<memory:0\, vCores:0>,applicationType=MAPREDUCE
2017-03-23 20:27:13,384 INFO org.apache.hadoop.yarn.server.resourcemanager.amlauncher.AMLauncher: Cleaning master appattempt_1490313515759_0003_000001
2017-03-23 20:27:13,384 INFO org.apache.hadoop.yarn.server.resourcemanager.scheduler.AppSchedulingInfo: Application application_1490313515759_0003 requests cleared
2017-03-23 20:27:13,385 INFO org.apache.hadoop.yarn.server.resourcemanager.scheduler.capacity.LeafQueue: Application removed - appId: application_1490313515759_0003 user: root queue: default #user-pending-applications: 0 #user-active-applications: 0 #queue-pending-applications: 0 #queue-active-applications: 0
2017-03-23 20:27:13,386 INFO org.apache.hadoop.yarn.server.resourcemanager.scheduler.capacity.ParentQueue: Application removed - appId: application_1490313515759_0003 user: root leaf-queue of parent: root #applications: 0
2017-03-23 20:27:14,410 INFO org.apache.hadoop.yarn.server.resourcemanager.scheduler.capacity.CapacityScheduler: Null container completed...
2017-03-23 20:29:39,529 INFO org.apache.hadoop.yarn.server.resourcemanager.ClientRMService: Allocated new applicationId: 4
2017-03-23 20:29:40,907 INFO org.apache.hadoop.yarn.server.resourcemanager.ClientRMService: Application with id 4 submitted by user root
2017-03-23 20:29:40,907 INFO org.apache.hadoop.yarn.server.resourcemanager.rmapp.RMAppImpl: Storing application with id application_1490313515759_0004
2017-03-23 20:29:40,908 INFO org.apache.hadoop.yarn.server.resourcemanager.RMAuditLogger: USER=root	IP=172.18.0.2	OPERATION=Submit Application Request	TARGET=ClientRMService	RESULT=SUCCESS	APPID=application_1490313515759_0004
2017-03-23 20:29:40,908 INFO org.apache.hadoop.yarn.server.resourcemanager.rmapp.RMAppImpl: application_1490313515759_0004 State change from NEW to NEW_SAVING
2017-03-23 20:29:40,908 INFO org.apache.hadoop.yarn.server.resourcemanager.recovery.RMStateStore: Storing info for app: application_1490313515759_0004
2017-03-23 20:29:40,908 INFO org.apache.hadoop.yarn.server.resourcemanager.rmapp.RMAppImpl: application_1490313515759_0004 State change from NEW_SAVING to SUBMITTED
2017-03-23 20:29:40,909 INFO org.apache.hadoop.yarn.server.resourcemanager.scheduler.capacity.ParentQueue: Application added - appId: application_1490313515759_0004 user: root leaf-queue of parent: root #applications: 1
2017-03-23 20:29:40,909 INFO org.apache.hadoop.yarn.server.resourcemanager.scheduler.capacity.CapacityScheduler: Accepted application application_1490313515759_0004 from user: root, in queue: default
2017-03-23 20:29:40,910 INFO org.apache.hadoop.yarn.server.resourcemanager.rmapp.RMAppImpl: application_1490313515759_0004 State change from SUBMITTED to ACCEPTED
2017-03-23 20:29:40,910 INFO org.apache.hadoop.yarn.server.resourcemanager.ApplicationMasterService: Registering app attempt : appattempt_1490313515759_0004_000001
2017-03-23 20:29:40,910 INFO org.apache.hadoop.yarn.server.resourcemanager.rmapp.attempt.RMAppAttemptImpl: appattempt_1490313515759_0004_000001 State change from NEW to SUBMITTED
2017-03-23 20:29:40,910 WARN org.apache.hadoop.yarn.server.resourcemanager.scheduler.capacity.LeafQueue: maximum-am-resource-percent is insufficient to start a single application in queue, it is likely set too low. skipping enforcement to allow at least one application to start
2017-03-23 20:29:40,910 WARN org.apache.hadoop.yarn.server.resourcemanager.scheduler.capacity.LeafQueue: maximum-am-resource-percent is insufficient to start a single application in queue for user, it is likely set too low. skipping enforcement to allow at least one application to start
2017-03-23 20:29:40,910 INFO org.apache.hadoop.yarn.server.resourcemanager.scheduler.capacity.LeafQueue: Application application_1490313515759_0004 from user: root activated in queue: default
2017-03-23 20:29:40,910 INFO org.apache.hadoop.yarn.server.resourcemanager.scheduler.capacity.LeafQueue: Application added - appId: application_1490313515759_0004 user: org.apache.hadoop.yarn.server.resourcemanager.scheduler.capacity.LeafQueue$User@12236bdc, leaf-queue: default #user-pending-applications: 0 #user-active-applications: 1 #queue-pending-applications: 0 #queue-active-applications: 1
2017-03-23 20:29:40,910 INFO org.apache.hadoop.yarn.server.resourcemanager.scheduler.capacity.CapacityScheduler: Added Application Attempt appattempt_1490313515759_0004_000001 to scheduler from user root in queue default
2017-03-23 20:29:40,911 INFO org.apache.hadoop.yarn.server.resourcemanager.rmapp.attempt.RMAppAttemptImpl: appattempt_1490313515759_0004_000001 State change from SUBMITTED to SCHEDULED
2017-03-23 20:29:41,774 INFO org.apache.hadoop.yarn.server.resourcemanager.rmcontainer.RMContainerImpl: container_1490313515759_0004_01_000001 Container Transitioned from NEW to ALLOCATED
2017-03-23 20:29:41,774 INFO org.apache.hadoop.yarn.server.resourcemanager.RMAuditLogger: USER=root	OPERATION=AM Allocated Container	TARGET=SchedulerApp	RESULT=SUCCESS	APPID=application_1490313515759_0004	CONTAINERID=container_1490313515759_0004_01_000001
2017-03-23 20:29:41,774 INFO org.apache.hadoop.yarn.server.resourcemanager.scheduler.SchedulerNode: Assigned container container_1490313515759_0004_01_000001 of capacity <memory:2048, vCores:1> on host 240008d2487e:44869, which has 1 containers, <memory:2048, vCores:1> used and <memory:6144, vCores:7> available after allocation
2017-03-23 20:29:41,774 INFO org.apache.hadoop.yarn.server.resourcemanager.scheduler.capacity.LeafQueue: assignedContainer application attempt=appattempt_1490313515759_0004_000001 container=Container: [ContainerId: container_1490313515759_0004_01_000001, NodeId: 240008d2487e:44869, NodeHttpAddress: 240008d2487e:8042, Resource: <memory:2048, vCores:1>, Priority: 0, Token: null, ] queue=default: capacity=1.0, absoluteCapacity=1.0, usedResources=<memory:0, vCores:0>, usedCapacity=0.0, absoluteUsedCapacity=0.0, numApps=1, numContainers=0 clusterResource=<memory:8192, vCores:8>
2017-03-23 20:29:41,774 INFO org.apache.hadoop.yarn.server.resourcemanager.scheduler.capacity.ParentQueue: Re-sorting assigned queue: root.default stats: default: capacity=1.0, absoluteCapacity=1.0, usedResources=<memory:2048, vCores:1>, usedCapacity=0.25, absoluteUsedCapacity=0.25, numApps=1, numContainers=1
2017-03-23 20:29:41,774 INFO org.apache.hadoop.yarn.server.resourcemanager.scheduler.capacity.ParentQueue: assignedContainer queue=root usedCapacity=0.25 absoluteUsedCapacity=0.25 used=<memory:2048, vCores:1> cluster=<memory:8192, vCores:8>
2017-03-23 20:29:41,776 INFO org.apache.hadoop.yarn.server.resourcemanager.security.NMTokenSecretManagerInRM: Sending NMToken for nodeId : 240008d2487e:44869 for container : container_1490313515759_0004_01_000001
2017-03-23 20:29:41,780 INFO org.apache.hadoop.yarn.server.resourcemanager.rmcontainer.RMContainerImpl: container_1490313515759_0004_01_000001 Container Transitioned from ALLOCATED to ACQUIRED
2017-03-23 20:29:41,780 INFO org.apache.hadoop.yarn.server.resourcemanager.security.NMTokenSecretManagerInRM: Clear node set for appattempt_1490313515759_0004_000001
2017-03-23 20:29:41,780 INFO org.apache.hadoop.yarn.server.resourcemanager.rmapp.attempt.RMAppAttemptImpl: Storing attempt: AppId: application_1490313515759_0004 AttemptId: appattempt_1490313515759_0004_000001 MasterContainer: Container: [ContainerId: container_1490313515759_0004_01_000001, NodeId: 240008d2487e:44869, NodeHttpAddress: 240008d2487e:8042, Resource: <memory:2048, vCores:1>, Priority: 0, Token: Token { kind: ContainerToken, service: 172.18.0.2:44869 }, ]
2017-03-23 20:29:41,780 INFO org.apache.hadoop.yarn.server.resourcemanager.rmapp.attempt.RMAppAttemptImpl: appattempt_1490313515759_0004_000001 State change from SCHEDULED to ALLOCATED_SAVING
2017-03-23 20:29:41,780 INFO org.apache.hadoop.yarn.server.resourcemanager.rmapp.attempt.RMAppAttemptImpl: appattempt_1490313515759_0004_000001 State change from ALLOCATED_SAVING to ALLOCATED
2017-03-23 20:29:41,781 INFO org.apache.hadoop.yarn.server.resourcemanager.amlauncher.AMLauncher: Launching masterappattempt_1490313515759_0004_000001
2017-03-23 20:29:41,784 INFO org.apache.hadoop.yarn.server.resourcemanager.amlauncher.AMLauncher: Setting up container Container: [ContainerId: container_1490313515759_0004_01_000001, NodeId: 240008d2487e:44869, NodeHttpAddress: 240008d2487e:8042, Resource: <memory:2048, vCores:1>, Priority: 0, Token: Token { kind: ContainerToken, service: 172.18.0.2:44869 }, ] for AM appattempt_1490313515759_0004_000001
2017-03-23 20:29:41,784 INFO org.apache.hadoop.yarn.server.resourcemanager.amlauncher.AMLauncher: Command to launch container container_1490313515759_0004_01_000001 : $JAVA_HOME/bin/java -Dlog4j.configuration=container-log4j.properties -Dyarn.app.container.log.dir=<LOG_DIR> -Dyarn.app.container.log.filesize=0 -Dhadoop.root.logger=INFO,CLA -Dhadoop.root.logfile=syslog  -Xmx1024m org.apache.hadoop.mapreduce.v2.app.MRAppMaster 1><LOG_DIR>/stdout 2><LOG_DIR>/stderr 
2017-03-23 20:29:41,784 INFO org.apache.hadoop.yarn.server.resourcemanager.security.AMRMTokenSecretManager: Create AMRMToken for ApplicationAttempt: appattempt_1490313515759_0004_000001
2017-03-23 20:29:41,784 INFO org.apache.hadoop.yarn.server.resourcemanager.security.AMRMTokenSecretManager: Creating password for appattempt_1490313515759_0004_000001
2017-03-23 20:29:41,798 INFO org.apache.hadoop.yarn.server.resourcemanager.amlauncher.AMLauncher: Done launching container Container: [ContainerId: container_1490313515759_0004_01_000001, NodeId: 240008d2487e:44869, NodeHttpAddress: 240008d2487e:8042, Resource: <memory:2048, vCores:1>, Priority: 0, Token: Token { kind: ContainerToken, service: 172.18.0.2:44869 }, ] for AM appattempt_1490313515759_0004_000001
2017-03-23 20:29:41,798 INFO org.apache.hadoop.yarn.server.resourcemanager.rmapp.attempt.RMAppAttemptImpl: appattempt_1490313515759_0004_000001 State change from ALLOCATED to LAUNCHED
2017-03-23 20:29:42,776 INFO org.apache.hadoop.yarn.server.resourcemanager.rmcontainer.RMContainerImpl: container_1490313515759_0004_01_000001 Container Transitioned from ACQUIRED to RUNNING
2017-03-23 20:29:46,923 INFO SecurityLogger.org.apache.hadoop.ipc.Server: Auth successful for appattempt_1490313515759_0004_000001 (auth:SIMPLE)
2017-03-23 20:29:46,928 INFO org.apache.hadoop.yarn.server.resourcemanager.ApplicationMasterService: AM registration appattempt_1490313515759_0004_000001
2017-03-23 20:29:46,928 INFO org.apache.hadoop.yarn.server.resourcemanager.RMAuditLogger: USER=root	IP=172.18.0.2	OPERATION=Register App Master	TARGET=ApplicationMasterService	RESULT=SUCCESS	APPID=application_1490313515759_0004	APPATTEMPTID=appattempt_1490313515759_0004_000001
2017-03-23 20:29:46,928 INFO org.apache.hadoop.yarn.server.resourcemanager.rmapp.attempt.RMAppAttemptImpl: appattempt_1490313515759_0004_000001 State change from LAUNCHED to RUNNING
2017-03-23 20:29:46,928 INFO org.apache.hadoop.yarn.server.resourcemanager.rmapp.RMAppImpl: application_1490313515759_0004 State change from ACCEPTED to RUNNING
2017-03-23 20:29:48,792 INFO org.apache.hadoop.yarn.server.resourcemanager.rmcontainer.RMContainerImpl: container_1490313515759_0004_01_000002 Container Transitioned from NEW to ALLOCATED
2017-03-23 20:29:48,792 INFO org.apache.hadoop.yarn.server.resourcemanager.RMAuditLogger: USER=root	OPERATION=AM Allocated Container	TARGET=SchedulerApp	RESULT=SUCCESS	APPID=application_1490313515759_0004	CONTAINERID=container_1490313515759_0004_01_000002
2017-03-23 20:29:48,792 INFO org.apache.hadoop.yarn.server.resourcemanager.scheduler.SchedulerNode: Assigned container container_1490313515759_0004_01_000002 of capacity <memory:1024, vCores:1> on host 240008d2487e:44869, which has 2 containers, <memory:3072, vCores:2> used and <memory:5120, vCores:6> available after allocation
2017-03-23 20:29:48,792 INFO org.apache.hadoop.yarn.server.resourcemanager.scheduler.capacity.LeafQueue: assignedContainer application attempt=appattempt_1490313515759_0004_000001 container=Container: [ContainerId: container_1490313515759_0004_01_000002, NodeId: 240008d2487e:44869, NodeHttpAddress: 240008d2487e:8042, Resource: <memory:1024, vCores:1>, Priority: 20, Token: null, ] queue=default: capacity=1.0, absoluteCapacity=1.0, usedResources=<memory:2048, vCores:1>, usedCapacity=0.25, absoluteUsedCapacity=0.25, numApps=1, numContainers=1 clusterResource=<memory:8192, vCores:8>
2017-03-23 20:29:48,793 INFO org.apache.hadoop.yarn.server.resourcemanager.scheduler.capacity.ParentQueue: Re-sorting assigned queue: root.default stats: default: capacity=1.0, absoluteCapacity=1.0, usedResources=<memory:3072, vCores:2>, usedCapacity=0.375, absoluteUsedCapacity=0.375, numApps=1, numContainers=2
2017-03-23 20:29:48,793 INFO org.apache.hadoop.yarn.server.resourcemanager.scheduler.capacity.ParentQueue: assignedContainer queue=root usedCapacity=0.375 absoluteUsedCapacity=0.375 used=<memory:3072, vCores:2> cluster=<memory:8192, vCores:8>
2017-03-23 20:29:48,793 INFO org.apache.hadoop.yarn.server.resourcemanager.rmcontainer.RMContainerImpl: container_1490313515759_0004_01_000003 Container Transitioned from NEW to ALLOCATED
2017-03-23 20:29:48,793 INFO org.apache.hadoop.yarn.server.resourcemanager.RMAuditLogger: USER=root	OPERATION=AM Allocated Container	TARGET=SchedulerApp	RESULT=SUCCESS	APPID=application_1490313515759_0004	CONTAINERID=container_1490313515759_0004_01_000003
2017-03-23 20:29:48,793 INFO org.apache.hadoop.yarn.server.resourcemanager.scheduler.SchedulerNode: Assigned container container_1490313515759_0004_01_000003 of capacity <memory:1024, vCores:1> on host 240008d2487e:44869, which has 3 containers, <memory:4096, vCores:3> used and <memory:4096, vCores:5> available after allocation
2017-03-23 20:29:48,793 INFO org.apache.hadoop.yarn.server.resourcemanager.scheduler.capacity.LeafQueue: assignedContainer application attempt=appattempt_1490313515759_0004_000001 container=Container: [ContainerId: container_1490313515759_0004_01_000003, NodeId: 240008d2487e:44869, NodeHttpAddress: 240008d2487e:8042, Resource: <memory:1024, vCores:1>, Priority: 20, Token: null, ] queue=default: capacity=1.0, absoluteCapacity=1.0, usedResources=<memory:3072, vCores:2>, usedCapacity=0.375, absoluteUsedCapacity=0.375, numApps=1, numContainers=2 clusterResource=<memory:8192, vCores:8>
2017-03-23 20:29:48,794 INFO org.apache.hadoop.yarn.server.resourcemanager.scheduler.capacity.ParentQueue: Re-sorting assigned queue: root.default stats: default: capacity=1.0, absoluteCapacity=1.0, usedResources=<memory:4096, vCores:3>, usedCapacity=0.5, absoluteUsedCapacity=0.5, numApps=1, numContainers=3
2017-03-23 20:29:48,794 INFO org.apache.hadoop.yarn.server.resourcemanager.scheduler.capacity.ParentQueue: assignedContainer queue=root usedCapacity=0.5 absoluteUsedCapacity=0.5 used=<memory:4096, vCores:3> cluster=<memory:8192, vCores:8>
2017-03-23 20:29:48,993 INFO org.apache.hadoop.yarn.server.resourcemanager.security.NMTokenSecretManagerInRM: Sending NMToken for nodeId : 240008d2487e:44869 for container : container_1490313515759_0004_01_000002
2017-03-23 20:29:48,995 INFO org.apache.hadoop.yarn.server.resourcemanager.rmcontainer.RMContainerImpl: container_1490313515759_0004_01_000002 Container Transitioned from ALLOCATED to ACQUIRED
2017-03-23 20:29:48,996 INFO org.apache.hadoop.yarn.server.resourcemanager.rmcontainer.RMContainerImpl: container_1490313515759_0004_01_000003 Container Transitioned from ALLOCATED to ACQUIRED
2017-03-23 20:29:49,796 INFO org.apache.hadoop.yarn.server.resourcemanager.rmcontainer.RMContainerImpl: container_1490313515759_0004_01_000002 Container Transitioned from ACQUIRED to RUNNING
2017-03-23 20:29:49,796 INFO org.apache.hadoop.yarn.server.resourcemanager.rmcontainer.RMContainerImpl: container_1490313515759_0004_01_000003 Container Transitioned from ACQUIRED to RUNNING
2017-03-23 20:29:50,012 INFO org.apache.hadoop.yarn.server.resourcemanager.scheduler.AppSchedulingInfo: checking for deactivate of application :application_1490313515759_0004
2017-03-23 20:30:05,188 INFO org.apache.hadoop.yarn.server.resourcemanager.rmcontainer.RMContainerImpl: container_1490313515759_0004_01_000003 Container Transitioned from RUNNING to COMPLETED
2017-03-23 20:30:05,188 INFO org.apache.hadoop.yarn.server.resourcemanager.scheduler.common.fica.FiCaSchedulerApp: Completed container: container_1490313515759_0004_01_000003 in state: COMPLETED event:FINISHED
2017-03-23 20:30:05,188 INFO org.apache.hadoop.yarn.server.resourcemanager.RMAuditLogger: USER=root	OPERATION=AM Released Container	TARGET=SchedulerApp	RESULT=SUCCESS	APPID=application_1490313515759_0004	CONTAINERID=container_1490313515759_0004_01_000003
2017-03-23 20:30:05,188 INFO org.apache.hadoop.yarn.server.resourcemanager.scheduler.SchedulerNode: Released container container_1490313515759_0004_01_000003 of capacity <memory:1024, vCores:1> on host 240008d2487e:44869, which currently has 2 containers, <memory:3072, vCores:2> used and <memory:5120, vCores:6> available, release resources=true
2017-03-23 20:30:05,189 INFO org.apache.hadoop.yarn.server.resourcemanager.scheduler.capacity.LeafQueue: default used=<memory:3072, vCores:2> numContainers=2 user=root user-resources=<memory:3072, vCores:2>
2017-03-23 20:30:05,189 INFO org.apache.hadoop.yarn.server.resourcemanager.scheduler.capacity.LeafQueue: completedContainer container=Container: [ContainerId: container_1490313515759_0004_01_000003, NodeId: 240008d2487e:44869, NodeHttpAddress: 240008d2487e:8042, Resource: <memory:1024, vCores:1>, Priority: 20, Token: Token { kind: ContainerToken, service: 172.18.0.2:44869 }, ] queue=default: capacity=1.0, absoluteCapacity=1.0, usedResources=<memory:3072, vCores:2>, usedCapacity=0.375, absoluteUsedCapacity=0.375, numApps=1, numContainers=2 cluster=<memory:8192, vCores:8>
2017-03-23 20:30:05,189 INFO org.apache.hadoop.yarn.server.resourcemanager.scheduler.capacity.ParentQueue: completedContainer queue=root usedCapacity=0.375 absoluteUsedCapacity=0.375 used=<memory:3072, vCores:2> cluster=<memory:8192, vCores:8>
2017-03-23 20:30:05,189 INFO org.apache.hadoop.yarn.server.resourcemanager.scheduler.capacity.ParentQueue: Re-sorting completed queue: root.default stats: default: capacity=1.0, absoluteCapacity=1.0, usedResources=<memory:3072, vCores:2>, usedCapacity=0.375, absoluteUsedCapacity=0.375, numApps=1, numContainers=2
2017-03-23 20:30:05,190 INFO org.apache.hadoop.yarn.server.resourcemanager.scheduler.capacity.CapacityScheduler: Application attempt appattempt_1490313515759_0004_000001 released container container_1490313515759_0004_01_000003 on node: host: 240008d2487e:44869 #containers=2 available=<memory:5120, vCores:6> used=<memory:3072, vCores:2> with event: FINISHED
2017-03-23 20:30:06,191 INFO org.apache.hadoop.yarn.server.resourcemanager.rmcontainer.RMContainerImpl: container_1490313515759_0004_01_000002 Container Transitioned from RUNNING to COMPLETED
2017-03-23 20:30:06,191 INFO org.apache.hadoop.yarn.server.resourcemanager.scheduler.common.fica.FiCaSchedulerApp: Completed container: container_1490313515759_0004_01_000002 in state: COMPLETED event:FINISHED
2017-03-23 20:30:06,191 INFO org.apache.hadoop.yarn.server.resourcemanager.RMAuditLogger: USER=root	OPERATION=AM Released Container	TARGET=SchedulerApp	RESULT=SUCCESS	APPID=application_1490313515759_0004	CONTAINERID=container_1490313515759_0004_01_000002
2017-03-23 20:30:06,191 INFO org.apache.hadoop.yarn.server.resourcemanager.scheduler.SchedulerNode: Released container container_1490313515759_0004_01_000002 of capacity <memory:1024, vCores:1> on host 240008d2487e:44869, which currently has 1 containers, <memory:2048, vCores:1> used and <memory:6144, vCores:7> available, release resources=true
2017-03-23 20:30:06,191 INFO org.apache.hadoop.yarn.server.resourcemanager.scheduler.capacity.LeafQueue: default used=<memory:2048, vCores:1> numContainers=1 user=root user-resources=<memory:2048, vCores:1>
2017-03-23 20:30:06,192 INFO org.apache.hadoop.yarn.server.resourcemanager.scheduler.capacity.LeafQueue: completedContainer container=Container: [ContainerId: container_1490313515759_0004_01_000002, NodeId: 240008d2487e:44869, NodeHttpAddress: 240008d2487e:8042, Resource: <memory:1024, vCores:1>, Priority: 20, Token: Token { kind: ContainerToken, service: 172.18.0.2:44869 }, ] queue=default: capacity=1.0, absoluteCapacity=1.0, usedResources=<memory:2048, vCores:1>, usedCapacity=0.25, absoluteUsedCapacity=0.25, numApps=1, numContainers=1 cluster=<memory:8192, vCores:8>
2017-03-23 20:30:06,192 INFO org.apache.hadoop.yarn.server.resourcemanager.scheduler.capacity.ParentQueue: completedContainer queue=root usedCapacity=0.25 absoluteUsedCapacity=0.25 used=<memory:2048, vCores:1> cluster=<memory:8192, vCores:8>
2017-03-23 20:30:06,192 INFO org.apache.hadoop.yarn.server.resourcemanager.scheduler.capacity.ParentQueue: Re-sorting completed queue: root.default stats: default: capacity=1.0, absoluteCapacity=1.0, usedResources=<memory:2048, vCores:1>, usedCapacity=0.25, absoluteUsedCapacity=0.25, numApps=1, numContainers=1
2017-03-23 20:30:06,192 INFO org.apache.hadoop.yarn.server.resourcemanager.scheduler.capacity.CapacityScheduler: Application attempt appattempt_1490313515759_0004_000001 released container container_1490313515759_0004_01_000002 on node: host: 240008d2487e:44869 #containers=1 available=<memory:6144, vCores:7> used=<memory:2048, vCores:1> with event: FINISHED
2017-03-23 20:30:06,193 INFO org.apache.hadoop.yarn.server.resourcemanager.rmcontainer.RMContainerImpl: container_1490313515759_0004_01_000004 Container Transitioned from NEW to ALLOCATED
2017-03-23 20:30:06,193 INFO org.apache.hadoop.yarn.server.resourcemanager.RMAuditLogger: USER=root	OPERATION=AM Allocated Container	TARGET=SchedulerApp	RESULT=SUCCESS	APPID=application_1490313515759_0004	CONTAINERID=container_1490313515759_0004_01_000004
2017-03-23 20:30:06,193 INFO org.apache.hadoop.yarn.server.resourcemanager.scheduler.SchedulerNode: Assigned container container_1490313515759_0004_01_000004 of capacity <memory:1024, vCores:1> on host 240008d2487e:44869, which has 2 containers, <memory:3072, vCores:2> used and <memory:5120, vCores:6> available after allocation
2017-03-23 20:30:06,193 INFO org.apache.hadoop.yarn.server.resourcemanager.scheduler.capacity.LeafQueue: assignedContainer application attempt=appattempt_1490313515759_0004_000001 container=Container: [ContainerId: container_1490313515759_0004_01_000004, NodeId: 240008d2487e:44869, NodeHttpAddress: 240008d2487e:8042, Resource: <memory:1024, vCores:1>, Priority: 10, Token: null, ] queue=default: capacity=1.0, absoluteCapacity=1.0, usedResources=<memory:2048, vCores:1>, usedCapacity=0.25, absoluteUsedCapacity=0.25, numApps=1, numContainers=1 clusterResource=<memory:8192, vCores:8>
2017-03-23 20:30:06,194 INFO org.apache.hadoop.yarn.server.resourcemanager.scheduler.capacity.ParentQueue: Re-sorting assigned queue: root.default stats: default: capacity=1.0, absoluteCapacity=1.0, usedResources=<memory:3072, vCores:2>, usedCapacity=0.375, absoluteUsedCapacity=0.375, numApps=1, numContainers=2
2017-03-23 20:30:06,194 INFO org.apache.hadoop.yarn.server.resourcemanager.scheduler.capacity.ParentQueue: assignedContainer queue=root usedCapacity=0.375 absoluteUsedCapacity=0.375 used=<memory:3072, vCores:2> cluster=<memory:8192, vCores:8>
2017-03-23 20:30:07,083 INFO org.apache.hadoop.yarn.server.resourcemanager.rmcontainer.RMContainerImpl: container_1490313515759_0004_01_000004 Container Transitioned from ALLOCATED to ACQUIRED
2017-03-23 20:30:07,193 INFO org.apache.hadoop.yarn.server.resourcemanager.rmcontainer.RMContainerImpl: container_1490313515759_0004_01_000004 Container Transitioned from ACQUIRED to RUNNING
2017-03-23 20:30:08,088 INFO org.apache.hadoop.yarn.server.resourcemanager.scheduler.AppSchedulingInfo: checking for deactivate of application :application_1490313515759_0004
2017-03-23 20:30:25,578 INFO org.apache.hadoop.yarn.server.resourcemanager.rmapp.attempt.RMAppAttemptImpl: Updating application attempt appattempt_1490313515759_0004_000001 with final state: FINISHING, and exit status: -1000
2017-03-23 20:30:25,578 INFO org.apache.hadoop.yarn.server.resourcemanager.rmapp.attempt.RMAppAttemptImpl: appattempt_1490313515759_0004_000001 State change from RUNNING to FINAL_SAVING
2017-03-23 20:30:25,578 INFO org.apache.hadoop.yarn.server.resourcemanager.rmapp.RMAppImpl: Updating application application_1490313515759_0004 with final state: FINISHING
2017-03-23 20:30:25,578 INFO org.apache.hadoop.yarn.server.resourcemanager.rmapp.RMAppImpl: application_1490313515759_0004 State change from RUNNING to FINAL_SAVING
2017-03-23 20:30:25,579 INFO org.apache.hadoop.yarn.server.resourcemanager.recovery.RMStateStore: Updating info for app: application_1490313515759_0004
2017-03-23 20:30:25,579 INFO org.apache.hadoop.yarn.server.resourcemanager.rmapp.attempt.RMAppAttemptImpl: appattempt_1490313515759_0004_000001 State change from FINAL_SAVING to FINISHING
2017-03-23 20:30:25,579 INFO org.apache.hadoop.yarn.server.resourcemanager.rmapp.RMAppImpl: application_1490313515759_0004 State change from FINAL_SAVING to FINISHING
2017-03-23 20:30:26,211 INFO org.apache.hadoop.yarn.server.resourcemanager.rmcontainer.RMContainerImpl: container_1490313515759_0004_01_000004 Container Transitioned from RUNNING to COMPLETED
2017-03-23 20:30:26,211 INFO org.apache.hadoop.yarn.server.resourcemanager.scheduler.common.fica.FiCaSchedulerApp: Completed container: container_1490313515759_0004_01_000004 in state: COMPLETED event:FINISHED
2017-03-23 20:30:26,211 INFO org.apache.hadoop.yarn.server.resourcemanager.RMAuditLogger: USER=root	OPERATION=AM Released Container	TARGET=SchedulerApp	RESULT=SUCCESS	APPID=application_1490313515759_0004	CONTAINERID=container_1490313515759_0004_01_000004
2017-03-23 20:30:26,211 INFO org.apache.hadoop.yarn.server.resourcemanager.scheduler.SchedulerNode: Released container container_1490313515759_0004_01_000004 of capacity <memory:1024, vCores:1> on host 240008d2487e:44869, which currently has 1 containers, <memory:2048, vCores:1> used and <memory:6144, vCores:7> available, release resources=true
2017-03-23 20:30:26,211 INFO org.apache.hadoop.yarn.server.resourcemanager.scheduler.capacity.LeafQueue: default used=<memory:2048, vCores:1> numContainers=1 user=root user-resources=<memory:2048, vCores:1>
2017-03-23 20:30:26,212 INFO org.apache.hadoop.yarn.server.resourcemanager.scheduler.capacity.LeafQueue: completedContainer container=Container: [ContainerId: container_1490313515759_0004_01_000004, NodeId: 240008d2487e:44869, NodeHttpAddress: 240008d2487e:8042, Resource: <memory:1024, vCores:1>, Priority: 10, Token: Token { kind: ContainerToken, service: 172.18.0.2:44869 }, ] queue=default: capacity=1.0, absoluteCapacity=1.0, usedResources=<memory:2048, vCores:1>, usedCapacity=0.25, absoluteUsedCapacity=0.25, numApps=1, numContainers=1 cluster=<memory:8192, vCores:8>
2017-03-23 20:30:26,212 INFO org.apache.hadoop.yarn.server.resourcemanager.scheduler.capacity.ParentQueue: completedContainer queue=root usedCapacity=0.25 absoluteUsedCapacity=0.25 used=<memory:2048, vCores:1> cluster=<memory:8192, vCores:8>
2017-03-23 20:30:26,212 INFO org.apache.hadoop.yarn.server.resourcemanager.scheduler.capacity.ParentQueue: Re-sorting completed queue: root.default stats: default: capacity=1.0, absoluteCapacity=1.0, usedResources=<memory:2048, vCores:1>, usedCapacity=0.25, absoluteUsedCapacity=0.25, numApps=1, numContainers=1
2017-03-23 20:30:26,212 INFO org.apache.hadoop.yarn.server.resourcemanager.scheduler.capacity.CapacityScheduler: Application attempt appattempt_1490313515759_0004_000001 released container container_1490313515759_0004_01_000004 on node: host: 240008d2487e:44869 #containers=1 available=<memory:6144, vCores:7> used=<memory:2048, vCores:1> with event: FINISHED
2017-03-23 20:30:26,582 INFO org.apache.hadoop.yarn.server.resourcemanager.ApplicationMasterService: application_1490313515759_0004 unregistered successfully. 
2017-03-23 20:30:32,227 INFO org.apache.hadoop.yarn.server.resourcemanager.rmcontainer.RMContainerImpl: container_1490313515759_0004_01_000001 Container Transitioned from RUNNING to COMPLETED
2017-03-23 20:30:32,227 INFO org.apache.hadoop.yarn.server.resourcemanager.ApplicationMasterService: Unregistering app attempt : appattempt_1490313515759_0004_000001
2017-03-23 20:30:32,227 INFO org.apache.hadoop.yarn.server.resourcemanager.scheduler.common.fica.FiCaSchedulerApp: Completed container: container_1490313515759_0004_01_000001 in state: COMPLETED event:FINISHED
2017-03-23 20:30:32,227 INFO org.apache.hadoop.yarn.server.resourcemanager.security.AMRMTokenSecretManager: Application finished, removing password for appattempt_1490313515759_0004_000001
2017-03-23 20:30:32,227 INFO org.apache.hadoop.yarn.server.resourcemanager.RMAuditLogger: USER=root	OPERATION=AM Released Container	TARGET=SchedulerApp	RESULT=SUCCESS	APPID=application_1490313515759_0004	CONTAINERID=container_1490313515759_0004_01_000001
2017-03-23 20:30:32,228 INFO org.apache.hadoop.yarn.server.resourcemanager.rmapp.attempt.RMAppAttemptImpl: appattempt_1490313515759_0004_000001 State change from FINISHING to FINISHED
2017-03-23 20:30:32,228 INFO org.apache.hadoop.yarn.server.resourcemanager.scheduler.SchedulerNode: Released container container_1490313515759_0004_01_000001 of capacity <memory:2048, vCores:1> on host 240008d2487e:44869, which currently has 0 containers, <memory:0, vCores:0> used and <memory:8192, vCores:8> available, release resources=true
2017-03-23 20:30:32,228 INFO org.apache.hadoop.yarn.server.resourcemanager.rmapp.RMAppImpl: application_1490313515759_0004 State change from FINISHING to FINISHED
2017-03-23 20:30:32,228 INFO org.apache.hadoop.yarn.server.resourcemanager.scheduler.capacity.LeafQueue: default used=<memory:0, vCores:0> numContainers=0 user=root user-resources=<memory:0, vCores:0>
2017-03-23 20:30:32,228 INFO org.apache.hadoop.yarn.server.resourcemanager.scheduler.capacity.LeafQueue: completedContainer container=Container: [ContainerId: container_1490313515759_0004_01_000001, NodeId: 240008d2487e:44869, NodeHttpAddress: 240008d2487e:8042, Resource: <memory:2048, vCores:1>, Priority: 0, Token: Token { kind: ContainerToken, service: 172.18.0.2:44869 }, ] queue=default: capacity=1.0, absoluteCapacity=1.0, usedResources=<memory:0, vCores:0>, usedCapacity=0.0, absoluteUsedCapacity=0.0, numApps=1, numContainers=0 cluster=<memory:8192, vCores:8>
2017-03-23 20:30:32,228 INFO org.apache.hadoop.yarn.server.resourcemanager.RMAuditLogger: USER=root	OPERATION=Application Finished - Succeeded	TARGET=RMAppManager	RESULT=SUCCESS	APPID=application_1490313515759_0004
2017-03-23 20:30:32,228 INFO org.apache.hadoop.yarn.server.resourcemanager.scheduler.capacity.ParentQueue: completedContainer queue=root usedCapacity=0.0 absoluteUsedCapacity=0.0 used=<memory:0, vCores:0> cluster=<memory:8192, vCores:8>
2017-03-23 20:30:32,230 INFO org.apache.hadoop.yarn.server.resourcemanager.scheduler.capacity.ParentQueue: Re-sorting completed queue: root.default stats: default: capacity=1.0, absoluteCapacity=1.0, usedResources=<memory:0, vCores:0>, usedCapacity=0.0, absoluteUsedCapacity=0.0, numApps=1, numContainers=0
2017-03-23 20:30:32,230 INFO org.apache.hadoop.yarn.server.resourcemanager.scheduler.capacity.CapacityScheduler: Application attempt appattempt_1490313515759_0004_000001 released container container_1490313515759_0004_01_000001 on node: host: 240008d2487e:44869 #containers=0 available=<memory:8192, vCores:8> used=<memory:0, vCores:0> with event: FINISHED
2017-03-23 20:30:32,230 INFO org.apache.hadoop.yarn.server.resourcemanager.amlauncher.AMLauncher: Cleaning master appattempt_1490313515759_0004_000001
2017-03-23 20:30:32,231 INFO org.apache.hadoop.yarn.server.resourcemanager.RMAppManager$ApplicationSummary: appId=application_1490313515759_0004,name=streamjob8882126929192787270.jar,user=root,queue=default,state=FINISHED,trackingUrl=http://240008d2487e:8088/proxy/application_1490313515759_0004/,appMasterHost=240008d2487e,startTime=1490315380907,finishTime=1490315425578,finalStatus=SUCCEEDED,memorySeconds=158431,vcoreSeconds=103,preemptedAMContainers=0,preemptedNonAMContainers=0,preemptedResources=<memory:0\, vCores:0>,applicationType=MAPREDUCE
2017-03-23 20:30:32,231 INFO org.apache.hadoop.yarn.server.resourcemanager.scheduler.capacity.CapacityScheduler: Application Attempt appattempt_1490313515759_0004_000001 is done. finalState=FINISHED
2017-03-23 20:30:32,231 INFO org.apache.hadoop.yarn.server.resourcemanager.scheduler.AppSchedulingInfo: Application application_1490313515759_0004 requests cleared
2017-03-23 20:30:32,231 INFO org.apache.hadoop.yarn.server.resourcemanager.scheduler.capacity.LeafQueue: Application removed - appId: application_1490313515759_0004 user: root queue: default #user-pending-applications: 0 #user-active-applications: 0 #queue-pending-applications: 0 #queue-active-applications: 0
2017-03-23 20:30:32,231 INFO org.apache.hadoop.yarn.server.resourcemanager.scheduler.capacity.ParentQueue: Application removed - appId: application_1490313515759_0004 user: root leaf-queue of parent: root #applications: 0
2017-03-23 20:30:33,246 INFO org.apache.hadoop.yarn.server.resourcemanager.scheduler.capacity.CapacityScheduler: Null container completed...
2017-03-23 20:31:35,835 INFO org.apache.hadoop.yarn.server.resourcemanager.ClientRMService: Allocated new applicationId: 5
2017-03-23 20:31:37,716 INFO org.apache.hadoop.yarn.server.resourcemanager.ClientRMService: Application with id 5 submitted by user root
2017-03-23 20:31:37,717 INFO org.apache.hadoop.yarn.server.resourcemanager.RMAuditLogger: USER=root	IP=172.18.0.2	OPERATION=Submit Application Request	TARGET=ClientRMService	RESULT=SUCCESS	APPID=application_1490313515759_0005
2017-03-23 20:31:37,717 INFO org.apache.hadoop.yarn.server.resourcemanager.rmapp.RMAppImpl: Storing application with id application_1490313515759_0005
2017-03-23 20:31:37,717 INFO org.apache.hadoop.yarn.server.resourcemanager.rmapp.RMAppImpl: application_1490313515759_0005 State change from NEW to NEW_SAVING
2017-03-23 20:31:37,717 INFO org.apache.hadoop.yarn.server.resourcemanager.recovery.RMStateStore: Storing info for app: application_1490313515759_0005
2017-03-23 20:31:37,718 INFO org.apache.hadoop.yarn.server.resourcemanager.rmapp.RMAppImpl: application_1490313515759_0005 State change from NEW_SAVING to SUBMITTED
2017-03-23 20:31:37,718 INFO org.apache.hadoop.yarn.server.resourcemanager.scheduler.capacity.ParentQueue: Application added - appId: application_1490313515759_0005 user: root leaf-queue of parent: root #applications: 1
2017-03-23 20:31:37,718 INFO org.apache.hadoop.yarn.server.resourcemanager.scheduler.capacity.CapacityScheduler: Accepted application application_1490313515759_0005 from user: root, in queue: default
2017-03-23 20:31:37,719 INFO org.apache.hadoop.yarn.server.resourcemanager.rmapp.RMAppImpl: application_1490313515759_0005 State change from SUBMITTED to ACCEPTED
2017-03-23 20:31:37,719 INFO org.apache.hadoop.yarn.server.resourcemanager.ApplicationMasterService: Registering app attempt : appattempt_1490313515759_0005_000001
2017-03-23 20:31:37,719 INFO org.apache.hadoop.yarn.server.resourcemanager.rmapp.attempt.RMAppAttemptImpl: appattempt_1490313515759_0005_000001 State change from NEW to SUBMITTED
2017-03-23 20:31:37,719 WARN org.apache.hadoop.yarn.server.resourcemanager.scheduler.capacity.LeafQueue: maximum-am-resource-percent is insufficient to start a single application in queue, it is likely set too low. skipping enforcement to allow at least one application to start
2017-03-23 20:31:37,719 WARN org.apache.hadoop.yarn.server.resourcemanager.scheduler.capacity.LeafQueue: maximum-am-resource-percent is insufficient to start a single application in queue for user, it is likely set too low. skipping enforcement to allow at least one application to start
2017-03-23 20:31:37,719 INFO org.apache.hadoop.yarn.server.resourcemanager.scheduler.capacity.LeafQueue: Application application_1490313515759_0005 from user: root activated in queue: default
2017-03-23 20:31:37,720 INFO org.apache.hadoop.yarn.server.resourcemanager.scheduler.capacity.LeafQueue: Application added - appId: application_1490313515759_0005 user: org.apache.hadoop.yarn.server.resourcemanager.scheduler.capacity.LeafQueue$User@4e9848f2, leaf-queue: default #user-pending-applications: 0 #user-active-applications: 1 #queue-pending-applications: 0 #queue-active-applications: 1
2017-03-23 20:31:37,720 INFO org.apache.hadoop.yarn.server.resourcemanager.scheduler.capacity.CapacityScheduler: Added Application Attempt appattempt_1490313515759_0005_000001 to scheduler from user root in queue default
2017-03-23 20:31:37,721 INFO org.apache.hadoop.yarn.server.resourcemanager.rmapp.attempt.RMAppAttemptImpl: appattempt_1490313515759_0005_000001 State change from SUBMITTED to SCHEDULED
2017-03-23 20:31:38,402 INFO org.apache.hadoop.yarn.server.resourcemanager.rmcontainer.RMContainerImpl: container_1490313515759_0005_01_000001 Container Transitioned from NEW to ALLOCATED
2017-03-23 20:31:38,403 INFO org.apache.hadoop.yarn.server.resourcemanager.RMAuditLogger: USER=root	OPERATION=AM Allocated Container	TARGET=SchedulerApp	RESULT=SUCCESS	APPID=application_1490313515759_0005	CONTAINERID=container_1490313515759_0005_01_000001
2017-03-23 20:31:38,403 INFO org.apache.hadoop.yarn.server.resourcemanager.scheduler.SchedulerNode: Assigned container container_1490313515759_0005_01_000001 of capacity <memory:2048, vCores:1> on host 240008d2487e:44869, which has 1 containers, <memory:2048, vCores:1> used and <memory:6144, vCores:7> available after allocation
2017-03-23 20:31:38,403 INFO org.apache.hadoop.yarn.server.resourcemanager.scheduler.capacity.LeafQueue: assignedContainer application attempt=appattempt_1490313515759_0005_000001 container=Container: [ContainerId: container_1490313515759_0005_01_000001, NodeId: 240008d2487e:44869, NodeHttpAddress: 240008d2487e:8042, Resource: <memory:2048, vCores:1>, Priority: 0, Token: null, ] queue=default: capacity=1.0, absoluteCapacity=1.0, usedResources=<memory:0, vCores:0>, usedCapacity=0.0, absoluteUsedCapacity=0.0, numApps=1, numContainers=0 clusterResource=<memory:8192, vCores:8>
2017-03-23 20:31:38,403 INFO org.apache.hadoop.yarn.server.resourcemanager.scheduler.capacity.ParentQueue: Re-sorting assigned queue: root.default stats: default: capacity=1.0, absoluteCapacity=1.0, usedResources=<memory:2048, vCores:1>, usedCapacity=0.25, absoluteUsedCapacity=0.25, numApps=1, numContainers=1
2017-03-23 20:31:38,403 INFO org.apache.hadoop.yarn.server.resourcemanager.scheduler.capacity.ParentQueue: assignedContainer queue=root usedCapacity=0.25 absoluteUsedCapacity=0.25 used=<memory:2048, vCores:1> cluster=<memory:8192, vCores:8>
2017-03-23 20:31:38,404 INFO org.apache.hadoop.yarn.server.resourcemanager.security.NMTokenSecretManagerInRM: Sending NMToken for nodeId : 240008d2487e:44869 for container : container_1490313515759_0005_01_000001
2017-03-23 20:31:38,406 INFO org.apache.hadoop.yarn.server.resourcemanager.rmcontainer.RMContainerImpl: container_1490313515759_0005_01_000001 Container Transitioned from ALLOCATED to ACQUIRED
2017-03-23 20:31:38,406 INFO org.apache.hadoop.yarn.server.resourcemanager.security.NMTokenSecretManagerInRM: Clear node set for appattempt_1490313515759_0005_000001
2017-03-23 20:31:38,406 INFO org.apache.hadoop.yarn.server.resourcemanager.rmapp.attempt.RMAppAttemptImpl: Storing attempt: AppId: application_1490313515759_0005 AttemptId: appattempt_1490313515759_0005_000001 MasterContainer: Container: [ContainerId: container_1490313515759_0005_01_000001, NodeId: 240008d2487e:44869, NodeHttpAddress: 240008d2487e:8042, Resource: <memory:2048, vCores:1>, Priority: 0, Token: Token { kind: ContainerToken, service: 172.18.0.2:44869 }, ]
2017-03-23 20:31:38,406 INFO org.apache.hadoop.yarn.server.resourcemanager.rmapp.attempt.RMAppAttemptImpl: appattempt_1490313515759_0005_000001 State change from SCHEDULED to ALLOCATED_SAVING
2017-03-23 20:31:38,407 INFO org.apache.hadoop.yarn.server.resourcemanager.rmapp.attempt.RMAppAttemptImpl: appattempt_1490313515759_0005_000001 State change from ALLOCATED_SAVING to ALLOCATED
2017-03-23 20:31:38,407 INFO org.apache.hadoop.yarn.server.resourcemanager.amlauncher.AMLauncher: Launching masterappattempt_1490313515759_0005_000001
2017-03-23 20:31:38,410 INFO org.apache.hadoop.yarn.server.resourcemanager.amlauncher.AMLauncher: Setting up container Container: [ContainerId: container_1490313515759_0005_01_000001, NodeId: 240008d2487e:44869, NodeHttpAddress: 240008d2487e:8042, Resource: <memory:2048, vCores:1>, Priority: 0, Token: Token { kind: ContainerToken, service: 172.18.0.2:44869 }, ] for AM appattempt_1490313515759_0005_000001
2017-03-23 20:31:38,410 INFO org.apache.hadoop.yarn.server.resourcemanager.amlauncher.AMLauncher: Command to launch container container_1490313515759_0005_01_000001 : $JAVA_HOME/bin/java -Dlog4j.configuration=container-log4j.properties -Dyarn.app.container.log.dir=<LOG_DIR> -Dyarn.app.container.log.filesize=0 -Dhadoop.root.logger=INFO,CLA -Dhadoop.root.logfile=syslog  -Xmx1024m org.apache.hadoop.mapreduce.v2.app.MRAppMaster 1><LOG_DIR>/stdout 2><LOG_DIR>/stderr 
2017-03-23 20:31:38,410 INFO org.apache.hadoop.yarn.server.resourcemanager.security.AMRMTokenSecretManager: Create AMRMToken for ApplicationAttempt: appattempt_1490313515759_0005_000001
2017-03-23 20:31:38,410 INFO org.apache.hadoop.yarn.server.resourcemanager.security.AMRMTokenSecretManager: Creating password for appattempt_1490313515759_0005_000001
2017-03-23 20:31:38,424 INFO org.apache.hadoop.yarn.server.resourcemanager.amlauncher.AMLauncher: Done launching container Container: [ContainerId: container_1490313515759_0005_01_000001, NodeId: 240008d2487e:44869, NodeHttpAddress: 240008d2487e:8042, Resource: <memory:2048, vCores:1>, Priority: 0, Token: Token { kind: ContainerToken, service: 172.18.0.2:44869 }, ] for AM appattempt_1490313515759_0005_000001
2017-03-23 20:31:38,425 INFO org.apache.hadoop.yarn.server.resourcemanager.rmapp.attempt.RMAppAttemptImpl: appattempt_1490313515759_0005_000001 State change from ALLOCATED to LAUNCHED
2017-03-23 20:31:39,405 INFO org.apache.hadoop.yarn.server.resourcemanager.rmcontainer.RMContainerImpl: container_1490313515759_0005_01_000001 Container Transitioned from ACQUIRED to RUNNING
2017-03-23 20:31:43,435 INFO SecurityLogger.org.apache.hadoop.ipc.Server: Auth successful for appattempt_1490313515759_0005_000001 (auth:SIMPLE)
2017-03-23 20:31:43,441 INFO org.apache.hadoop.yarn.server.resourcemanager.ApplicationMasterService: AM registration appattempt_1490313515759_0005_000001
2017-03-23 20:31:43,441 INFO org.apache.hadoop.yarn.server.resourcemanager.RMAuditLogger: USER=root	IP=172.18.0.2	OPERATION=Register App Master	TARGET=ApplicationMasterService	RESULT=SUCCESS	APPID=application_1490313515759_0005	APPATTEMPTID=appattempt_1490313515759_0005_000001
2017-03-23 20:31:43,441 INFO org.apache.hadoop.yarn.server.resourcemanager.rmapp.attempt.RMAppAttemptImpl: appattempt_1490313515759_0005_000001 State change from LAUNCHED to RUNNING
2017-03-23 20:31:43,441 INFO org.apache.hadoop.yarn.server.resourcemanager.rmapp.RMAppImpl: application_1490313515759_0005 State change from ACCEPTED to RUNNING
2017-03-23 20:31:45,422 INFO org.apache.hadoop.yarn.server.resourcemanager.rmcontainer.RMContainerImpl: container_1490313515759_0005_01_000002 Container Transitioned from NEW to ALLOCATED
2017-03-23 20:31:45,423 INFO org.apache.hadoop.yarn.server.resourcemanager.RMAuditLogger: USER=root	OPERATION=AM Allocated Container	TARGET=SchedulerApp	RESULT=SUCCESS	APPID=application_1490313515759_0005	CONTAINERID=container_1490313515759_0005_01_000002
2017-03-23 20:31:45,423 INFO org.apache.hadoop.yarn.server.resourcemanager.scheduler.SchedulerNode: Assigned container container_1490313515759_0005_01_000002 of capacity <memory:1024, vCores:1> on host 240008d2487e:44869, which has 2 containers, <memory:3072, vCores:2> used and <memory:5120, vCores:6> available after allocation
2017-03-23 20:31:45,423 INFO org.apache.hadoop.yarn.server.resourcemanager.scheduler.capacity.LeafQueue: assignedContainer application attempt=appattempt_1490313515759_0005_000001 container=Container: [ContainerId: container_1490313515759_0005_01_000002, NodeId: 240008d2487e:44869, NodeHttpAddress: 240008d2487e:8042, Resource: <memory:1024, vCores:1>, Priority: 20, Token: null, ] queue=default: capacity=1.0, absoluteCapacity=1.0, usedResources=<memory:2048, vCores:1>, usedCapacity=0.25, absoluteUsedCapacity=0.25, numApps=1, numContainers=1 clusterResource=<memory:8192, vCores:8>
2017-03-23 20:31:45,423 INFO org.apache.hadoop.yarn.server.resourcemanager.scheduler.capacity.ParentQueue: Re-sorting assigned queue: root.default stats: default: capacity=1.0, absoluteCapacity=1.0, usedResources=<memory:3072, vCores:2>, usedCapacity=0.375, absoluteUsedCapacity=0.375, numApps=1, numContainers=2
2017-03-23 20:31:45,423 INFO org.apache.hadoop.yarn.server.resourcemanager.scheduler.capacity.ParentQueue: assignedContainer queue=root usedCapacity=0.375 absoluteUsedCapacity=0.375 used=<memory:3072, vCores:2> cluster=<memory:8192, vCores:8>
2017-03-23 20:31:45,423 INFO org.apache.hadoop.yarn.server.resourcemanager.rmcontainer.RMContainerImpl: container_1490313515759_0005_01_000003 Container Transitioned from NEW to ALLOCATED
2017-03-23 20:31:45,424 INFO org.apache.hadoop.yarn.server.resourcemanager.RMAuditLogger: USER=root	OPERATION=AM Allocated Container	TARGET=SchedulerApp	RESULT=SUCCESS	APPID=application_1490313515759_0005	CONTAINERID=container_1490313515759_0005_01_000003
2017-03-23 20:31:45,424 INFO org.apache.hadoop.yarn.server.resourcemanager.scheduler.SchedulerNode: Assigned container container_1490313515759_0005_01_000003 of capacity <memory:1024, vCores:1> on host 240008d2487e:44869, which has 3 containers, <memory:4096, vCores:3> used and <memory:4096, vCores:5> available after allocation
2017-03-23 20:31:45,424 INFO org.apache.hadoop.yarn.server.resourcemanager.scheduler.capacity.LeafQueue: assignedContainer application attempt=appattempt_1490313515759_0005_000001 container=Container: [ContainerId: container_1490313515759_0005_01_000003, NodeId: 240008d2487e:44869, NodeHttpAddress: 240008d2487e:8042, Resource: <memory:1024, vCores:1>, Priority: 20, Token: null, ] queue=default: capacity=1.0, absoluteCapacity=1.0, usedResources=<memory:3072, vCores:2>, usedCapacity=0.375, absoluteUsedCapacity=0.375, numApps=1, numContainers=2 clusterResource=<memory:8192, vCores:8>
2017-03-23 20:31:45,424 INFO org.apache.hadoop.yarn.server.resourcemanager.scheduler.capacity.ParentQueue: Re-sorting assigned queue: root.default stats: default: capacity=1.0, absoluteCapacity=1.0, usedResources=<memory:4096, vCores:3>, usedCapacity=0.5, absoluteUsedCapacity=0.5, numApps=1, numContainers=3
2017-03-23 20:31:45,424 INFO org.apache.hadoop.yarn.server.resourcemanager.scheduler.capacity.ParentQueue: assignedContainer queue=root usedCapacity=0.5 absoluteUsedCapacity=0.5 used=<memory:4096, vCores:3> cluster=<memory:8192, vCores:8>
2017-03-23 20:31:45,540 INFO org.apache.hadoop.yarn.server.resourcemanager.security.NMTokenSecretManagerInRM: Sending NMToken for nodeId : 240008d2487e:44869 for container : container_1490313515759_0005_01_000002
2017-03-23 20:31:45,542 INFO org.apache.hadoop.yarn.server.resourcemanager.rmcontainer.RMContainerImpl: container_1490313515759_0005_01_000002 Container Transitioned from ALLOCATED to ACQUIRED
2017-03-23 20:31:45,543 INFO org.apache.hadoop.yarn.server.resourcemanager.rmcontainer.RMContainerImpl: container_1490313515759_0005_01_000003 Container Transitioned from ALLOCATED to ACQUIRED
2017-03-23 20:31:46,424 INFO org.apache.hadoop.yarn.server.resourcemanager.rmcontainer.RMContainerImpl: container_1490313515759_0005_01_000002 Container Transitioned from ACQUIRED to RUNNING
2017-03-23 20:31:46,425 INFO org.apache.hadoop.yarn.server.resourcemanager.rmcontainer.RMContainerImpl: container_1490313515759_0005_01_000003 Container Transitioned from ACQUIRED to RUNNING
2017-03-23 20:31:46,559 INFO org.apache.hadoop.yarn.server.resourcemanager.scheduler.AppSchedulingInfo: checking for deactivate of application :application_1490313515759_0005
2017-03-23 20:31:59,888 INFO org.apache.hadoop.yarn.server.resourcemanager.rmcontainer.RMContainerImpl: container_1490313515759_0005_01_000002 Container Transitioned from RUNNING to COMPLETED
2017-03-23 20:31:59,888 INFO org.apache.hadoop.yarn.server.resourcemanager.scheduler.common.fica.FiCaSchedulerApp: Completed container: container_1490313515759_0005_01_000002 in state: COMPLETED event:FINISHED
2017-03-23 20:31:59,888 INFO org.apache.hadoop.yarn.server.resourcemanager.RMAuditLogger: USER=root	OPERATION=AM Released Container	TARGET=SchedulerApp	RESULT=SUCCESS	APPID=application_1490313515759_0005	CONTAINERID=container_1490313515759_0005_01_000002
2017-03-23 20:31:59,888 INFO org.apache.hadoop.yarn.server.resourcemanager.scheduler.SchedulerNode: Released container container_1490313515759_0005_01_000002 of capacity <memory:1024, vCores:1> on host 240008d2487e:44869, which currently has 2 containers, <memory:3072, vCores:2> used and <memory:5120, vCores:6> available, release resources=true
2017-03-23 20:31:59,888 INFO org.apache.hadoop.yarn.server.resourcemanager.scheduler.capacity.LeafQueue: default used=<memory:3072, vCores:2> numContainers=2 user=root user-resources=<memory:3072, vCores:2>
2017-03-23 20:31:59,889 INFO org.apache.hadoop.yarn.server.resourcemanager.scheduler.capacity.LeafQueue: completedContainer container=Container: [ContainerId: container_1490313515759_0005_01_000002, NodeId: 240008d2487e:44869, NodeHttpAddress: 240008d2487e:8042, Resource: <memory:1024, vCores:1>, Priority: 20, Token: Token { kind: ContainerToken, service: 172.18.0.2:44869 }, ] queue=default: capacity=1.0, absoluteCapacity=1.0, usedResources=<memory:3072, vCores:2>, usedCapacity=0.375, absoluteUsedCapacity=0.375, numApps=1, numContainers=2 cluster=<memory:8192, vCores:8>
2017-03-23 20:31:59,889 INFO org.apache.hadoop.yarn.server.resourcemanager.scheduler.capacity.ParentQueue: completedContainer queue=root usedCapacity=0.375 absoluteUsedCapacity=0.375 used=<memory:3072, vCores:2> cluster=<memory:8192, vCores:8>
2017-03-23 20:31:59,889 INFO org.apache.hadoop.yarn.server.resourcemanager.scheduler.capacity.ParentQueue: Re-sorting completed queue: root.default stats: default: capacity=1.0, absoluteCapacity=1.0, usedResources=<memory:3072, vCores:2>, usedCapacity=0.375, absoluteUsedCapacity=0.375, numApps=1, numContainers=2
2017-03-23 20:31:59,889 INFO org.apache.hadoop.yarn.server.resourcemanager.scheduler.capacity.CapacityScheduler: Application attempt appattempt_1490313515759_0005_000001 released container container_1490313515759_0005_01_000002 on node: host: 240008d2487e:44869 #containers=2 available=<memory:5120, vCores:6> used=<memory:3072, vCores:2> with event: FINISHED
2017-03-23 20:32:00,890 INFO org.apache.hadoop.yarn.server.resourcemanager.rmcontainer.RMContainerImpl: container_1490313515759_0005_01_000003 Container Transitioned from RUNNING to COMPLETED
2017-03-23 20:32:00,891 INFO org.apache.hadoop.yarn.server.resourcemanager.scheduler.common.fica.FiCaSchedulerApp: Completed container: container_1490313515759_0005_01_000003 in state: COMPLETED event:FINISHED
2017-03-23 20:32:00,891 INFO org.apache.hadoop.yarn.server.resourcemanager.RMAuditLogger: USER=root	OPERATION=AM Released Container	TARGET=SchedulerApp	RESULT=SUCCESS	APPID=application_1490313515759_0005	CONTAINERID=container_1490313515759_0005_01_000003
2017-03-23 20:32:00,891 INFO org.apache.hadoop.yarn.server.resourcemanager.scheduler.SchedulerNode: Released container container_1490313515759_0005_01_000003 of capacity <memory:1024, vCores:1> on host 240008d2487e:44869, which currently has 1 containers, <memory:2048, vCores:1> used and <memory:6144, vCores:7> available, release resources=true
2017-03-23 20:32:00,891 INFO org.apache.hadoop.yarn.server.resourcemanager.scheduler.capacity.LeafQueue: default used=<memory:2048, vCores:1> numContainers=1 user=root user-resources=<memory:2048, vCores:1>
2017-03-23 20:32:00,891 INFO org.apache.hadoop.yarn.server.resourcemanager.scheduler.capacity.LeafQueue: completedContainer container=Container: [ContainerId: container_1490313515759_0005_01_000003, NodeId: 240008d2487e:44869, NodeHttpAddress: 240008d2487e:8042, Resource: <memory:1024, vCores:1>, Priority: 20, Token: Token { kind: ContainerToken, service: 172.18.0.2:44869 }, ] queue=default: capacity=1.0, absoluteCapacity=1.0, usedResources=<memory:2048, vCores:1>, usedCapacity=0.25, absoluteUsedCapacity=0.25, numApps=1, numContainers=1 cluster=<memory:8192, vCores:8>
2017-03-23 20:32:00,891 INFO org.apache.hadoop.yarn.server.resourcemanager.scheduler.capacity.ParentQueue: completedContainer queue=root usedCapacity=0.25 absoluteUsedCapacity=0.25 used=<memory:2048, vCores:1> cluster=<memory:8192, vCores:8>
2017-03-23 20:32:00,891 INFO org.apache.hadoop.yarn.server.resourcemanager.scheduler.capacity.ParentQueue: Re-sorting completed queue: root.default stats: default: capacity=1.0, absoluteCapacity=1.0, usedResources=<memory:2048, vCores:1>, usedCapacity=0.25, absoluteUsedCapacity=0.25, numApps=1, numContainers=1
2017-03-23 20:32:00,892 INFO org.apache.hadoop.yarn.server.resourcemanager.scheduler.capacity.CapacityScheduler: Application attempt appattempt_1490313515759_0005_000001 released container container_1490313515759_0005_01_000003 on node: host: 240008d2487e:44869 #containers=1 available=<memory:6144, vCores:7> used=<memory:2048, vCores:1> with event: FINISHED
2017-03-23 20:32:01,895 INFO org.apache.hadoop.yarn.server.resourcemanager.rmcontainer.RMContainerImpl: container_1490313515759_0005_01_000004 Container Transitioned from NEW to ALLOCATED
2017-03-23 20:32:01,895 INFO org.apache.hadoop.yarn.server.resourcemanager.RMAuditLogger: USER=root	OPERATION=AM Allocated Container	TARGET=SchedulerApp	RESULT=SUCCESS	APPID=application_1490313515759_0005	CONTAINERID=container_1490313515759_0005_01_000004
2017-03-23 20:32:01,895 INFO org.apache.hadoop.yarn.server.resourcemanager.scheduler.SchedulerNode: Assigned container container_1490313515759_0005_01_000004 of capacity <memory:1024, vCores:1> on host 240008d2487e:44869, which has 2 containers, <memory:3072, vCores:2> used and <memory:5120, vCores:6> available after allocation
2017-03-23 20:32:01,895 INFO org.apache.hadoop.yarn.server.resourcemanager.scheduler.capacity.LeafQueue: assignedContainer application attempt=appattempt_1490313515759_0005_000001 container=Container: [ContainerId: container_1490313515759_0005_01_000004, NodeId: 240008d2487e:44869, NodeHttpAddress: 240008d2487e:8042, Resource: <memory:1024, vCores:1>, Priority: 10, Token: null, ] queue=default: capacity=1.0, absoluteCapacity=1.0, usedResources=<memory:2048, vCores:1>, usedCapacity=0.25, absoluteUsedCapacity=0.25, numApps=1, numContainers=1 clusterResource=<memory:8192, vCores:8>
2017-03-23 20:32:01,895 INFO org.apache.hadoop.yarn.server.resourcemanager.scheduler.capacity.ParentQueue: Re-sorting assigned queue: root.default stats: default: capacity=1.0, absoluteCapacity=1.0, usedResources=<memory:3072, vCores:2>, usedCapacity=0.375, absoluteUsedCapacity=0.375, numApps=1, numContainers=2
2017-03-23 20:32:01,895 INFO org.apache.hadoop.yarn.server.resourcemanager.scheduler.capacity.ParentQueue: assignedContainer queue=root usedCapacity=0.375 absoluteUsedCapacity=0.375 used=<memory:3072, vCores:2> cluster=<memory:8192, vCores:8>
2017-03-23 20:32:02,624 INFO org.apache.hadoop.yarn.server.resourcemanager.rmcontainer.RMContainerImpl: container_1490313515759_0005_01_000004 Container Transitioned from ALLOCATED to ACQUIRED
2017-03-23 20:32:02,898 INFO org.apache.hadoop.yarn.server.resourcemanager.rmcontainer.RMContainerImpl: container_1490313515759_0005_01_000004 Container Transitioned from ACQUIRED to RUNNING
2017-03-23 20:32:03,630 INFO org.apache.hadoop.yarn.server.resourcemanager.scheduler.AppSchedulingInfo: checking for deactivate of application :application_1490313515759_0005
2017-03-23 20:32:23,277 INFO org.apache.hadoop.yarn.server.resourcemanager.rmapp.attempt.RMAppAttemptImpl: Updating application attempt appattempt_1490313515759_0005_000001 with final state: FINISHING, and exit status: -1000
2017-03-23 20:32:23,277 INFO org.apache.hadoop.yarn.server.resourcemanager.rmapp.attempt.RMAppAttemptImpl: appattempt_1490313515759_0005_000001 State change from RUNNING to FINAL_SAVING
2017-03-23 20:32:23,277 INFO org.apache.hadoop.yarn.server.resourcemanager.rmapp.RMAppImpl: Updating application application_1490313515759_0005 with final state: FINISHING
2017-03-23 20:32:23,277 INFO org.apache.hadoop.yarn.server.resourcemanager.rmapp.RMAppImpl: application_1490313515759_0005 State change from RUNNING to FINAL_SAVING
2017-03-23 20:32:23,277 INFO org.apache.hadoop.yarn.server.resourcemanager.recovery.RMStateStore: Updating info for app: application_1490313515759_0005
2017-03-23 20:32:23,278 INFO org.apache.hadoop.yarn.server.resourcemanager.rmapp.attempt.RMAppAttemptImpl: appattempt_1490313515759_0005_000001 State change from FINAL_SAVING to FINISHING
2017-03-23 20:32:23,278 INFO org.apache.hadoop.yarn.server.resourcemanager.rmapp.RMAppImpl: application_1490313515759_0005 State change from FINAL_SAVING to FINISHING
2017-03-23 20:32:23,827 INFO org.apache.hadoop.yarn.server.resourcemanager.rmcontainer.RMContainerImpl: container_1490313515759_0005_01_000004 Container Transitioned from RUNNING to COMPLETED
2017-03-23 20:32:23,827 INFO org.apache.hadoop.yarn.server.resourcemanager.scheduler.common.fica.FiCaSchedulerApp: Completed container: container_1490313515759_0005_01_000004 in state: COMPLETED event:FINISHED
2017-03-23 20:32:23,827 INFO org.apache.hadoop.yarn.server.resourcemanager.RMAuditLogger: USER=root	OPERATION=AM Released Container	TARGET=SchedulerApp	RESULT=SUCCESS	APPID=application_1490313515759_0005	CONTAINERID=container_1490313515759_0005_01_000004
2017-03-23 20:32:23,827 INFO org.apache.hadoop.yarn.server.resourcemanager.scheduler.SchedulerNode: Released container container_1490313515759_0005_01_000004 of capacity <memory:1024, vCores:1> on host 240008d2487e:44869, which currently has 1 containers, <memory:2048, vCores:1> used and <memory:6144, vCores:7> available, release resources=true
2017-03-23 20:32:23,827 INFO org.apache.hadoop.yarn.server.resourcemanager.scheduler.capacity.LeafQueue: default used=<memory:2048, vCores:1> numContainers=1 user=root user-resources=<memory:2048, vCores:1>
2017-03-23 20:32:23,828 INFO org.apache.hadoop.yarn.server.resourcemanager.scheduler.capacity.LeafQueue: completedContainer container=Container: [ContainerId: container_1490313515759_0005_01_000004, NodeId: 240008d2487e:44869, NodeHttpAddress: 240008d2487e:8042, Resource: <memory:1024, vCores:1>, Priority: 10, Token: Token { kind: ContainerToken, service: 172.18.0.2:44869 }, ] queue=default: capacity=1.0, absoluteCapacity=1.0, usedResources=<memory:2048, vCores:1>, usedCapacity=0.25, absoluteUsedCapacity=0.25, numApps=1, numContainers=1 cluster=<memory:8192, vCores:8>
2017-03-23 20:32:23,828 INFO org.apache.hadoop.yarn.server.resourcemanager.scheduler.capacity.ParentQueue: completedContainer queue=root usedCapacity=0.25 absoluteUsedCapacity=0.25 used=<memory:2048, vCores:1> cluster=<memory:8192, vCores:8>
2017-03-23 20:32:23,828 INFO org.apache.hadoop.yarn.server.resourcemanager.scheduler.capacity.ParentQueue: Re-sorting completed queue: root.default stats: default: capacity=1.0, absoluteCapacity=1.0, usedResources=<memory:2048, vCores:1>, usedCapacity=0.25, absoluteUsedCapacity=0.25, numApps=1, numContainers=1
2017-03-23 20:32:23,828 INFO org.apache.hadoop.yarn.server.resourcemanager.scheduler.capacity.CapacityScheduler: Application attempt appattempt_1490313515759_0005_000001 released container container_1490313515759_0005_01_000004 on node: host: 240008d2487e:44869 #containers=1 available=<memory:6144, vCores:7> used=<memory:2048, vCores:1> with event: FINISHED
2017-03-23 20:32:24,281 INFO org.apache.hadoop.yarn.server.resourcemanager.ApplicationMasterService: application_1490313515759_0005 unregistered successfully. 
2017-03-23 20:32:29,843 INFO org.apache.hadoop.yarn.server.resourcemanager.rmcontainer.RMContainerImpl: container_1490313515759_0005_01_000001 Container Transitioned from RUNNING to COMPLETED
2017-03-23 20:32:29,843 INFO org.apache.hadoop.yarn.server.resourcemanager.ApplicationMasterService: Unregistering app attempt : appattempt_1490313515759_0005_000001
2017-03-23 20:32:29,843 INFO org.apache.hadoop.yarn.server.resourcemanager.scheduler.common.fica.FiCaSchedulerApp: Completed container: container_1490313515759_0005_01_000001 in state: COMPLETED event:FINISHED
2017-03-23 20:32:29,843 INFO org.apache.hadoop.yarn.server.resourcemanager.security.AMRMTokenSecretManager: Application finished, removing password for appattempt_1490313515759_0005_000001
2017-03-23 20:32:29,843 INFO org.apache.hadoop.yarn.server.resourcemanager.RMAuditLogger: USER=root	OPERATION=AM Released Container	TARGET=SchedulerApp	RESULT=SUCCESS	APPID=application_1490313515759_0005	CONTAINERID=container_1490313515759_0005_01_000001
2017-03-23 20:32:29,843 INFO org.apache.hadoop.yarn.server.resourcemanager.rmapp.attempt.RMAppAttemptImpl: appattempt_1490313515759_0005_000001 State change from FINISHING to FINISHED
2017-03-23 20:32:29,843 INFO org.apache.hadoop.yarn.server.resourcemanager.scheduler.SchedulerNode: Released container container_1490313515759_0005_01_000001 of capacity <memory:2048, vCores:1> on host 240008d2487e:44869, which currently has 0 containers, <memory:0, vCores:0> used and <memory:8192, vCores:8> available, release resources=true
2017-03-23 20:32:29,843 INFO org.apache.hadoop.yarn.server.resourcemanager.rmapp.RMAppImpl: application_1490313515759_0005 State change from FINISHING to FINISHED
2017-03-23 20:32:29,843 INFO org.apache.hadoop.yarn.server.resourcemanager.scheduler.capacity.LeafQueue: default used=<memory:0, vCores:0> numContainers=0 user=root user-resources=<memory:0, vCores:0>
2017-03-23 20:32:29,844 INFO org.apache.hadoop.yarn.server.resourcemanager.RMAuditLogger: USER=root	OPERATION=Application Finished - Succeeded	TARGET=RMAppManager	RESULT=SUCCESS	APPID=application_1490313515759_0005
2017-03-23 20:32:29,844 INFO org.apache.hadoop.yarn.server.resourcemanager.scheduler.capacity.LeafQueue: completedContainer container=Container: [ContainerId: container_1490313515759_0005_01_000001, NodeId: 240008d2487e:44869, NodeHttpAddress: 240008d2487e:8042, Resource: <memory:2048, vCores:1>, Priority: 0, Token: Token { kind: ContainerToken, service: 172.18.0.2:44869 }, ] queue=default: capacity=1.0, absoluteCapacity=1.0, usedResources=<memory:0, vCores:0>, usedCapacity=0.0, absoluteUsedCapacity=0.0, numApps=1, numContainers=0 cluster=<memory:8192, vCores:8>
2017-03-23 20:32:29,844 INFO org.apache.hadoop.yarn.server.resourcemanager.scheduler.capacity.ParentQueue: completedContainer queue=root usedCapacity=0.0 absoluteUsedCapacity=0.0 used=<memory:0, vCores:0> cluster=<memory:8192, vCores:8>
2017-03-23 20:32:29,844 INFO org.apache.hadoop.yarn.server.resourcemanager.scheduler.capacity.ParentQueue: Re-sorting completed queue: root.default stats: default: capacity=1.0, absoluteCapacity=1.0, usedResources=<memory:0, vCores:0>, usedCapacity=0.0, absoluteUsedCapacity=0.0, numApps=1, numContainers=0
2017-03-23 20:32:29,844 INFO org.apache.hadoop.yarn.server.resourcemanager.scheduler.capacity.CapacityScheduler: Application attempt appattempt_1490313515759_0005_000001 released container container_1490313515759_0005_01_000001 on node: host: 240008d2487e:44869 #containers=0 available=<memory:8192, vCores:8> used=<memory:0, vCores:0> with event: FINISHED
2017-03-23 20:32:29,844 INFO org.apache.hadoop.yarn.server.resourcemanager.scheduler.capacity.CapacityScheduler: Application Attempt appattempt_1490313515759_0005_000001 is done. finalState=FINISHED
2017-03-23 20:32:29,844 INFO org.apache.hadoop.yarn.server.resourcemanager.RMAppManager$ApplicationSummary: appId=application_1490313515759_0005,name=streamjob3545759551423442309.jar,user=root,queue=default,state=FINISHED,trackingUrl=http://240008d2487e:8088/proxy/application_1490313515759_0005/,appMasterHost=240008d2487e,startTime=1490315497716,finishTime=1490315543277,finalStatus=SUCCEEDED,memorySeconds=158460,vcoreSeconds=101,preemptedAMContainers=0,preemptedNonAMContainers=0,preemptedResources=<memory:0\, vCores:0>,applicationType=MAPREDUCE
2017-03-23 20:32:29,844 INFO org.apache.hadoop.yarn.server.resourcemanager.scheduler.AppSchedulingInfo: Application application_1490313515759_0005 requests cleared
2017-03-23 20:32:29,845 INFO org.apache.hadoop.yarn.server.resourcemanager.amlauncher.AMLauncher: Cleaning master appattempt_1490313515759_0005_000001
2017-03-23 20:32:29,845 INFO org.apache.hadoop.yarn.server.resourcemanager.scheduler.capacity.LeafQueue: Application removed - appId: application_1490313515759_0005 user: root queue: default #user-pending-applications: 0 #user-active-applications: 0 #queue-pending-applications: 0 #queue-active-applications: 0
2017-03-23 20:32:29,845 INFO org.apache.hadoop.yarn.server.resourcemanager.scheduler.capacity.ParentQueue: Application removed - appId: application_1490313515759_0005 user: root leaf-queue of parent: root #applications: 0
2017-03-23 20:32:30,861 INFO org.apache.hadoop.yarn.server.resourcemanager.scheduler.capacity.CapacityScheduler: Null container completed...
2017-03-23 20:35:00,732 INFO org.apache.hadoop.yarn.server.resourcemanager.ClientRMService: Allocated new applicationId: 6
2017-03-23 20:35:02,109 INFO org.apache.hadoop.yarn.server.resourcemanager.ClientRMService: Application with id 6 submitted by user root
2017-03-23 20:35:02,109 INFO org.apache.hadoop.yarn.server.resourcemanager.RMAuditLogger: USER=root	IP=172.18.0.2	OPERATION=Submit Application Request	TARGET=ClientRMService	RESULT=SUCCESS	APPID=application_1490313515759_0006
2017-03-23 20:35:02,109 INFO org.apache.hadoop.yarn.server.resourcemanager.rmapp.RMAppImpl: Storing application with id application_1490313515759_0006
2017-03-23 20:35:02,110 INFO org.apache.hadoop.yarn.server.resourcemanager.rmapp.RMAppImpl: application_1490313515759_0006 State change from NEW to NEW_SAVING
2017-03-23 20:35:02,110 INFO org.apache.hadoop.yarn.server.resourcemanager.recovery.RMStateStore: Storing info for app: application_1490313515759_0006
2017-03-23 20:35:02,110 INFO org.apache.hadoop.yarn.server.resourcemanager.rmapp.RMAppImpl: application_1490313515759_0006 State change from NEW_SAVING to SUBMITTED
2017-03-23 20:35:02,111 INFO org.apache.hadoop.yarn.server.resourcemanager.scheduler.capacity.ParentQueue: Application added - appId: application_1490313515759_0006 user: root leaf-queue of parent: root #applications: 1
2017-03-23 20:35:02,111 INFO org.apache.hadoop.yarn.server.resourcemanager.scheduler.capacity.CapacityScheduler: Accepted application application_1490313515759_0006 from user: root, in queue: default
2017-03-23 20:35:02,112 INFO org.apache.hadoop.yarn.server.resourcemanager.rmapp.RMAppImpl: application_1490313515759_0006 State change from SUBMITTED to ACCEPTED
2017-03-23 20:35:02,112 INFO org.apache.hadoop.yarn.server.resourcemanager.ApplicationMasterService: Registering app attempt : appattempt_1490313515759_0006_000001
2017-03-23 20:35:02,112 INFO org.apache.hadoop.yarn.server.resourcemanager.rmapp.attempt.RMAppAttemptImpl: appattempt_1490313515759_0006_000001 State change from NEW to SUBMITTED
2017-03-23 20:35:02,112 WARN org.apache.hadoop.yarn.server.resourcemanager.scheduler.capacity.LeafQueue: maximum-am-resource-percent is insufficient to start a single application in queue, it is likely set too low. skipping enforcement to allow at least one application to start
2017-03-23 20:35:02,112 WARN org.apache.hadoop.yarn.server.resourcemanager.scheduler.capacity.LeafQueue: maximum-am-resource-percent is insufficient to start a single application in queue for user, it is likely set too low. skipping enforcement to allow at least one application to start
2017-03-23 20:35:02,112 INFO org.apache.hadoop.yarn.server.resourcemanager.scheduler.capacity.LeafQueue: Application application_1490313515759_0006 from user: root activated in queue: default
2017-03-23 20:35:02,112 INFO org.apache.hadoop.yarn.server.resourcemanager.scheduler.capacity.LeafQueue: Application added - appId: application_1490313515759_0006 user: org.apache.hadoop.yarn.server.resourcemanager.scheduler.capacity.LeafQueue$User@13657737, leaf-queue: default #user-pending-applications: 0 #user-active-applications: 1 #queue-pending-applications: 0 #queue-active-applications: 1
2017-03-23 20:35:02,112 INFO org.apache.hadoop.yarn.server.resourcemanager.scheduler.capacity.CapacityScheduler: Added Application Attempt appattempt_1490313515759_0006_000001 to scheduler from user root in queue default
2017-03-23 20:35:02,113 INFO org.apache.hadoop.yarn.server.resourcemanager.rmapp.attempt.RMAppAttemptImpl: appattempt_1490313515759_0006_000001 State change from SUBMITTED to SCHEDULED
2017-03-23 20:35:02,226 INFO org.apache.hadoop.yarn.server.resourcemanager.rmcontainer.RMContainerImpl: container_1490313515759_0006_01_000001 Container Transitioned from NEW to ALLOCATED
2017-03-23 20:35:02,226 INFO org.apache.hadoop.yarn.server.resourcemanager.RMAuditLogger: USER=root	OPERATION=AM Allocated Container	TARGET=SchedulerApp	RESULT=SUCCESS	APPID=application_1490313515759_0006	CONTAINERID=container_1490313515759_0006_01_000001
2017-03-23 20:35:02,226 INFO org.apache.hadoop.yarn.server.resourcemanager.scheduler.SchedulerNode: Assigned container container_1490313515759_0006_01_000001 of capacity <memory:2048, vCores:1> on host 240008d2487e:44869, which has 1 containers, <memory:2048, vCores:1> used and <memory:6144, vCores:7> available after allocation
2017-03-23 20:35:02,227 INFO org.apache.hadoop.yarn.server.resourcemanager.scheduler.capacity.LeafQueue: assignedContainer application attempt=appattempt_1490313515759_0006_000001 container=Container: [ContainerId: container_1490313515759_0006_01_000001, NodeId: 240008d2487e:44869, NodeHttpAddress: 240008d2487e:8042, Resource: <memory:2048, vCores:1>, Priority: 0, Token: null, ] queue=default: capacity=1.0, absoluteCapacity=1.0, usedResources=<memory:0, vCores:0>, usedCapacity=0.0, absoluteUsedCapacity=0.0, numApps=1, numContainers=0 clusterResource=<memory:8192, vCores:8>
2017-03-23 20:35:02,227 INFO org.apache.hadoop.yarn.server.resourcemanager.scheduler.capacity.ParentQueue: Re-sorting assigned queue: root.default stats: default: capacity=1.0, absoluteCapacity=1.0, usedResources=<memory:2048, vCores:1>, usedCapacity=0.25, absoluteUsedCapacity=0.25, numApps=1, numContainers=1
2017-03-23 20:35:02,227 INFO org.apache.hadoop.yarn.server.resourcemanager.scheduler.capacity.ParentQueue: assignedContainer queue=root usedCapacity=0.25 absoluteUsedCapacity=0.25 used=<memory:2048, vCores:1> cluster=<memory:8192, vCores:8>
2017-03-23 20:35:02,228 INFO org.apache.hadoop.yarn.server.resourcemanager.security.NMTokenSecretManagerInRM: Sending NMToken for nodeId : 240008d2487e:44869 for container : container_1490313515759_0006_01_000001
2017-03-23 20:35:02,230 INFO org.apache.hadoop.yarn.server.resourcemanager.rmcontainer.RMContainerImpl: container_1490313515759_0006_01_000001 Container Transitioned from ALLOCATED to ACQUIRED
2017-03-23 20:35:02,230 INFO org.apache.hadoop.yarn.server.resourcemanager.security.NMTokenSecretManagerInRM: Clear node set for appattempt_1490313515759_0006_000001
2017-03-23 20:35:02,230 INFO org.apache.hadoop.yarn.server.resourcemanager.rmapp.attempt.RMAppAttemptImpl: Storing attempt: AppId: application_1490313515759_0006 AttemptId: appattempt_1490313515759_0006_000001 MasterContainer: Container: [ContainerId: container_1490313515759_0006_01_000001, NodeId: 240008d2487e:44869, NodeHttpAddress: 240008d2487e:8042, Resource: <memory:2048, vCores:1>, Priority: 0, Token: Token { kind: ContainerToken, service: 172.18.0.2:44869 }, ]
2017-03-23 20:35:02,230 INFO org.apache.hadoop.yarn.server.resourcemanager.rmapp.attempt.RMAppAttemptImpl: appattempt_1490313515759_0006_000001 State change from SCHEDULED to ALLOCATED_SAVING
2017-03-23 20:35:02,230 INFO org.apache.hadoop.yarn.server.resourcemanager.rmapp.attempt.RMAppAttemptImpl: appattempt_1490313515759_0006_000001 State change from ALLOCATED_SAVING to ALLOCATED
2017-03-23 20:35:02,231 INFO org.apache.hadoop.yarn.server.resourcemanager.amlauncher.AMLauncher: Launching masterappattempt_1490313515759_0006_000001
2017-03-23 20:35:02,238 INFO org.apache.hadoop.yarn.server.resourcemanager.amlauncher.AMLauncher: Setting up container Container: [ContainerId: container_1490313515759_0006_01_000001, NodeId: 240008d2487e:44869, NodeHttpAddress: 240008d2487e:8042, Resource: <memory:2048, vCores:1>, Priority: 0, Token: Token { kind: ContainerToken, service: 172.18.0.2:44869 }, ] for AM appattempt_1490313515759_0006_000001
2017-03-23 20:35:02,238 INFO org.apache.hadoop.yarn.server.resourcemanager.amlauncher.AMLauncher: Command to launch container container_1490313515759_0006_01_000001 : $JAVA_HOME/bin/java -Dlog4j.configuration=container-log4j.properties -Dyarn.app.container.log.dir=<LOG_DIR> -Dyarn.app.container.log.filesize=0 -Dhadoop.root.logger=INFO,CLA -Dhadoop.root.logfile=syslog  -Xmx1024m org.apache.hadoop.mapreduce.v2.app.MRAppMaster 1><LOG_DIR>/stdout 2><LOG_DIR>/stderr 
2017-03-23 20:35:02,238 INFO org.apache.hadoop.yarn.server.resourcemanager.security.AMRMTokenSecretManager: Create AMRMToken for ApplicationAttempt: appattempt_1490313515759_0006_000001
2017-03-23 20:35:02,238 INFO org.apache.hadoop.yarn.server.resourcemanager.security.AMRMTokenSecretManager: Creating password for appattempt_1490313515759_0006_000001
2017-03-23 20:35:02,253 INFO org.apache.hadoop.yarn.server.resourcemanager.amlauncher.AMLauncher: Done launching container Container: [ContainerId: container_1490313515759_0006_01_000001, NodeId: 240008d2487e:44869, NodeHttpAddress: 240008d2487e:8042, Resource: <memory:2048, vCores:1>, Priority: 0, Token: Token { kind: ContainerToken, service: 172.18.0.2:44869 }, ] for AM appattempt_1490313515759_0006_000001
2017-03-23 20:35:02,253 INFO org.apache.hadoop.yarn.server.resourcemanager.rmapp.attempt.RMAppAttemptImpl: appattempt_1490313515759_0006_000001 State change from ALLOCATED to LAUNCHED
2017-03-23 20:35:03,229 INFO org.apache.hadoop.yarn.server.resourcemanager.rmcontainer.RMContainerImpl: container_1490313515759_0006_01_000001 Container Transitioned from ACQUIRED to RUNNING
2017-03-23 20:35:07,199 INFO SecurityLogger.org.apache.hadoop.ipc.Server: Auth successful for appattempt_1490313515759_0006_000001 (auth:SIMPLE)
2017-03-23 20:35:07,204 INFO org.apache.hadoop.yarn.server.resourcemanager.ApplicationMasterService: AM registration appattempt_1490313515759_0006_000001
2017-03-23 20:35:07,204 INFO org.apache.hadoop.yarn.server.resourcemanager.RMAuditLogger: USER=root	IP=172.18.0.2	OPERATION=Register App Master	TARGET=ApplicationMasterService	RESULT=SUCCESS	APPID=application_1490313515759_0006	APPATTEMPTID=appattempt_1490313515759_0006_000001
2017-03-23 20:35:07,205 INFO org.apache.hadoop.yarn.server.resourcemanager.rmapp.attempt.RMAppAttemptImpl: appattempt_1490313515759_0006_000001 State change from LAUNCHED to RUNNING
2017-03-23 20:35:07,205 INFO org.apache.hadoop.yarn.server.resourcemanager.rmapp.RMAppImpl: application_1490313515759_0006 State change from ACCEPTED to RUNNING
2017-03-23 20:35:09,245 INFO org.apache.hadoop.yarn.server.resourcemanager.rmcontainer.RMContainerImpl: container_1490313515759_0006_01_000002 Container Transitioned from NEW to ALLOCATED
2017-03-23 20:35:09,245 INFO org.apache.hadoop.yarn.server.resourcemanager.RMAuditLogger: USER=root	OPERATION=AM Allocated Container	TARGET=SchedulerApp	RESULT=SUCCESS	APPID=application_1490313515759_0006	CONTAINERID=container_1490313515759_0006_01_000002
2017-03-23 20:35:09,245 INFO org.apache.hadoop.yarn.server.resourcemanager.scheduler.SchedulerNode: Assigned container container_1490313515759_0006_01_000002 of capacity <memory:1024, vCores:1> on host 240008d2487e:44869, which has 2 containers, <memory:3072, vCores:2> used and <memory:5120, vCores:6> available after allocation
2017-03-23 20:35:09,246 INFO org.apache.hadoop.yarn.server.resourcemanager.scheduler.capacity.LeafQueue: assignedContainer application attempt=appattempt_1490313515759_0006_000001 container=Container: [ContainerId: container_1490313515759_0006_01_000002, NodeId: 240008d2487e:44869, NodeHttpAddress: 240008d2487e:8042, Resource: <memory:1024, vCores:1>, Priority: 20, Token: null, ] queue=default: capacity=1.0, absoluteCapacity=1.0, usedResources=<memory:2048, vCores:1>, usedCapacity=0.25, absoluteUsedCapacity=0.25, numApps=1, numContainers=1 clusterResource=<memory:8192, vCores:8>
2017-03-23 20:35:09,246 INFO org.apache.hadoop.yarn.server.resourcemanager.scheduler.capacity.ParentQueue: Re-sorting assigned queue: root.default stats: default: capacity=1.0, absoluteCapacity=1.0, usedResources=<memory:3072, vCores:2>, usedCapacity=0.375, absoluteUsedCapacity=0.375, numApps=1, numContainers=2
2017-03-23 20:35:09,246 INFO org.apache.hadoop.yarn.server.resourcemanager.scheduler.capacity.ParentQueue: assignedContainer queue=root usedCapacity=0.375 absoluteUsedCapacity=0.375 used=<memory:3072, vCores:2> cluster=<memory:8192, vCores:8>
2017-03-23 20:35:09,246 INFO org.apache.hadoop.yarn.server.resourcemanager.rmcontainer.RMContainerImpl: container_1490313515759_0006_01_000003 Container Transitioned from NEW to ALLOCATED
2017-03-23 20:35:09,246 INFO org.apache.hadoop.yarn.server.resourcemanager.RMAuditLogger: USER=root	OPERATION=AM Allocated Container	TARGET=SchedulerApp	RESULT=SUCCESS	APPID=application_1490313515759_0006	CONTAINERID=container_1490313515759_0006_01_000003
2017-03-23 20:35:09,246 INFO org.apache.hadoop.yarn.server.resourcemanager.scheduler.SchedulerNode: Assigned container container_1490313515759_0006_01_000003 of capacity <memory:1024, vCores:1> on host 240008d2487e:44869, which has 3 containers, <memory:4096, vCores:3> used and <memory:4096, vCores:5> available after allocation
2017-03-23 20:35:09,247 INFO org.apache.hadoop.yarn.server.resourcemanager.scheduler.capacity.LeafQueue: assignedContainer application attempt=appattempt_1490313515759_0006_000001 container=Container: [ContainerId: container_1490313515759_0006_01_000003, NodeId: 240008d2487e:44869, NodeHttpAddress: 240008d2487e:8042, Resource: <memory:1024, vCores:1>, Priority: 20, Token: null, ] queue=default: capacity=1.0, absoluteCapacity=1.0, usedResources=<memory:3072, vCores:2>, usedCapacity=0.375, absoluteUsedCapacity=0.375, numApps=1, numContainers=2 clusterResource=<memory:8192, vCores:8>
2017-03-23 20:35:09,247 INFO org.apache.hadoop.yarn.server.resourcemanager.scheduler.capacity.ParentQueue: Re-sorting assigned queue: root.default stats: default: capacity=1.0, absoluteCapacity=1.0, usedResources=<memory:4096, vCores:3>, usedCapacity=0.5, absoluteUsedCapacity=0.5, numApps=1, numContainers=3
2017-03-23 20:35:09,247 INFO org.apache.hadoop.yarn.server.resourcemanager.scheduler.capacity.ParentQueue: assignedContainer queue=root usedCapacity=0.5 absoluteUsedCapacity=0.5 used=<memory:4096, vCores:3> cluster=<memory:8192, vCores:8>
2017-03-23 20:35:09,331 INFO org.apache.hadoop.yarn.server.resourcemanager.security.NMTokenSecretManagerInRM: Sending NMToken for nodeId : 240008d2487e:44869 for container : container_1490313515759_0006_01_000002
2017-03-23 20:35:09,332 INFO org.apache.hadoop.yarn.server.resourcemanager.rmcontainer.RMContainerImpl: container_1490313515759_0006_01_000002 Container Transitioned from ALLOCATED to ACQUIRED
2017-03-23 20:35:09,334 INFO org.apache.hadoop.yarn.server.resourcemanager.rmcontainer.RMContainerImpl: container_1490313515759_0006_01_000003 Container Transitioned from ALLOCATED to ACQUIRED
2017-03-23 20:35:10,247 INFO org.apache.hadoop.yarn.server.resourcemanager.rmcontainer.RMContainerImpl: container_1490313515759_0006_01_000002 Container Transitioned from ACQUIRED to RUNNING
2017-03-23 20:35:10,248 INFO org.apache.hadoop.yarn.server.resourcemanager.rmcontainer.RMContainerImpl: container_1490313515759_0006_01_000003 Container Transitioned from ACQUIRED to RUNNING
2017-03-23 20:35:10,350 INFO org.apache.hadoop.yarn.server.resourcemanager.scheduler.AppSchedulingInfo: checking for deactivate of application :application_1490313515759_0006
2017-03-23 20:35:23,744 INFO org.apache.hadoop.yarn.server.resourcemanager.rmcontainer.RMContainerImpl: container_1490313515759_0006_01_000003 Container Transitioned from RUNNING to COMPLETED
2017-03-23 20:35:23,745 INFO org.apache.hadoop.yarn.server.resourcemanager.scheduler.common.fica.FiCaSchedulerApp: Completed container: container_1490313515759_0006_01_000003 in state: COMPLETED event:FINISHED
2017-03-23 20:35:23,745 INFO org.apache.hadoop.yarn.server.resourcemanager.RMAuditLogger: USER=root	OPERATION=AM Released Container	TARGET=SchedulerApp	RESULT=SUCCESS	APPID=application_1490313515759_0006	CONTAINERID=container_1490313515759_0006_01_000003
2017-03-23 20:35:23,745 INFO org.apache.hadoop.yarn.server.resourcemanager.scheduler.SchedulerNode: Released container container_1490313515759_0006_01_000003 of capacity <memory:1024, vCores:1> on host 240008d2487e:44869, which currently has 2 containers, <memory:3072, vCores:2> used and <memory:5120, vCores:6> available, release resources=true
2017-03-23 20:35:23,745 INFO org.apache.hadoop.yarn.server.resourcemanager.scheduler.capacity.LeafQueue: default used=<memory:3072, vCores:2> numContainers=2 user=root user-resources=<memory:3072, vCores:2>
2017-03-23 20:35:23,745 INFO org.apache.hadoop.yarn.server.resourcemanager.scheduler.capacity.LeafQueue: completedContainer container=Container: [ContainerId: container_1490313515759_0006_01_000003, NodeId: 240008d2487e:44869, NodeHttpAddress: 240008d2487e:8042, Resource: <memory:1024, vCores:1>, Priority: 20, Token: Token { kind: ContainerToken, service: 172.18.0.2:44869 }, ] queue=default: capacity=1.0, absoluteCapacity=1.0, usedResources=<memory:3072, vCores:2>, usedCapacity=0.375, absoluteUsedCapacity=0.375, numApps=1, numContainers=2 cluster=<memory:8192, vCores:8>
2017-03-23 20:35:23,745 INFO org.apache.hadoop.yarn.server.resourcemanager.scheduler.capacity.ParentQueue: completedContainer queue=root usedCapacity=0.375 absoluteUsedCapacity=0.375 used=<memory:3072, vCores:2> cluster=<memory:8192, vCores:8>
2017-03-23 20:35:23,745 INFO org.apache.hadoop.yarn.server.resourcemanager.scheduler.capacity.ParentQueue: Re-sorting completed queue: root.default stats: default: capacity=1.0, absoluteCapacity=1.0, usedResources=<memory:3072, vCores:2>, usedCapacity=0.375, absoluteUsedCapacity=0.375, numApps=1, numContainers=2
2017-03-23 20:35:23,745 INFO org.apache.hadoop.yarn.server.resourcemanager.scheduler.capacity.CapacityScheduler: Application attempt appattempt_1490313515759_0006_000001 released container container_1490313515759_0006_01_000003 on node: host: 240008d2487e:44869 #containers=2 available=<memory:5120, vCores:6> used=<memory:3072, vCores:2> with event: FINISHED
2017-03-23 20:35:24,747 INFO org.apache.hadoop.yarn.server.resourcemanager.rmcontainer.RMContainerImpl: container_1490313515759_0006_01_000002 Container Transitioned from RUNNING to COMPLETED
2017-03-23 20:35:24,747 INFO org.apache.hadoop.yarn.server.resourcemanager.scheduler.common.fica.FiCaSchedulerApp: Completed container: container_1490313515759_0006_01_000002 in state: COMPLETED event:FINISHED
2017-03-23 20:35:24,747 INFO org.apache.hadoop.yarn.server.resourcemanager.RMAuditLogger: USER=root	OPERATION=AM Released Container	TARGET=SchedulerApp	RESULT=SUCCESS	APPID=application_1490313515759_0006	CONTAINERID=container_1490313515759_0006_01_000002
2017-03-23 20:35:24,747 INFO org.apache.hadoop.yarn.server.resourcemanager.scheduler.SchedulerNode: Released container container_1490313515759_0006_01_000002 of capacity <memory:1024, vCores:1> on host 240008d2487e:44869, which currently has 1 containers, <memory:2048, vCores:1> used and <memory:6144, vCores:7> available, release resources=true
2017-03-23 20:35:24,748 INFO org.apache.hadoop.yarn.server.resourcemanager.scheduler.capacity.LeafQueue: default used=<memory:2048, vCores:1> numContainers=1 user=root user-resources=<memory:2048, vCores:1>
2017-03-23 20:35:24,748 INFO org.apache.hadoop.yarn.server.resourcemanager.scheduler.capacity.LeafQueue: completedContainer container=Container: [ContainerId: container_1490313515759_0006_01_000002, NodeId: 240008d2487e:44869, NodeHttpAddress: 240008d2487e:8042, Resource: <memory:1024, vCores:1>, Priority: 20, Token: Token { kind: ContainerToken, service: 172.18.0.2:44869 }, ] queue=default: capacity=1.0, absoluteCapacity=1.0, usedResources=<memory:2048, vCores:1>, usedCapacity=0.25, absoluteUsedCapacity=0.25, numApps=1, numContainers=1 cluster=<memory:8192, vCores:8>
2017-03-23 20:35:24,748 INFO org.apache.hadoop.yarn.server.resourcemanager.scheduler.capacity.ParentQueue: completedContainer queue=root usedCapacity=0.25 absoluteUsedCapacity=0.25 used=<memory:2048, vCores:1> cluster=<memory:8192, vCores:8>
2017-03-23 20:35:24,748 INFO org.apache.hadoop.yarn.server.resourcemanager.scheduler.capacity.ParentQueue: Re-sorting completed queue: root.default stats: default: capacity=1.0, absoluteCapacity=1.0, usedResources=<memory:2048, vCores:1>, usedCapacity=0.25, absoluteUsedCapacity=0.25, numApps=1, numContainers=1
2017-03-23 20:35:24,748 INFO org.apache.hadoop.yarn.server.resourcemanager.scheduler.capacity.CapacityScheduler: Application attempt appattempt_1490313515759_0006_000001 released container container_1490313515759_0006_01_000002 on node: host: 240008d2487e:44869 #containers=1 available=<memory:6144, vCores:7> used=<memory:2048, vCores:1> with event: FINISHED
2017-03-23 20:35:24,749 INFO org.apache.hadoop.yarn.server.resourcemanager.rmcontainer.RMContainerImpl: container_1490313515759_0006_01_000004 Container Transitioned from NEW to ALLOCATED
2017-03-23 20:35:24,749 INFO org.apache.hadoop.yarn.server.resourcemanager.RMAuditLogger: USER=root	OPERATION=AM Allocated Container	TARGET=SchedulerApp	RESULT=SUCCESS	APPID=application_1490313515759_0006	CONTAINERID=container_1490313515759_0006_01_000004
2017-03-23 20:35:24,749 INFO org.apache.hadoop.yarn.server.resourcemanager.scheduler.SchedulerNode: Assigned container container_1490313515759_0006_01_000004 of capacity <memory:1024, vCores:1> on host 240008d2487e:44869, which has 2 containers, <memory:3072, vCores:2> used and <memory:5120, vCores:6> available after allocation
2017-03-23 20:35:24,750 INFO org.apache.hadoop.yarn.server.resourcemanager.scheduler.capacity.LeafQueue: assignedContainer application attempt=appattempt_1490313515759_0006_000001 container=Container: [ContainerId: container_1490313515759_0006_01_000004, NodeId: 240008d2487e:44869, NodeHttpAddress: 240008d2487e:8042, Resource: <memory:1024, vCores:1>, Priority: 10, Token: null, ] queue=default: capacity=1.0, absoluteCapacity=1.0, usedResources=<memory:2048, vCores:1>, usedCapacity=0.25, absoluteUsedCapacity=0.25, numApps=1, numContainers=1 clusterResource=<memory:8192, vCores:8>
2017-03-23 20:35:24,750 INFO org.apache.hadoop.yarn.server.resourcemanager.scheduler.capacity.ParentQueue: Re-sorting assigned queue: root.default stats: default: capacity=1.0, absoluteCapacity=1.0, usedResources=<memory:3072, vCores:2>, usedCapacity=0.375, absoluteUsedCapacity=0.375, numApps=1, numContainers=2
2017-03-23 20:35:24,750 INFO org.apache.hadoop.yarn.server.resourcemanager.scheduler.capacity.ParentQueue: assignedContainer queue=root usedCapacity=0.375 absoluteUsedCapacity=0.375 used=<memory:3072, vCores:2> cluster=<memory:8192, vCores:8>
2017-03-23 20:35:25,404 INFO org.apache.hadoop.yarn.server.resourcemanager.rmcontainer.RMContainerImpl: container_1490313515759_0006_01_000004 Container Transitioned from ALLOCATED to ACQUIRED
2017-03-23 20:35:25,750 INFO org.apache.hadoop.yarn.server.resourcemanager.rmcontainer.RMContainerImpl: container_1490313515759_0006_01_000004 Container Transitioned from ACQUIRED to RUNNING
2017-03-23 20:35:26,409 INFO org.apache.hadoop.yarn.server.resourcemanager.scheduler.AppSchedulingInfo: checking for deactivate of application :application_1490313515759_0006
2017-03-23 20:35:48,819 INFO org.apache.hadoop.yarn.server.resourcemanager.rmapp.attempt.RMAppAttemptImpl: Updating application attempt appattempt_1490313515759_0006_000001 with final state: FINISHING, and exit status: -1000
2017-03-23 20:35:48,819 INFO org.apache.hadoop.yarn.server.resourcemanager.rmapp.attempt.RMAppAttemptImpl: appattempt_1490313515759_0006_000001 State change from RUNNING to FINAL_SAVING
2017-03-23 20:35:48,819 INFO org.apache.hadoop.yarn.server.resourcemanager.rmapp.RMAppImpl: Updating application application_1490313515759_0006 with final state: FINISHING
2017-03-23 20:35:48,819 INFO org.apache.hadoop.yarn.server.resourcemanager.rmapp.RMAppImpl: application_1490313515759_0006 State change from RUNNING to FINAL_SAVING
2017-03-23 20:35:48,819 INFO org.apache.hadoop.yarn.server.resourcemanager.rmapp.attempt.RMAppAttemptImpl: appattempt_1490313515759_0006_000001 State change from FINAL_SAVING to FINISHING
2017-03-23 20:35:48,819 INFO org.apache.hadoop.yarn.server.resourcemanager.recovery.RMStateStore: Updating info for app: application_1490313515759_0006
2017-03-23 20:35:48,820 INFO org.apache.hadoop.yarn.server.resourcemanager.rmapp.RMAppImpl: application_1490313515759_0006 State change from FINAL_SAVING to FINISHING
2017-03-23 20:35:49,006 INFO org.apache.hadoop.yarn.server.resourcemanager.rmcontainer.RMContainerImpl: container_1490313515759_0006_01_000004 Container Transitioned from RUNNING to COMPLETED
2017-03-23 20:35:49,006 INFO org.apache.hadoop.yarn.server.resourcemanager.scheduler.common.fica.FiCaSchedulerApp: Completed container: container_1490313515759_0006_01_000004 in state: COMPLETED event:FINISHED
2017-03-23 20:35:49,006 INFO org.apache.hadoop.yarn.server.resourcemanager.RMAuditLogger: USER=root	OPERATION=AM Released Container	TARGET=SchedulerApp	RESULT=SUCCESS	APPID=application_1490313515759_0006	CONTAINERID=container_1490313515759_0006_01_000004
2017-03-23 20:35:49,006 INFO org.apache.hadoop.yarn.server.resourcemanager.scheduler.SchedulerNode: Released container container_1490313515759_0006_01_000004 of capacity <memory:1024, vCores:1> on host 240008d2487e:44869, which currently has 1 containers, <memory:2048, vCores:1> used and <memory:6144, vCores:7> available, release resources=true
2017-03-23 20:35:49,006 INFO org.apache.hadoop.yarn.server.resourcemanager.scheduler.capacity.LeafQueue: default used=<memory:2048, vCores:1> numContainers=1 user=root user-resources=<memory:2048, vCores:1>
2017-03-23 20:35:49,007 INFO org.apache.hadoop.yarn.server.resourcemanager.scheduler.capacity.LeafQueue: completedContainer container=Container: [ContainerId: container_1490313515759_0006_01_000004, NodeId: 240008d2487e:44869, NodeHttpAddress: 240008d2487e:8042, Resource: <memory:1024, vCores:1>, Priority: 10, Token: Token { kind: ContainerToken, service: 172.18.0.2:44869 }, ] queue=default: capacity=1.0, absoluteCapacity=1.0, usedResources=<memory:2048, vCores:1>, usedCapacity=0.25, absoluteUsedCapacity=0.25, numApps=1, numContainers=1 cluster=<memory:8192, vCores:8>
2017-03-23 20:35:49,008 INFO org.apache.hadoop.yarn.server.resourcemanager.scheduler.capacity.ParentQueue: completedContainer queue=root usedCapacity=0.25 absoluteUsedCapacity=0.25 used=<memory:2048, vCores:1> cluster=<memory:8192, vCores:8>
2017-03-23 20:35:49,008 INFO org.apache.hadoop.yarn.server.resourcemanager.scheduler.capacity.ParentQueue: Re-sorting completed queue: root.default stats: default: capacity=1.0, absoluteCapacity=1.0, usedResources=<memory:2048, vCores:1>, usedCapacity=0.25, absoluteUsedCapacity=0.25, numApps=1, numContainers=1
2017-03-23 20:35:49,008 INFO org.apache.hadoop.yarn.server.resourcemanager.scheduler.capacity.CapacityScheduler: Application attempt appattempt_1490313515759_0006_000001 released container container_1490313515759_0006_01_000004 on node: host: 240008d2487e:44869 #containers=1 available=<memory:6144, vCores:7> used=<memory:2048, vCores:1> with event: FINISHED
2017-03-23 20:35:49,823 INFO org.apache.hadoop.yarn.server.resourcemanager.ApplicationMasterService: application_1490313515759_0006 unregistered successfully. 
2017-03-23 20:35:56,025 INFO org.apache.hadoop.yarn.server.resourcemanager.rmcontainer.RMContainerImpl: container_1490313515759_0006_01_000001 Container Transitioned from RUNNING to COMPLETED
2017-03-23 20:35:56,026 INFO org.apache.hadoop.yarn.server.resourcemanager.ApplicationMasterService: Unregistering app attempt : appattempt_1490313515759_0006_000001
2017-03-23 20:35:56,026 INFO org.apache.hadoop.yarn.server.resourcemanager.scheduler.common.fica.FiCaSchedulerApp: Completed container: container_1490313515759_0006_01_000001 in state: COMPLETED event:FINISHED
2017-03-23 20:35:56,026 INFO org.apache.hadoop.yarn.server.resourcemanager.security.AMRMTokenSecretManager: Application finished, removing password for appattempt_1490313515759_0006_000001
2017-03-23 20:35:56,026 INFO org.apache.hadoop.yarn.server.resourcemanager.RMAuditLogger: USER=root	OPERATION=AM Released Container	TARGET=SchedulerApp	RESULT=SUCCESS	APPID=application_1490313515759_0006	CONTAINERID=container_1490313515759_0006_01_000001
2017-03-23 20:35:56,026 INFO org.apache.hadoop.yarn.server.resourcemanager.rmapp.attempt.RMAppAttemptImpl: appattempt_1490313515759_0006_000001 State change from FINISHING to FINISHED
2017-03-23 20:35:56,026 INFO org.apache.hadoop.yarn.server.resourcemanager.scheduler.SchedulerNode: Released container container_1490313515759_0006_01_000001 of capacity <memory:2048, vCores:1> on host 240008d2487e:44869, which currently has 0 containers, <memory:0, vCores:0> used and <memory:8192, vCores:8> available, release resources=true
2017-03-23 20:35:56,026 INFO org.apache.hadoop.yarn.server.resourcemanager.rmapp.RMAppImpl: application_1490313515759_0006 State change from FINISHING to FINISHED
2017-03-23 20:35:56,027 INFO org.apache.hadoop.yarn.server.resourcemanager.scheduler.capacity.LeafQueue: default used=<memory:0, vCores:0> numContainers=0 user=root user-resources=<memory:0, vCores:0>
2017-03-23 20:35:56,027 INFO org.apache.hadoop.yarn.server.resourcemanager.scheduler.capacity.LeafQueue: completedContainer container=Container: [ContainerId: container_1490313515759_0006_01_000001, NodeId: 240008d2487e:44869, NodeHttpAddress: 240008d2487e:8042, Resource: <memory:2048, vCores:1>, Priority: 0, Token: Token { kind: ContainerToken, service: 172.18.0.2:44869 }, ] queue=default: capacity=1.0, absoluteCapacity=1.0, usedResources=<memory:0, vCores:0>, usedCapacity=0.0, absoluteUsedCapacity=0.0, numApps=1, numContainers=0 cluster=<memory:8192, vCores:8>
2017-03-23 20:35:56,027 INFO org.apache.hadoop.yarn.server.resourcemanager.RMAuditLogger: USER=root	OPERATION=Application Finished - Succeeded	TARGET=RMAppManager	RESULT=SUCCESS	APPID=application_1490313515759_0006
2017-03-23 20:35:56,027 INFO org.apache.hadoop.yarn.server.resourcemanager.scheduler.capacity.ParentQueue: completedContainer queue=root usedCapacity=0.0 absoluteUsedCapacity=0.0 used=<memory:0, vCores:0> cluster=<memory:8192, vCores:8>
2017-03-23 20:35:56,027 INFO org.apache.hadoop.yarn.server.resourcemanager.scheduler.capacity.ParentQueue: Re-sorting completed queue: root.default stats: default: capacity=1.0, absoluteCapacity=1.0, usedResources=<memory:0, vCores:0>, usedCapacity=0.0, absoluteUsedCapacity=0.0, numApps=1, numContainers=0
2017-03-23 20:35:56,028 INFO org.apache.hadoop.yarn.server.resourcemanager.amlauncher.AMLauncher: Cleaning master appattempt_1490313515759_0006_000001
2017-03-23 20:35:56,028 INFO org.apache.hadoop.yarn.server.resourcemanager.scheduler.capacity.CapacityScheduler: Application attempt appattempt_1490313515759_0006_000001 released container container_1490313515759_0006_01_000001 on node: host: 240008d2487e:44869 #containers=0 available=<memory:8192, vCores:8> used=<memory:0, vCores:0> with event: FINISHED
2017-03-23 20:35:56,028 INFO org.apache.hadoop.yarn.server.resourcemanager.scheduler.capacity.CapacityScheduler: Application Attempt appattempt_1490313515759_0006_000001 is done. finalState=FINISHED
2017-03-23 20:35:56,028 INFO org.apache.hadoop.yarn.server.resourcemanager.RMAppManager$ApplicationSummary: appId=application_1490313515759_0006,name=streamjob8987020612725927637.jar,user=root,queue=default,state=FINISHED,trackingUrl=http://240008d2487e:8088/proxy/application_1490313515759_0006/,appMasterHost=240008d2487e,startTime=1490315702109,finishTime=1490315748819,finalStatus=SUCCEEDED,memorySeconds=165737,vcoreSeconds=106,preemptedAMContainers=0,preemptedNonAMContainers=0,preemptedResources=<memory:0\, vCores:0>,applicationType=MAPREDUCE
2017-03-23 20:35:56,028 INFO org.apache.hadoop.yarn.server.resourcemanager.scheduler.AppSchedulingInfo: Application application_1490313515759_0006 requests cleared
2017-03-23 20:35:56,028 INFO org.apache.hadoop.yarn.server.resourcemanager.scheduler.capacity.LeafQueue: Application removed - appId: application_1490313515759_0006 user: root queue: default #user-pending-applications: 0 #user-active-applications: 0 #queue-pending-applications: 0 #queue-active-applications: 0
2017-03-23 20:35:56,028 INFO org.apache.hadoop.yarn.server.resourcemanager.scheduler.capacity.ParentQueue: Application removed - appId: application_1490313515759_0006 user: root leaf-queue of parent: root #applications: 0
2017-03-23 20:35:57,045 INFO org.apache.hadoop.yarn.server.resourcemanager.scheduler.capacity.CapacityScheduler: Null container completed...
2017-03-23 20:43:21,025 INFO org.apache.hadoop.yarn.server.resourcemanager.ClientRMService: Allocated new applicationId: 7
2017-03-23 20:43:22,383 INFO org.apache.hadoop.yarn.server.resourcemanager.ClientRMService: Application with id 7 submitted by user root
2017-03-23 20:43:22,383 INFO org.apache.hadoop.yarn.server.resourcemanager.RMAuditLogger: USER=root	IP=172.18.0.2	OPERATION=Submit Application Request	TARGET=ClientRMService	RESULT=SUCCESS	APPID=application_1490313515759_0007
2017-03-23 20:43:22,384 INFO org.apache.hadoop.yarn.server.resourcemanager.rmapp.RMAppImpl: Storing application with id application_1490313515759_0007
2017-03-23 20:43:22,384 INFO org.apache.hadoop.yarn.server.resourcemanager.rmapp.RMAppImpl: application_1490313515759_0007 State change from NEW to NEW_SAVING
2017-03-23 20:43:22,384 INFO org.apache.hadoop.yarn.server.resourcemanager.recovery.RMStateStore: Storing info for app: application_1490313515759_0007
2017-03-23 20:43:22,385 INFO org.apache.hadoop.yarn.server.resourcemanager.rmapp.RMAppImpl: application_1490313515759_0007 State change from NEW_SAVING to SUBMITTED
2017-03-23 20:43:22,385 INFO org.apache.hadoop.yarn.server.resourcemanager.scheduler.capacity.ParentQueue: Application added - appId: application_1490313515759_0007 user: root leaf-queue of parent: root #applications: 1
2017-03-23 20:43:22,385 INFO org.apache.hadoop.yarn.server.resourcemanager.scheduler.capacity.CapacityScheduler: Accepted application application_1490313515759_0007 from user: root, in queue: default
2017-03-23 20:43:22,386 INFO org.apache.hadoop.yarn.server.resourcemanager.rmapp.RMAppImpl: application_1490313515759_0007 State change from SUBMITTED to ACCEPTED
2017-03-23 20:43:22,386 INFO org.apache.hadoop.yarn.server.resourcemanager.ApplicationMasterService: Registering app attempt : appattempt_1490313515759_0007_000001
2017-03-23 20:43:22,386 INFO org.apache.hadoop.yarn.server.resourcemanager.rmapp.attempt.RMAppAttemptImpl: appattempt_1490313515759_0007_000001 State change from NEW to SUBMITTED
2017-03-23 20:43:22,387 WARN org.apache.hadoop.yarn.server.resourcemanager.scheduler.capacity.LeafQueue: maximum-am-resource-percent is insufficient to start a single application in queue, it is likely set too low. skipping enforcement to allow at least one application to start
2017-03-23 20:43:22,387 WARN org.apache.hadoop.yarn.server.resourcemanager.scheduler.capacity.LeafQueue: maximum-am-resource-percent is insufficient to start a single application in queue for user, it is likely set too low. skipping enforcement to allow at least one application to start
2017-03-23 20:43:22,387 INFO org.apache.hadoop.yarn.server.resourcemanager.scheduler.capacity.LeafQueue: Application application_1490313515759_0007 from user: root activated in queue: default
2017-03-23 20:43:22,387 INFO org.apache.hadoop.yarn.server.resourcemanager.scheduler.capacity.LeafQueue: Application added - appId: application_1490313515759_0007 user: org.apache.hadoop.yarn.server.resourcemanager.scheduler.capacity.LeafQueue$User@54ef1826, leaf-queue: default #user-pending-applications: 0 #user-active-applications: 1 #queue-pending-applications: 0 #queue-active-applications: 1
2017-03-23 20:43:22,387 INFO org.apache.hadoop.yarn.server.resourcemanager.scheduler.capacity.CapacityScheduler: Added Application Attempt appattempt_1490313515759_0007_000001 to scheduler from user root in queue default
2017-03-23 20:43:22,388 INFO org.apache.hadoop.yarn.server.resourcemanager.rmapp.attempt.RMAppAttemptImpl: appattempt_1490313515759_0007_000001 State change from SUBMITTED to SCHEDULED
2017-03-23 20:43:23,121 INFO org.apache.hadoop.yarn.server.resourcemanager.rmcontainer.RMContainerImpl: container_1490313515759_0007_01_000001 Container Transitioned from NEW to ALLOCATED
2017-03-23 20:43:23,121 INFO org.apache.hadoop.yarn.server.resourcemanager.RMAuditLogger: USER=root	OPERATION=AM Allocated Container	TARGET=SchedulerApp	RESULT=SUCCESS	APPID=application_1490313515759_0007	CONTAINERID=container_1490313515759_0007_01_000001
2017-03-23 20:43:23,121 INFO org.apache.hadoop.yarn.server.resourcemanager.scheduler.SchedulerNode: Assigned container container_1490313515759_0007_01_000001 of capacity <memory:2048, vCores:1> on host 240008d2487e:44869, which has 1 containers, <memory:2048, vCores:1> used and <memory:6144, vCores:7> available after allocation
2017-03-23 20:43:23,121 INFO org.apache.hadoop.yarn.server.resourcemanager.scheduler.capacity.LeafQueue: assignedContainer application attempt=appattempt_1490313515759_0007_000001 container=Container: [ContainerId: container_1490313515759_0007_01_000001, NodeId: 240008d2487e:44869, NodeHttpAddress: 240008d2487e:8042, Resource: <memory:2048, vCores:1>, Priority: 0, Token: null, ] queue=default: capacity=1.0, absoluteCapacity=1.0, usedResources=<memory:0, vCores:0>, usedCapacity=0.0, absoluteUsedCapacity=0.0, numApps=1, numContainers=0 clusterResource=<memory:8192, vCores:8>
2017-03-23 20:43:23,122 INFO org.apache.hadoop.yarn.server.resourcemanager.scheduler.capacity.ParentQueue: Re-sorting assigned queue: root.default stats: default: capacity=1.0, absoluteCapacity=1.0, usedResources=<memory:2048, vCores:1>, usedCapacity=0.25, absoluteUsedCapacity=0.25, numApps=1, numContainers=1
2017-03-23 20:43:23,122 INFO org.apache.hadoop.yarn.server.resourcemanager.scheduler.capacity.ParentQueue: assignedContainer queue=root usedCapacity=0.25 absoluteUsedCapacity=0.25 used=<memory:2048, vCores:1> cluster=<memory:8192, vCores:8>
2017-03-23 20:43:23,123 INFO org.apache.hadoop.yarn.server.resourcemanager.security.NMTokenSecretManagerInRM: Sending NMToken for nodeId : 240008d2487e:44869 for container : container_1490313515759_0007_01_000001
2017-03-23 20:43:23,125 INFO org.apache.hadoop.yarn.server.resourcemanager.rmcontainer.RMContainerImpl: container_1490313515759_0007_01_000001 Container Transitioned from ALLOCATED to ACQUIRED
2017-03-23 20:43:23,125 INFO org.apache.hadoop.yarn.server.resourcemanager.security.NMTokenSecretManagerInRM: Clear node set for appattempt_1490313515759_0007_000001
2017-03-23 20:43:23,125 INFO org.apache.hadoop.yarn.server.resourcemanager.rmapp.attempt.RMAppAttemptImpl: Storing attempt: AppId: application_1490313515759_0007 AttemptId: appattempt_1490313515759_0007_000001 MasterContainer: Container: [ContainerId: container_1490313515759_0007_01_000001, NodeId: 240008d2487e:44869, NodeHttpAddress: 240008d2487e:8042, Resource: <memory:2048, vCores:1>, Priority: 0, Token: Token { kind: ContainerToken, service: 172.18.0.2:44869 }, ]
2017-03-23 20:43:23,125 INFO org.apache.hadoop.yarn.server.resourcemanager.rmapp.attempt.RMAppAttemptImpl: appattempt_1490313515759_0007_000001 State change from SCHEDULED to ALLOCATED_SAVING
2017-03-23 20:43:23,126 INFO org.apache.hadoop.yarn.server.resourcemanager.rmapp.attempt.RMAppAttemptImpl: appattempt_1490313515759_0007_000001 State change from ALLOCATED_SAVING to ALLOCATED
2017-03-23 20:43:23,127 INFO org.apache.hadoop.yarn.server.resourcemanager.amlauncher.AMLauncher: Launching masterappattempt_1490313515759_0007_000001
2017-03-23 20:43:23,129 INFO org.apache.hadoop.yarn.server.resourcemanager.amlauncher.AMLauncher: Setting up container Container: [ContainerId: container_1490313515759_0007_01_000001, NodeId: 240008d2487e:44869, NodeHttpAddress: 240008d2487e:8042, Resource: <memory:2048, vCores:1>, Priority: 0, Token: Token { kind: ContainerToken, service: 172.18.0.2:44869 }, ] for AM appattempt_1490313515759_0007_000001
2017-03-23 20:43:23,129 INFO org.apache.hadoop.yarn.server.resourcemanager.amlauncher.AMLauncher: Command to launch container container_1490313515759_0007_01_000001 : $JAVA_HOME/bin/java -Dlog4j.configuration=container-log4j.properties -Dyarn.app.container.log.dir=<LOG_DIR> -Dyarn.app.container.log.filesize=0 -Dhadoop.root.logger=INFO,CLA -Dhadoop.root.logfile=syslog  -Xmx1024m org.apache.hadoop.mapreduce.v2.app.MRAppMaster 1><LOG_DIR>/stdout 2><LOG_DIR>/stderr 
2017-03-23 20:43:23,129 INFO org.apache.hadoop.yarn.server.resourcemanager.security.AMRMTokenSecretManager: Create AMRMToken for ApplicationAttempt: appattempt_1490313515759_0007_000001
2017-03-23 20:43:23,129 INFO org.apache.hadoop.yarn.server.resourcemanager.security.AMRMTokenSecretManager: Creating password for appattempt_1490313515759_0007_000001
2017-03-23 20:43:23,144 INFO org.apache.hadoop.yarn.server.resourcemanager.amlauncher.AMLauncher: Done launching container Container: [ContainerId: container_1490313515759_0007_01_000001, NodeId: 240008d2487e:44869, NodeHttpAddress: 240008d2487e:8042, Resource: <memory:2048, vCores:1>, Priority: 0, Token: Token { kind: ContainerToken, service: 172.18.0.2:44869 }, ] for AM appattempt_1490313515759_0007_000001
2017-03-23 20:43:23,144 INFO org.apache.hadoop.yarn.server.resourcemanager.rmapp.attempt.RMAppAttemptImpl: appattempt_1490313515759_0007_000001 State change from ALLOCATED to LAUNCHED
2017-03-23 20:43:24,124 INFO org.apache.hadoop.yarn.server.resourcemanager.rmcontainer.RMContainerImpl: container_1490313515759_0007_01_000001 Container Transitioned from ACQUIRED to RUNNING
2017-03-23 20:43:28,147 INFO SecurityLogger.org.apache.hadoop.ipc.Server: Auth successful for appattempt_1490313515759_0007_000001 (auth:SIMPLE)
2017-03-23 20:43:28,151 INFO org.apache.hadoop.yarn.server.resourcemanager.ApplicationMasterService: AM registration appattempt_1490313515759_0007_000001
2017-03-23 20:43:28,151 INFO org.apache.hadoop.yarn.server.resourcemanager.RMAuditLogger: USER=root	IP=172.18.0.2	OPERATION=Register App Master	TARGET=ApplicationMasterService	RESULT=SUCCESS	APPID=application_1490313515759_0007	APPATTEMPTID=appattempt_1490313515759_0007_000001
2017-03-23 20:43:28,151 INFO org.apache.hadoop.yarn.server.resourcemanager.rmapp.attempt.RMAppAttemptImpl: appattempt_1490313515759_0007_000001 State change from LAUNCHED to RUNNING
2017-03-23 20:43:28,151 INFO org.apache.hadoop.yarn.server.resourcemanager.rmapp.RMAppImpl: application_1490313515759_0007 State change from ACCEPTED to RUNNING
2017-03-23 20:43:30,139 INFO org.apache.hadoop.yarn.server.resourcemanager.rmcontainer.RMContainerImpl: container_1490313515759_0007_01_000002 Container Transitioned from NEW to ALLOCATED
2017-03-23 20:43:30,139 INFO org.apache.hadoop.yarn.server.resourcemanager.RMAuditLogger: USER=root	OPERATION=AM Allocated Container	TARGET=SchedulerApp	RESULT=SUCCESS	APPID=application_1490313515759_0007	CONTAINERID=container_1490313515759_0007_01_000002
2017-03-23 20:43:30,139 INFO org.apache.hadoop.yarn.server.resourcemanager.scheduler.SchedulerNode: Assigned container container_1490313515759_0007_01_000002 of capacity <memory:1024, vCores:1> on host 240008d2487e:44869, which has 2 containers, <memory:3072, vCores:2> used and <memory:5120, vCores:6> available after allocation
2017-03-23 20:43:30,139 INFO org.apache.hadoop.yarn.server.resourcemanager.scheduler.capacity.LeafQueue: assignedContainer application attempt=appattempt_1490313515759_0007_000001 container=Container: [ContainerId: container_1490313515759_0007_01_000002, NodeId: 240008d2487e:44869, NodeHttpAddress: 240008d2487e:8042, Resource: <memory:1024, vCores:1>, Priority: 20, Token: null, ] queue=default: capacity=1.0, absoluteCapacity=1.0, usedResources=<memory:2048, vCores:1>, usedCapacity=0.25, absoluteUsedCapacity=0.25, numApps=1, numContainers=1 clusterResource=<memory:8192, vCores:8>
2017-03-23 20:43:30,139 INFO org.apache.hadoop.yarn.server.resourcemanager.scheduler.capacity.ParentQueue: Re-sorting assigned queue: root.default stats: default: capacity=1.0, absoluteCapacity=1.0, usedResources=<memory:3072, vCores:2>, usedCapacity=0.375, absoluteUsedCapacity=0.375, numApps=1, numContainers=2
2017-03-23 20:43:30,140 INFO org.apache.hadoop.yarn.server.resourcemanager.scheduler.capacity.ParentQueue: assignedContainer queue=root usedCapacity=0.375 absoluteUsedCapacity=0.375 used=<memory:3072, vCores:2> cluster=<memory:8192, vCores:8>
2017-03-23 20:43:30,140 INFO org.apache.hadoop.yarn.server.resourcemanager.rmcontainer.RMContainerImpl: container_1490313515759_0007_01_000003 Container Transitioned from NEW to ALLOCATED
2017-03-23 20:43:30,140 INFO org.apache.hadoop.yarn.server.resourcemanager.RMAuditLogger: USER=root	OPERATION=AM Allocated Container	TARGET=SchedulerApp	RESULT=SUCCESS	APPID=application_1490313515759_0007	CONTAINERID=container_1490313515759_0007_01_000003
2017-03-23 20:43:30,140 INFO org.apache.hadoop.yarn.server.resourcemanager.scheduler.SchedulerNode: Assigned container container_1490313515759_0007_01_000003 of capacity <memory:1024, vCores:1> on host 240008d2487e:44869, which has 3 containers, <memory:4096, vCores:3> used and <memory:4096, vCores:5> available after allocation
2017-03-23 20:43:30,140 INFO org.apache.hadoop.yarn.server.resourcemanager.scheduler.capacity.LeafQueue: assignedContainer application attempt=appattempt_1490313515759_0007_000001 container=Container: [ContainerId: container_1490313515759_0007_01_000003, NodeId: 240008d2487e:44869, NodeHttpAddress: 240008d2487e:8042, Resource: <memory:1024, vCores:1>, Priority: 20, Token: null, ] queue=default: capacity=1.0, absoluteCapacity=1.0, usedResources=<memory:3072, vCores:2>, usedCapacity=0.375, absoluteUsedCapacity=0.375, numApps=1, numContainers=2 clusterResource=<memory:8192, vCores:8>
2017-03-23 20:43:30,140 INFO org.apache.hadoop.yarn.server.resourcemanager.scheduler.capacity.ParentQueue: Re-sorting assigned queue: root.default stats: default: capacity=1.0, absoluteCapacity=1.0, usedResources=<memory:4096, vCores:3>, usedCapacity=0.5, absoluteUsedCapacity=0.5, numApps=1, numContainers=3
2017-03-23 20:43:30,141 INFO org.apache.hadoop.yarn.server.resourcemanager.scheduler.capacity.ParentQueue: assignedContainer queue=root usedCapacity=0.5 absoluteUsedCapacity=0.5 used=<memory:4096, vCores:3> cluster=<memory:8192, vCores:8>
2017-03-23 20:43:30,246 INFO org.apache.hadoop.yarn.server.resourcemanager.security.NMTokenSecretManagerInRM: Sending NMToken for nodeId : 240008d2487e:44869 for container : container_1490313515759_0007_01_000002
2017-03-23 20:43:30,248 INFO org.apache.hadoop.yarn.server.resourcemanager.rmcontainer.RMContainerImpl: container_1490313515759_0007_01_000002 Container Transitioned from ALLOCATED to ACQUIRED
2017-03-23 20:43:30,249 INFO org.apache.hadoop.yarn.server.resourcemanager.rmcontainer.RMContainerImpl: container_1490313515759_0007_01_000003 Container Transitioned from ALLOCATED to ACQUIRED
2017-03-23 20:43:31,141 INFO org.apache.hadoop.yarn.server.resourcemanager.rmcontainer.RMContainerImpl: container_1490313515759_0007_01_000002 Container Transitioned from ACQUIRED to RUNNING
2017-03-23 20:43:31,142 INFO org.apache.hadoop.yarn.server.resourcemanager.rmcontainer.RMContainerImpl: container_1490313515759_0007_01_000003 Container Transitioned from ACQUIRED to RUNNING
2017-03-23 20:43:31,265 INFO org.apache.hadoop.yarn.server.resourcemanager.scheduler.AppSchedulingInfo: checking for deactivate of application :application_1490313515759_0007
2017-03-23 20:43:45,072 INFO org.apache.hadoop.yarn.server.resourcemanager.rmcontainer.RMContainerImpl: container_1490313515759_0007_01_000003 Container Transitioned from RUNNING to COMPLETED
2017-03-23 20:43:45,072 INFO org.apache.hadoop.yarn.server.resourcemanager.scheduler.common.fica.FiCaSchedulerApp: Completed container: container_1490313515759_0007_01_000003 in state: COMPLETED event:FINISHED
2017-03-23 20:43:45,072 INFO org.apache.hadoop.yarn.server.resourcemanager.RMAuditLogger: USER=root	OPERATION=AM Released Container	TARGET=SchedulerApp	RESULT=SUCCESS	APPID=application_1490313515759_0007	CONTAINERID=container_1490313515759_0007_01_000003
2017-03-23 20:43:45,072 INFO org.apache.hadoop.yarn.server.resourcemanager.scheduler.SchedulerNode: Released container container_1490313515759_0007_01_000003 of capacity <memory:1024, vCores:1> on host 240008d2487e:44869, which currently has 2 containers, <memory:3072, vCores:2> used and <memory:5120, vCores:6> available, release resources=true
2017-03-23 20:43:45,072 INFO org.apache.hadoop.yarn.server.resourcemanager.scheduler.capacity.LeafQueue: default used=<memory:3072, vCores:2> numContainers=2 user=root user-resources=<memory:3072, vCores:2>
2017-03-23 20:43:45,073 INFO org.apache.hadoop.yarn.server.resourcemanager.scheduler.capacity.LeafQueue: completedContainer container=Container: [ContainerId: container_1490313515759_0007_01_000003, NodeId: 240008d2487e:44869, NodeHttpAddress: 240008d2487e:8042, Resource: <memory:1024, vCores:1>, Priority: 20, Token: Token { kind: ContainerToken, service: 172.18.0.2:44869 }, ] queue=default: capacity=1.0, absoluteCapacity=1.0, usedResources=<memory:3072, vCores:2>, usedCapacity=0.375, absoluteUsedCapacity=0.375, numApps=1, numContainers=2 cluster=<memory:8192, vCores:8>
2017-03-23 20:43:45,073 INFO org.apache.hadoop.yarn.server.resourcemanager.scheduler.capacity.ParentQueue: completedContainer queue=root usedCapacity=0.375 absoluteUsedCapacity=0.375 used=<memory:3072, vCores:2> cluster=<memory:8192, vCores:8>
2017-03-23 20:43:45,073 INFO org.apache.hadoop.yarn.server.resourcemanager.scheduler.capacity.ParentQueue: Re-sorting completed queue: root.default stats: default: capacity=1.0, absoluteCapacity=1.0, usedResources=<memory:3072, vCores:2>, usedCapacity=0.375, absoluteUsedCapacity=0.375, numApps=1, numContainers=2
2017-03-23 20:43:45,073 INFO org.apache.hadoop.yarn.server.resourcemanager.scheduler.capacity.CapacityScheduler: Application attempt appattempt_1490313515759_0007_000001 released container container_1490313515759_0007_01_000003 on node: host: 240008d2487e:44869 #containers=2 available=<memory:5120, vCores:6> used=<memory:3072, vCores:2> with event: FINISHED
2017-03-23 20:43:45,074 INFO org.apache.hadoop.yarn.server.resourcemanager.rmcontainer.RMContainerImpl: container_1490313515759_0007_01_000002 Container Transitioned from RUNNING to COMPLETED
2017-03-23 20:43:45,074 INFO org.apache.hadoop.yarn.server.resourcemanager.scheduler.common.fica.FiCaSchedulerApp: Completed container: container_1490313515759_0007_01_000002 in state: COMPLETED event:FINISHED
2017-03-23 20:43:45,074 INFO org.apache.hadoop.yarn.server.resourcemanager.RMAuditLogger: USER=root	OPERATION=AM Released Container	TARGET=SchedulerApp	RESULT=SUCCESS	APPID=application_1490313515759_0007	CONTAINERID=container_1490313515759_0007_01_000002
2017-03-23 20:43:45,074 INFO org.apache.hadoop.yarn.server.resourcemanager.scheduler.SchedulerNode: Released container container_1490313515759_0007_01_000002 of capacity <memory:1024, vCores:1> on host 240008d2487e:44869, which currently has 1 containers, <memory:2048, vCores:1> used and <memory:6144, vCores:7> available, release resources=true
2017-03-23 20:43:45,074 INFO org.apache.hadoop.yarn.server.resourcemanager.scheduler.capacity.LeafQueue: default used=<memory:2048, vCores:1> numContainers=1 user=root user-resources=<memory:2048, vCores:1>
2017-03-23 20:43:45,074 INFO org.apache.hadoop.yarn.server.resourcemanager.scheduler.capacity.LeafQueue: completedContainer container=Container: [ContainerId: container_1490313515759_0007_01_000002, NodeId: 240008d2487e:44869, NodeHttpAddress: 240008d2487e:8042, Resource: <memory:1024, vCores:1>, Priority: 20, Token: Token { kind: ContainerToken, service: 172.18.0.2:44869 }, ] queue=default: capacity=1.0, absoluteCapacity=1.0, usedResources=<memory:2048, vCores:1>, usedCapacity=0.25, absoluteUsedCapacity=0.25, numApps=1, numContainers=1 cluster=<memory:8192, vCores:8>
2017-03-23 20:43:45,074 INFO org.apache.hadoop.yarn.server.resourcemanager.scheduler.capacity.ParentQueue: completedContainer queue=root usedCapacity=0.25 absoluteUsedCapacity=0.25 used=<memory:2048, vCores:1> cluster=<memory:8192, vCores:8>
2017-03-23 20:43:45,075 INFO org.apache.hadoop.yarn.server.resourcemanager.scheduler.capacity.ParentQueue: Re-sorting completed queue: root.default stats: default: capacity=1.0, absoluteCapacity=1.0, usedResources=<memory:2048, vCores:1>, usedCapacity=0.25, absoluteUsedCapacity=0.25, numApps=1, numContainers=1
2017-03-23 20:43:45,075 INFO org.apache.hadoop.yarn.server.resourcemanager.scheduler.capacity.CapacityScheduler: Application attempt appattempt_1490313515759_0007_000001 released container container_1490313515759_0007_01_000002 on node: host: 240008d2487e:44869 #containers=1 available=<memory:6144, vCores:7> used=<memory:2048, vCores:1> with event: FINISHED
2017-03-23 20:43:46,074 INFO org.apache.hadoop.yarn.server.resourcemanager.rmcontainer.RMContainerImpl: container_1490313515759_0007_01_000004 Container Transitioned from NEW to ALLOCATED
2017-03-23 20:43:46,074 INFO org.apache.hadoop.yarn.server.resourcemanager.RMAuditLogger: USER=root	OPERATION=AM Allocated Container	TARGET=SchedulerApp	RESULT=SUCCESS	APPID=application_1490313515759_0007	CONTAINERID=container_1490313515759_0007_01_000004
2017-03-23 20:43:46,075 INFO org.apache.hadoop.yarn.server.resourcemanager.scheduler.SchedulerNode: Assigned container container_1490313515759_0007_01_000004 of capacity <memory:1024, vCores:1> on host 240008d2487e:44869, which has 2 containers, <memory:3072, vCores:2> used and <memory:5120, vCores:6> available after allocation
2017-03-23 20:43:46,075 INFO org.apache.hadoop.yarn.server.resourcemanager.scheduler.capacity.LeafQueue: assignedContainer application attempt=appattempt_1490313515759_0007_000001 container=Container: [ContainerId: container_1490313515759_0007_01_000004, NodeId: 240008d2487e:44869, NodeHttpAddress: 240008d2487e:8042, Resource: <memory:1024, vCores:1>, Priority: 10, Token: null, ] queue=default: capacity=1.0, absoluteCapacity=1.0, usedResources=<memory:2048, vCores:1>, usedCapacity=0.25, absoluteUsedCapacity=0.25, numApps=1, numContainers=1 clusterResource=<memory:8192, vCores:8>
2017-03-23 20:43:46,075 INFO org.apache.hadoop.yarn.server.resourcemanager.scheduler.capacity.ParentQueue: Re-sorting assigned queue: root.default stats: default: capacity=1.0, absoluteCapacity=1.0, usedResources=<memory:3072, vCores:2>, usedCapacity=0.375, absoluteUsedCapacity=0.375, numApps=1, numContainers=2
2017-03-23 20:43:46,075 INFO org.apache.hadoop.yarn.server.resourcemanager.scheduler.capacity.ParentQueue: assignedContainer queue=root usedCapacity=0.375 absoluteUsedCapacity=0.375 used=<memory:3072, vCores:2> cluster=<memory:8192, vCores:8>
2017-03-23 20:43:46,320 INFO org.apache.hadoop.yarn.server.resourcemanager.rmcontainer.RMContainerImpl: container_1490313515759_0007_01_000004 Container Transitioned from ALLOCATED to ACQUIRED
2017-03-23 20:43:47,077 INFO org.apache.hadoop.yarn.server.resourcemanager.rmcontainer.RMContainerImpl: container_1490313515759_0007_01_000004 Container Transitioned from ACQUIRED to RUNNING
2017-03-23 20:43:47,325 INFO org.apache.hadoop.yarn.server.resourcemanager.scheduler.AppSchedulingInfo: checking for deactivate of application :application_1490313515759_0007
2017-03-23 20:44:07,010 INFO org.apache.hadoop.yarn.server.resourcemanager.rmapp.attempt.RMAppAttemptImpl: Updating application attempt appattempt_1490313515759_0007_000001 with final state: FINISHING, and exit status: -1000
2017-03-23 20:44:07,010 INFO org.apache.hadoop.yarn.server.resourcemanager.rmapp.attempt.RMAppAttemptImpl: appattempt_1490313515759_0007_000001 State change from RUNNING to FINAL_SAVING
2017-03-23 20:44:07,010 INFO org.apache.hadoop.yarn.server.resourcemanager.rmapp.RMAppImpl: Updating application application_1490313515759_0007 with final state: FINISHING
2017-03-23 20:44:07,010 INFO org.apache.hadoop.yarn.server.resourcemanager.rmapp.RMAppImpl: application_1490313515759_0007 State change from RUNNING to FINAL_SAVING
2017-03-23 20:44:07,010 INFO org.apache.hadoop.yarn.server.resourcemanager.recovery.RMStateStore: Updating info for app: application_1490313515759_0007
2017-03-23 20:44:07,010 INFO org.apache.hadoop.yarn.server.resourcemanager.rmapp.attempt.RMAppAttemptImpl: appattempt_1490313515759_0007_000001 State change from FINAL_SAVING to FINISHING
2017-03-23 20:44:07,010 INFO org.apache.hadoop.yarn.server.resourcemanager.rmapp.RMAppImpl: application_1490313515759_0007 State change from FINAL_SAVING to FINISHING
2017-03-23 20:44:07,633 INFO org.apache.hadoop.yarn.server.resourcemanager.rmcontainer.RMContainerImpl: container_1490313515759_0007_01_000004 Container Transitioned from RUNNING to COMPLETED
2017-03-23 20:44:07,633 INFO org.apache.hadoop.yarn.server.resourcemanager.scheduler.common.fica.FiCaSchedulerApp: Completed container: container_1490313515759_0007_01_000004 in state: COMPLETED event:FINISHED
2017-03-23 20:44:07,634 INFO org.apache.hadoop.yarn.server.resourcemanager.RMAuditLogger: USER=root	OPERATION=AM Released Container	TARGET=SchedulerApp	RESULT=SUCCESS	APPID=application_1490313515759_0007	CONTAINERID=container_1490313515759_0007_01_000004
2017-03-23 20:44:07,634 INFO org.apache.hadoop.yarn.server.resourcemanager.scheduler.SchedulerNode: Released container container_1490313515759_0007_01_000004 of capacity <memory:1024, vCores:1> on host 240008d2487e:44869, which currently has 1 containers, <memory:2048, vCores:1> used and <memory:6144, vCores:7> available, release resources=true
2017-03-23 20:44:07,634 INFO org.apache.hadoop.yarn.server.resourcemanager.scheduler.capacity.LeafQueue: default used=<memory:2048, vCores:1> numContainers=1 user=root user-resources=<memory:2048, vCores:1>
2017-03-23 20:44:07,634 INFO org.apache.hadoop.yarn.server.resourcemanager.scheduler.capacity.LeafQueue: completedContainer container=Container: [ContainerId: container_1490313515759_0007_01_000004, NodeId: 240008d2487e:44869, NodeHttpAddress: 240008d2487e:8042, Resource: <memory:1024, vCores:1>, Priority: 10, Token: Token { kind: ContainerToken, service: 172.18.0.2:44869 }, ] queue=default: capacity=1.0, absoluteCapacity=1.0, usedResources=<memory:2048, vCores:1>, usedCapacity=0.25, absoluteUsedCapacity=0.25, numApps=1, numContainers=1 cluster=<memory:8192, vCores:8>
2017-03-23 20:44:07,634 INFO org.apache.hadoop.yarn.server.resourcemanager.scheduler.capacity.ParentQueue: completedContainer queue=root usedCapacity=0.25 absoluteUsedCapacity=0.25 used=<memory:2048, vCores:1> cluster=<memory:8192, vCores:8>
2017-03-23 20:44:07,635 INFO org.apache.hadoop.yarn.server.resourcemanager.scheduler.capacity.ParentQueue: Re-sorting completed queue: root.default stats: default: capacity=1.0, absoluteCapacity=1.0, usedResources=<memory:2048, vCores:1>, usedCapacity=0.25, absoluteUsedCapacity=0.25, numApps=1, numContainers=1
2017-03-23 20:44:07,635 INFO org.apache.hadoop.yarn.server.resourcemanager.scheduler.capacity.CapacityScheduler: Application attempt appattempt_1490313515759_0007_000001 released container container_1490313515759_0007_01_000004 on node: host: 240008d2487e:44869 #containers=1 available=<memory:6144, vCores:7> used=<memory:2048, vCores:1> with event: FINISHED
2017-03-23 20:44:08,014 INFO org.apache.hadoop.yarn.server.resourcemanager.ApplicationMasterService: application_1490313515759_0007 unregistered successfully. 
2017-03-23 20:44:13,649 INFO org.apache.hadoop.yarn.server.resourcemanager.rmcontainer.RMContainerImpl: container_1490313515759_0007_01_000001 Container Transitioned from RUNNING to COMPLETED
2017-03-23 20:44:13,649 INFO org.apache.hadoop.yarn.server.resourcemanager.ApplicationMasterService: Unregistering app attempt : appattempt_1490313515759_0007_000001
2017-03-23 20:44:13,649 INFO org.apache.hadoop.yarn.server.resourcemanager.scheduler.common.fica.FiCaSchedulerApp: Completed container: container_1490313515759_0007_01_000001 in state: COMPLETED event:FINISHED
2017-03-23 20:44:13,649 INFO org.apache.hadoop.yarn.server.resourcemanager.security.AMRMTokenSecretManager: Application finished, removing password for appattempt_1490313515759_0007_000001
2017-03-23 20:44:13,649 INFO org.apache.hadoop.yarn.server.resourcemanager.RMAuditLogger: USER=root	OPERATION=AM Released Container	TARGET=SchedulerApp	RESULT=SUCCESS	APPID=application_1490313515759_0007	CONTAINERID=container_1490313515759_0007_01_000001
2017-03-23 20:44:13,650 INFO org.apache.hadoop.yarn.server.resourcemanager.rmapp.attempt.RMAppAttemptImpl: appattempt_1490313515759_0007_000001 State change from FINISHING to FINISHED
2017-03-23 20:44:13,650 INFO org.apache.hadoop.yarn.server.resourcemanager.scheduler.SchedulerNode: Released container container_1490313515759_0007_01_000001 of capacity <memory:2048, vCores:1> on host 240008d2487e:44869, which currently has 0 containers, <memory:0, vCores:0> used and <memory:8192, vCores:8> available, release resources=true
2017-03-23 20:44:13,650 INFO org.apache.hadoop.yarn.server.resourcemanager.rmapp.RMAppImpl: application_1490313515759_0007 State change from FINISHING to FINISHED
2017-03-23 20:44:13,650 INFO org.apache.hadoop.yarn.server.resourcemanager.scheduler.capacity.LeafQueue: default used=<memory:0, vCores:0> numContainers=0 user=root user-resources=<memory:0, vCores:0>
2017-03-23 20:44:13,650 INFO org.apache.hadoop.yarn.server.resourcemanager.scheduler.capacity.LeafQueue: completedContainer container=Container: [ContainerId: container_1490313515759_0007_01_000001, NodeId: 240008d2487e:44869, NodeHttpAddress: 240008d2487e:8042, Resource: <memory:2048, vCores:1>, Priority: 0, Token: Token { kind: ContainerToken, service: 172.18.0.2:44869 }, ] queue=default: capacity=1.0, absoluteCapacity=1.0, usedResources=<memory:0, vCores:0>, usedCapacity=0.0, absoluteUsedCapacity=0.0, numApps=1, numContainers=0 cluster=<memory:8192, vCores:8>
2017-03-23 20:44:13,650 INFO org.apache.hadoop.yarn.server.resourcemanager.RMAuditLogger: USER=root	OPERATION=Application Finished - Succeeded	TARGET=RMAppManager	RESULT=SUCCESS	APPID=application_1490313515759_0007
2017-03-23 20:44:13,650 INFO org.apache.hadoop.yarn.server.resourcemanager.scheduler.capacity.ParentQueue: completedContainer queue=root usedCapacity=0.0 absoluteUsedCapacity=0.0 used=<memory:0, vCores:0> cluster=<memory:8192, vCores:8>
2017-03-23 20:44:13,653 INFO org.apache.hadoop.yarn.server.resourcemanager.amlauncher.AMLauncher: Cleaning master appattempt_1490313515759_0007_000001
2017-03-23 20:44:13,653 INFO org.apache.hadoop.yarn.server.resourcemanager.RMAppManager$ApplicationSummary: appId=application_1490313515759_0007,name=streamjob3391438718023286476.jar,user=root,queue=default,state=FINISHED,trackingUrl=http://240008d2487e:8088/proxy/application_1490313515759_0007/,appMasterHost=240008d2487e,startTime=1490316202383,finishTime=1490316247010,finalStatus=SUCCEEDED,memorySeconds=156140,vcoreSeconds=99,preemptedAMContainers=0,preemptedNonAMContainers=0,preemptedResources=<memory:0\, vCores:0>,applicationType=MAPREDUCE
2017-03-23 20:44:13,653 INFO org.apache.hadoop.yarn.server.resourcemanager.scheduler.capacity.ParentQueue: Re-sorting completed queue: root.default stats: default: capacity=1.0, absoluteCapacity=1.0, usedResources=<memory:0, vCores:0>, usedCapacity=0.0, absoluteUsedCapacity=0.0, numApps=1, numContainers=0
2017-03-23 20:44:13,653 INFO org.apache.hadoop.yarn.server.resourcemanager.scheduler.capacity.CapacityScheduler: Application attempt appattempt_1490313515759_0007_000001 released container container_1490313515759_0007_01_000001 on node: host: 240008d2487e:44869 #containers=0 available=<memory:8192, vCores:8> used=<memory:0, vCores:0> with event: FINISHED
2017-03-23 20:44:13,654 INFO org.apache.hadoop.yarn.server.resourcemanager.scheduler.capacity.CapacityScheduler: Application Attempt appattempt_1490313515759_0007_000001 is done. finalState=FINISHED
2017-03-23 20:44:13,654 INFO org.apache.hadoop.yarn.server.resourcemanager.scheduler.AppSchedulingInfo: Application application_1490313515759_0007 requests cleared
2017-03-23 20:44:13,654 INFO org.apache.hadoop.yarn.server.resourcemanager.scheduler.capacity.LeafQueue: Application removed - appId: application_1490313515759_0007 user: root queue: default #user-pending-applications: 0 #user-active-applications: 0 #queue-pending-applications: 0 #queue-active-applications: 0
2017-03-23 20:44:13,654 INFO org.apache.hadoop.yarn.server.resourcemanager.scheduler.capacity.ParentQueue: Application removed - appId: application_1490313515759_0007 user: root leaf-queue of parent: root #applications: 0
2017-03-23 20:44:14,679 INFO org.apache.hadoop.yarn.server.resourcemanager.scheduler.capacity.CapacityScheduler: Null container completed...
2017-03-23 20:48:48,126 INFO org.apache.hadoop.yarn.server.resourcemanager.ClientRMService: Allocated new applicationId: 8
2017-03-23 20:48:49,478 INFO org.apache.hadoop.yarn.server.resourcemanager.ClientRMService: Application with id 8 submitted by user root
2017-03-23 20:48:49,478 INFO org.apache.hadoop.yarn.server.resourcemanager.RMAuditLogger: USER=root	IP=172.18.0.2	OPERATION=Submit Application Request	TARGET=ClientRMService	RESULT=SUCCESS	APPID=application_1490313515759_0008
2017-03-23 20:48:49,478 INFO org.apache.hadoop.yarn.server.resourcemanager.rmapp.RMAppImpl: Storing application with id application_1490313515759_0008
2017-03-23 20:48:49,478 INFO org.apache.hadoop.yarn.server.resourcemanager.rmapp.RMAppImpl: application_1490313515759_0008 State change from NEW to NEW_SAVING
2017-03-23 20:48:49,478 INFO org.apache.hadoop.yarn.server.resourcemanager.recovery.RMStateStore: Storing info for app: application_1490313515759_0008
2017-03-23 20:48:49,479 INFO org.apache.hadoop.yarn.server.resourcemanager.rmapp.RMAppImpl: application_1490313515759_0008 State change from NEW_SAVING to SUBMITTED
2017-03-23 20:48:49,479 INFO org.apache.hadoop.yarn.server.resourcemanager.scheduler.capacity.ParentQueue: Application added - appId: application_1490313515759_0008 user: root leaf-queue of parent: root #applications: 1
2017-03-23 20:48:49,479 INFO org.apache.hadoop.yarn.server.resourcemanager.scheduler.capacity.CapacityScheduler: Accepted application application_1490313515759_0008 from user: root, in queue: default
2017-03-23 20:48:49,480 INFO org.apache.hadoop.yarn.server.resourcemanager.rmapp.RMAppImpl: application_1490313515759_0008 State change from SUBMITTED to ACCEPTED
2017-03-23 20:48:49,480 INFO org.apache.hadoop.yarn.server.resourcemanager.ApplicationMasterService: Registering app attempt : appattempt_1490313515759_0008_000001
2017-03-23 20:48:49,480 INFO org.apache.hadoop.yarn.server.resourcemanager.rmapp.attempt.RMAppAttemptImpl: appattempt_1490313515759_0008_000001 State change from NEW to SUBMITTED
2017-03-23 20:48:49,481 WARN org.apache.hadoop.yarn.server.resourcemanager.scheduler.capacity.LeafQueue: maximum-am-resource-percent is insufficient to start a single application in queue, it is likely set too low. skipping enforcement to allow at least one application to start
2017-03-23 20:48:49,481 WARN org.apache.hadoop.yarn.server.resourcemanager.scheduler.capacity.LeafQueue: maximum-am-resource-percent is insufficient to start a single application in queue for user, it is likely set too low. skipping enforcement to allow at least one application to start
2017-03-23 20:48:49,481 INFO org.apache.hadoop.yarn.server.resourcemanager.scheduler.capacity.LeafQueue: Application application_1490313515759_0008 from user: root activated in queue: default
2017-03-23 20:48:49,481 INFO org.apache.hadoop.yarn.server.resourcemanager.scheduler.capacity.LeafQueue: Application added - appId: application_1490313515759_0008 user: org.apache.hadoop.yarn.server.resourcemanager.scheduler.capacity.LeafQueue$User@4b1131e, leaf-queue: default #user-pending-applications: 0 #user-active-applications: 1 #queue-pending-applications: 0 #queue-active-applications: 1
2017-03-23 20:48:49,481 INFO org.apache.hadoop.yarn.server.resourcemanager.scheduler.capacity.CapacityScheduler: Added Application Attempt appattempt_1490313515759_0008_000001 to scheduler from user root in queue default
2017-03-23 20:48:49,482 INFO org.apache.hadoop.yarn.server.resourcemanager.rmapp.attempt.RMAppAttemptImpl: appattempt_1490313515759_0008_000001 State change from SUBMITTED to SCHEDULED
2017-03-23 20:48:50,348 INFO org.apache.hadoop.yarn.server.resourcemanager.rmcontainer.RMContainerImpl: container_1490313515759_0008_01_000001 Container Transitioned from NEW to ALLOCATED
2017-03-23 20:48:50,349 INFO org.apache.hadoop.yarn.server.resourcemanager.RMAuditLogger: USER=root	OPERATION=AM Allocated Container	TARGET=SchedulerApp	RESULT=SUCCESS	APPID=application_1490313515759_0008	CONTAINERID=container_1490313515759_0008_01_000001
2017-03-23 20:48:50,349 INFO org.apache.hadoop.yarn.server.resourcemanager.scheduler.SchedulerNode: Assigned container container_1490313515759_0008_01_000001 of capacity <memory:2048, vCores:1> on host 240008d2487e:44869, which has 1 containers, <memory:2048, vCores:1> used and <memory:6144, vCores:7> available after allocation
2017-03-23 20:48:50,349 INFO org.apache.hadoop.yarn.server.resourcemanager.scheduler.capacity.LeafQueue: assignedContainer application attempt=appattempt_1490313515759_0008_000001 container=Container: [ContainerId: container_1490313515759_0008_01_000001, NodeId: 240008d2487e:44869, NodeHttpAddress: 240008d2487e:8042, Resource: <memory:2048, vCores:1>, Priority: 0, Token: null, ] queue=default: capacity=1.0, absoluteCapacity=1.0, usedResources=<memory:0, vCores:0>, usedCapacity=0.0, absoluteUsedCapacity=0.0, numApps=1, numContainers=0 clusterResource=<memory:8192, vCores:8>
2017-03-23 20:48:50,349 INFO org.apache.hadoop.yarn.server.resourcemanager.scheduler.capacity.ParentQueue: Re-sorting assigned queue: root.default stats: default: capacity=1.0, absoluteCapacity=1.0, usedResources=<memory:2048, vCores:1>, usedCapacity=0.25, absoluteUsedCapacity=0.25, numApps=1, numContainers=1
2017-03-23 20:48:50,349 INFO org.apache.hadoop.yarn.server.resourcemanager.scheduler.capacity.ParentQueue: assignedContainer queue=root usedCapacity=0.25 absoluteUsedCapacity=0.25 used=<memory:2048, vCores:1> cluster=<memory:8192, vCores:8>
2017-03-23 20:48:50,350 INFO org.apache.hadoop.yarn.server.resourcemanager.security.NMTokenSecretManagerInRM: Sending NMToken for nodeId : 240008d2487e:44869 for container : container_1490313515759_0008_01_000001
2017-03-23 20:48:50,352 INFO org.apache.hadoop.yarn.server.resourcemanager.rmcontainer.RMContainerImpl: container_1490313515759_0008_01_000001 Container Transitioned from ALLOCATED to ACQUIRED
2017-03-23 20:48:50,352 INFO org.apache.hadoop.yarn.server.resourcemanager.security.NMTokenSecretManagerInRM: Clear node set for appattempt_1490313515759_0008_000001
2017-03-23 20:48:50,352 INFO org.apache.hadoop.yarn.server.resourcemanager.rmapp.attempt.RMAppAttemptImpl: Storing attempt: AppId: application_1490313515759_0008 AttemptId: appattempt_1490313515759_0008_000001 MasterContainer: Container: [ContainerId: container_1490313515759_0008_01_000001, NodeId: 240008d2487e:44869, NodeHttpAddress: 240008d2487e:8042, Resource: <memory:2048, vCores:1>, Priority: 0, Token: Token { kind: ContainerToken, service: 172.18.0.2:44869 }, ]
2017-03-23 20:48:50,353 INFO org.apache.hadoop.yarn.server.resourcemanager.rmapp.attempt.RMAppAttemptImpl: appattempt_1490313515759_0008_000001 State change from SCHEDULED to ALLOCATED_SAVING
2017-03-23 20:48:50,353 INFO org.apache.hadoop.yarn.server.resourcemanager.rmapp.attempt.RMAppAttemptImpl: appattempt_1490313515759_0008_000001 State change from ALLOCATED_SAVING to ALLOCATED
2017-03-23 20:48:50,354 INFO org.apache.hadoop.yarn.server.resourcemanager.amlauncher.AMLauncher: Launching masterappattempt_1490313515759_0008_000001
2017-03-23 20:48:50,356 INFO org.apache.hadoop.yarn.server.resourcemanager.amlauncher.AMLauncher: Setting up container Container: [ContainerId: container_1490313515759_0008_01_000001, NodeId: 240008d2487e:44869, NodeHttpAddress: 240008d2487e:8042, Resource: <memory:2048, vCores:1>, Priority: 0, Token: Token { kind: ContainerToken, service: 172.18.0.2:44869 }, ] for AM appattempt_1490313515759_0008_000001
2017-03-23 20:48:50,356 INFO org.apache.hadoop.yarn.server.resourcemanager.amlauncher.AMLauncher: Command to launch container container_1490313515759_0008_01_000001 : $JAVA_HOME/bin/java -Dlog4j.configuration=container-log4j.properties -Dyarn.app.container.log.dir=<LOG_DIR> -Dyarn.app.container.log.filesize=0 -Dhadoop.root.logger=INFO,CLA -Dhadoop.root.logfile=syslog  -Xmx1024m org.apache.hadoop.mapreduce.v2.app.MRAppMaster 1><LOG_DIR>/stdout 2><LOG_DIR>/stderr 
2017-03-23 20:48:50,356 INFO org.apache.hadoop.yarn.server.resourcemanager.security.AMRMTokenSecretManager: Create AMRMToken for ApplicationAttempt: appattempt_1490313515759_0008_000001
2017-03-23 20:48:50,356 INFO org.apache.hadoop.yarn.server.resourcemanager.security.AMRMTokenSecretManager: Creating password for appattempt_1490313515759_0008_000001
2017-03-23 20:48:50,371 INFO org.apache.hadoop.yarn.server.resourcemanager.amlauncher.AMLauncher: Done launching container Container: [ContainerId: container_1490313515759_0008_01_000001, NodeId: 240008d2487e:44869, NodeHttpAddress: 240008d2487e:8042, Resource: <memory:2048, vCores:1>, Priority: 0, Token: Token { kind: ContainerToken, service: 172.18.0.2:44869 }, ] for AM appattempt_1490313515759_0008_000001
2017-03-23 20:48:50,372 INFO org.apache.hadoop.yarn.server.resourcemanager.rmapp.attempt.RMAppAttemptImpl: appattempt_1490313515759_0008_000001 State change from ALLOCATED to LAUNCHED
2017-03-23 20:48:51,351 INFO org.apache.hadoop.yarn.server.resourcemanager.rmcontainer.RMContainerImpl: container_1490313515759_0008_01_000001 Container Transitioned from ACQUIRED to RUNNING
2017-03-23 20:48:55,540 INFO SecurityLogger.org.apache.hadoop.ipc.Server: Auth successful for appattempt_1490313515759_0008_000001 (auth:SIMPLE)
2017-03-23 20:48:55,545 INFO org.apache.hadoop.yarn.server.resourcemanager.ApplicationMasterService: AM registration appattempt_1490313515759_0008_000001
2017-03-23 20:48:55,545 INFO org.apache.hadoop.yarn.server.resourcemanager.RMAuditLogger: USER=root	IP=172.18.0.2	OPERATION=Register App Master	TARGET=ApplicationMasterService	RESULT=SUCCESS	APPID=application_1490313515759_0008	APPATTEMPTID=appattempt_1490313515759_0008_000001
2017-03-23 20:48:55,545 INFO org.apache.hadoop.yarn.server.resourcemanager.rmapp.attempt.RMAppAttemptImpl: appattempt_1490313515759_0008_000001 State change from LAUNCHED to RUNNING
2017-03-23 20:48:55,545 INFO org.apache.hadoop.yarn.server.resourcemanager.rmapp.RMAppImpl: application_1490313515759_0008 State change from ACCEPTED to RUNNING
2017-03-23 20:48:57,369 INFO org.apache.hadoop.yarn.server.resourcemanager.rmcontainer.RMContainerImpl: container_1490313515759_0008_01_000002 Container Transitioned from NEW to ALLOCATED
2017-03-23 20:48:57,369 INFO org.apache.hadoop.yarn.server.resourcemanager.RMAuditLogger: USER=root	OPERATION=AM Allocated Container	TARGET=SchedulerApp	RESULT=SUCCESS	APPID=application_1490313515759_0008	CONTAINERID=container_1490313515759_0008_01_000002
2017-03-23 20:48:57,369 INFO org.apache.hadoop.yarn.server.resourcemanager.scheduler.SchedulerNode: Assigned container container_1490313515759_0008_01_000002 of capacity <memory:1024, vCores:1> on host 240008d2487e:44869, which has 2 containers, <memory:3072, vCores:2> used and <memory:5120, vCores:6> available after allocation
2017-03-23 20:48:57,369 INFO org.apache.hadoop.yarn.server.resourcemanager.scheduler.capacity.LeafQueue: assignedContainer application attempt=appattempt_1490313515759_0008_000001 container=Container: [ContainerId: container_1490313515759_0008_01_000002, NodeId: 240008d2487e:44869, NodeHttpAddress: 240008d2487e:8042, Resource: <memory:1024, vCores:1>, Priority: 20, Token: null, ] queue=default: capacity=1.0, absoluteCapacity=1.0, usedResources=<memory:2048, vCores:1>, usedCapacity=0.25, absoluteUsedCapacity=0.25, numApps=1, numContainers=1 clusterResource=<memory:8192, vCores:8>
2017-03-23 20:48:57,370 INFO org.apache.hadoop.yarn.server.resourcemanager.scheduler.capacity.ParentQueue: Re-sorting assigned queue: root.default stats: default: capacity=1.0, absoluteCapacity=1.0, usedResources=<memory:3072, vCores:2>, usedCapacity=0.375, absoluteUsedCapacity=0.375, numApps=1, numContainers=2
2017-03-23 20:48:57,370 INFO org.apache.hadoop.yarn.server.resourcemanager.scheduler.capacity.ParentQueue: assignedContainer queue=root usedCapacity=0.375 absoluteUsedCapacity=0.375 used=<memory:3072, vCores:2> cluster=<memory:8192, vCores:8>
2017-03-23 20:48:57,370 INFO org.apache.hadoop.yarn.server.resourcemanager.rmcontainer.RMContainerImpl: container_1490313515759_0008_01_000003 Container Transitioned from NEW to ALLOCATED
2017-03-23 20:48:57,370 INFO org.apache.hadoop.yarn.server.resourcemanager.RMAuditLogger: USER=root	OPERATION=AM Allocated Container	TARGET=SchedulerApp	RESULT=SUCCESS	APPID=application_1490313515759_0008	CONTAINERID=container_1490313515759_0008_01_000003
2017-03-23 20:48:57,370 INFO org.apache.hadoop.yarn.server.resourcemanager.scheduler.SchedulerNode: Assigned container container_1490313515759_0008_01_000003 of capacity <memory:1024, vCores:1> on host 240008d2487e:44869, which has 3 containers, <memory:4096, vCores:3> used and <memory:4096, vCores:5> available after allocation
2017-03-23 20:48:57,370 INFO org.apache.hadoop.yarn.server.resourcemanager.scheduler.capacity.LeafQueue: assignedContainer application attempt=appattempt_1490313515759_0008_000001 container=Container: [ContainerId: container_1490313515759_0008_01_000003, NodeId: 240008d2487e:44869, NodeHttpAddress: 240008d2487e:8042, Resource: <memory:1024, vCores:1>, Priority: 20, Token: null, ] queue=default: capacity=1.0, absoluteCapacity=1.0, usedResources=<memory:3072, vCores:2>, usedCapacity=0.375, absoluteUsedCapacity=0.375, numApps=1, numContainers=2 clusterResource=<memory:8192, vCores:8>
2017-03-23 20:48:57,371 INFO org.apache.hadoop.yarn.server.resourcemanager.scheduler.capacity.ParentQueue: Re-sorting assigned queue: root.default stats: default: capacity=1.0, absoluteCapacity=1.0, usedResources=<memory:4096, vCores:3>, usedCapacity=0.5, absoluteUsedCapacity=0.5, numApps=1, numContainers=3
2017-03-23 20:48:57,371 INFO org.apache.hadoop.yarn.server.resourcemanager.scheduler.capacity.ParentQueue: assignedContainer queue=root usedCapacity=0.5 absoluteUsedCapacity=0.5 used=<memory:4096, vCores:3> cluster=<memory:8192, vCores:8>
2017-03-23 20:48:57,610 INFO org.apache.hadoop.yarn.server.resourcemanager.security.NMTokenSecretManagerInRM: Sending NMToken for nodeId : 240008d2487e:44869 for container : container_1490313515759_0008_01_000002
2017-03-23 20:48:57,612 INFO org.apache.hadoop.yarn.server.resourcemanager.rmcontainer.RMContainerImpl: container_1490313515759_0008_01_000002 Container Transitioned from ALLOCATED to ACQUIRED
2017-03-23 20:48:57,614 INFO org.apache.hadoop.yarn.server.resourcemanager.rmcontainer.RMContainerImpl: container_1490313515759_0008_01_000003 Container Transitioned from ALLOCATED to ACQUIRED
2017-03-23 20:48:58,369 INFO org.apache.hadoop.yarn.server.resourcemanager.rmcontainer.RMContainerImpl: container_1490313515759_0008_01_000002 Container Transitioned from ACQUIRED to RUNNING
2017-03-23 20:48:58,369 INFO org.apache.hadoop.yarn.server.resourcemanager.rmcontainer.RMContainerImpl: container_1490313515759_0008_01_000003 Container Transitioned from ACQUIRED to RUNNING
2017-03-23 20:48:58,629 INFO org.apache.hadoop.yarn.server.resourcemanager.scheduler.AppSchedulingInfo: checking for deactivate of application :application_1490313515759_0008
2017-03-23 20:49:11,338 INFO org.apache.hadoop.yarn.server.resourcemanager.rmcontainer.RMContainerImpl: container_1490313515759_0008_01_000003 Container Transitioned from RUNNING to COMPLETED
2017-03-23 20:49:11,338 INFO org.apache.hadoop.yarn.server.resourcemanager.scheduler.common.fica.FiCaSchedulerApp: Completed container: container_1490313515759_0008_01_000003 in state: COMPLETED event:FINISHED
2017-03-23 20:49:11,339 INFO org.apache.hadoop.yarn.server.resourcemanager.RMAuditLogger: USER=root	OPERATION=AM Released Container	TARGET=SchedulerApp	RESULT=SUCCESS	APPID=application_1490313515759_0008	CONTAINERID=container_1490313515759_0008_01_000003
2017-03-23 20:49:11,339 INFO org.apache.hadoop.yarn.server.resourcemanager.scheduler.SchedulerNode: Released container container_1490313515759_0008_01_000003 of capacity <memory:1024, vCores:1> on host 240008d2487e:44869, which currently has 2 containers, <memory:3072, vCores:2> used and <memory:5120, vCores:6> available, release resources=true
2017-03-23 20:49:11,339 INFO org.apache.hadoop.yarn.server.resourcemanager.scheduler.capacity.LeafQueue: default used=<memory:3072, vCores:2> numContainers=2 user=root user-resources=<memory:3072, vCores:2>
2017-03-23 20:49:11,339 INFO org.apache.hadoop.yarn.server.resourcemanager.scheduler.capacity.LeafQueue: completedContainer container=Container: [ContainerId: container_1490313515759_0008_01_000003, NodeId: 240008d2487e:44869, NodeHttpAddress: 240008d2487e:8042, Resource: <memory:1024, vCores:1>, Priority: 20, Token: Token { kind: ContainerToken, service: 172.18.0.2:44869 }, ] queue=default: capacity=1.0, absoluteCapacity=1.0, usedResources=<memory:3072, vCores:2>, usedCapacity=0.375, absoluteUsedCapacity=0.375, numApps=1, numContainers=2 cluster=<memory:8192, vCores:8>
2017-03-23 20:49:11,339 INFO org.apache.hadoop.yarn.server.resourcemanager.scheduler.capacity.ParentQueue: completedContainer queue=root usedCapacity=0.375 absoluteUsedCapacity=0.375 used=<memory:3072, vCores:2> cluster=<memory:8192, vCores:8>
2017-03-23 20:49:11,340 INFO org.apache.hadoop.yarn.server.resourcemanager.scheduler.capacity.ParentQueue: Re-sorting completed queue: root.default stats: default: capacity=1.0, absoluteCapacity=1.0, usedResources=<memory:3072, vCores:2>, usedCapacity=0.375, absoluteUsedCapacity=0.375, numApps=1, numContainers=2
2017-03-23 20:49:11,340 INFO org.apache.hadoop.yarn.server.resourcemanager.scheduler.capacity.CapacityScheduler: Application attempt appattempt_1490313515759_0008_000001 released container container_1490313515759_0008_01_000003 on node: host: 240008d2487e:44869 #containers=2 available=<memory:5120, vCores:6> used=<memory:3072, vCores:2> with event: FINISHED
2017-03-23 20:49:12,341 INFO org.apache.hadoop.yarn.server.resourcemanager.rmcontainer.RMContainerImpl: container_1490313515759_0008_01_000002 Container Transitioned from RUNNING to COMPLETED
2017-03-23 20:49:12,341 INFO org.apache.hadoop.yarn.server.resourcemanager.scheduler.common.fica.FiCaSchedulerApp: Completed container: container_1490313515759_0008_01_000002 in state: COMPLETED event:FINISHED
2017-03-23 20:49:12,341 INFO org.apache.hadoop.yarn.server.resourcemanager.RMAuditLogger: USER=root	OPERATION=AM Released Container	TARGET=SchedulerApp	RESULT=SUCCESS	APPID=application_1490313515759_0008	CONTAINERID=container_1490313515759_0008_01_000002
2017-03-23 20:49:12,341 INFO org.apache.hadoop.yarn.server.resourcemanager.scheduler.SchedulerNode: Released container container_1490313515759_0008_01_000002 of capacity <memory:1024, vCores:1> on host 240008d2487e:44869, which currently has 1 containers, <memory:2048, vCores:1> used and <memory:6144, vCores:7> available, release resources=true
2017-03-23 20:49:12,342 INFO org.apache.hadoop.yarn.server.resourcemanager.scheduler.capacity.LeafQueue: default used=<memory:2048, vCores:1> numContainers=1 user=root user-resources=<memory:2048, vCores:1>
2017-03-23 20:49:12,342 INFO org.apache.hadoop.yarn.server.resourcemanager.scheduler.capacity.LeafQueue: completedContainer container=Container: [ContainerId: container_1490313515759_0008_01_000002, NodeId: 240008d2487e:44869, NodeHttpAddress: 240008d2487e:8042, Resource: <memory:1024, vCores:1>, Priority: 20, Token: Token { kind: ContainerToken, service: 172.18.0.2:44869 }, ] queue=default: capacity=1.0, absoluteCapacity=1.0, usedResources=<memory:2048, vCores:1>, usedCapacity=0.25, absoluteUsedCapacity=0.25, numApps=1, numContainers=1 cluster=<memory:8192, vCores:8>
2017-03-23 20:49:12,342 INFO org.apache.hadoop.yarn.server.resourcemanager.scheduler.capacity.ParentQueue: completedContainer queue=root usedCapacity=0.25 absoluteUsedCapacity=0.25 used=<memory:2048, vCores:1> cluster=<memory:8192, vCores:8>
2017-03-23 20:49:12,342 INFO org.apache.hadoop.yarn.server.resourcemanager.scheduler.capacity.ParentQueue: Re-sorting completed queue: root.default stats: default: capacity=1.0, absoluteCapacity=1.0, usedResources=<memory:2048, vCores:1>, usedCapacity=0.25, absoluteUsedCapacity=0.25, numApps=1, numContainers=1
2017-03-23 20:49:12,342 INFO org.apache.hadoop.yarn.server.resourcemanager.scheduler.capacity.CapacityScheduler: Application attempt appattempt_1490313515759_0008_000001 released container container_1490313515759_0008_01_000002 on node: host: 240008d2487e:44869 #containers=1 available=<memory:6144, vCores:7> used=<memory:2048, vCores:1> with event: FINISHED
2017-03-23 20:49:13,344 INFO org.apache.hadoop.yarn.server.resourcemanager.rmcontainer.RMContainerImpl: container_1490313515759_0008_01_000004 Container Transitioned from NEW to ALLOCATED
2017-03-23 20:49:13,344 INFO org.apache.hadoop.yarn.server.resourcemanager.RMAuditLogger: USER=root	OPERATION=AM Allocated Container	TARGET=SchedulerApp	RESULT=SUCCESS	APPID=application_1490313515759_0008	CONTAINERID=container_1490313515759_0008_01_000004
2017-03-23 20:49:13,344 INFO org.apache.hadoop.yarn.server.resourcemanager.scheduler.SchedulerNode: Assigned container container_1490313515759_0008_01_000004 of capacity <memory:1024, vCores:1> on host 240008d2487e:44869, which has 2 containers, <memory:3072, vCores:2> used and <memory:5120, vCores:6> available after allocation
2017-03-23 20:49:13,345 INFO org.apache.hadoop.yarn.server.resourcemanager.scheduler.capacity.LeafQueue: assignedContainer application attempt=appattempt_1490313515759_0008_000001 container=Container: [ContainerId: container_1490313515759_0008_01_000004, NodeId: 240008d2487e:44869, NodeHttpAddress: 240008d2487e:8042, Resource: <memory:1024, vCores:1>, Priority: 10, Token: null, ] queue=default: capacity=1.0, absoluteCapacity=1.0, usedResources=<memory:2048, vCores:1>, usedCapacity=0.25, absoluteUsedCapacity=0.25, numApps=1, numContainers=1 clusterResource=<memory:8192, vCores:8>
2017-03-23 20:49:13,345 INFO org.apache.hadoop.yarn.server.resourcemanager.scheduler.capacity.ParentQueue: Re-sorting assigned queue: root.default stats: default: capacity=1.0, absoluteCapacity=1.0, usedResources=<memory:3072, vCores:2>, usedCapacity=0.375, absoluteUsedCapacity=0.375, numApps=1, numContainers=2
2017-03-23 20:49:13,345 INFO org.apache.hadoop.yarn.server.resourcemanager.scheduler.capacity.ParentQueue: assignedContainer queue=root usedCapacity=0.375 absoluteUsedCapacity=0.375 used=<memory:3072, vCores:2> cluster=<memory:8192, vCores:8>
2017-03-23 20:49:13,691 INFO org.apache.hadoop.yarn.server.resourcemanager.rmcontainer.RMContainerImpl: container_1490313515759_0008_01_000004 Container Transitioned from ALLOCATED to ACQUIRED
2017-03-23 20:49:14,347 INFO org.apache.hadoop.yarn.server.resourcemanager.rmcontainer.RMContainerImpl: container_1490313515759_0008_01_000004 Container Transitioned from ACQUIRED to RUNNING
2017-03-23 20:49:14,695 INFO org.apache.hadoop.yarn.server.resourcemanager.scheduler.AppSchedulingInfo: checking for deactivate of application :application_1490313515759_0008
2017-03-23 20:49:34,926 INFO org.apache.hadoop.yarn.server.resourcemanager.rmcontainer.RMContainerImpl: container_1490313515759_0008_01_000004 Container Transitioned from RUNNING to COMPLETED
2017-03-23 20:49:34,926 INFO org.apache.hadoop.yarn.server.resourcemanager.scheduler.common.fica.FiCaSchedulerApp: Completed container: container_1490313515759_0008_01_000004 in state: COMPLETED event:FINISHED
2017-03-23 20:49:34,926 INFO org.apache.hadoop.yarn.server.resourcemanager.RMAuditLogger: USER=root	OPERATION=AM Released Container	TARGET=SchedulerApp	RESULT=SUCCESS	APPID=application_1490313515759_0008	CONTAINERID=container_1490313515759_0008_01_000004
2017-03-23 20:49:34,926 INFO org.apache.hadoop.yarn.server.resourcemanager.scheduler.SchedulerNode: Released container container_1490313515759_0008_01_000004 of capacity <memory:1024, vCores:1> on host 240008d2487e:44869, which currently has 1 containers, <memory:2048, vCores:1> used and <memory:6144, vCores:7> available, release resources=true
2017-03-23 20:49:34,926 INFO org.apache.hadoop.yarn.server.resourcemanager.scheduler.capacity.LeafQueue: default used=<memory:2048, vCores:1> numContainers=1 user=root user-resources=<memory:2048, vCores:1>
2017-03-23 20:49:34,927 INFO org.apache.hadoop.yarn.server.resourcemanager.scheduler.capacity.LeafQueue: completedContainer container=Container: [ContainerId: container_1490313515759_0008_01_000004, NodeId: 240008d2487e:44869, NodeHttpAddress: 240008d2487e:8042, Resource: <memory:1024, vCores:1>, Priority: 10, Token: Token { kind: ContainerToken, service: 172.18.0.2:44869 }, ] queue=default: capacity=1.0, absoluteCapacity=1.0, usedResources=<memory:2048, vCores:1>, usedCapacity=0.25, absoluteUsedCapacity=0.25, numApps=1, numContainers=1 cluster=<memory:8192, vCores:8>
2017-03-23 20:49:34,927 INFO org.apache.hadoop.yarn.server.resourcemanager.scheduler.capacity.ParentQueue: completedContainer queue=root usedCapacity=0.25 absoluteUsedCapacity=0.25 used=<memory:2048, vCores:1> cluster=<memory:8192, vCores:8>
2017-03-23 20:49:34,927 INFO org.apache.hadoop.yarn.server.resourcemanager.scheduler.capacity.ParentQueue: Re-sorting completed queue: root.default stats: default: capacity=1.0, absoluteCapacity=1.0, usedResources=<memory:2048, vCores:1>, usedCapacity=0.25, absoluteUsedCapacity=0.25, numApps=1, numContainers=1
2017-03-23 20:49:34,927 INFO org.apache.hadoop.yarn.server.resourcemanager.scheduler.capacity.CapacityScheduler: Application attempt appattempt_1490313515759_0008_000001 released container container_1490313515759_0008_01_000004 on node: host: 240008d2487e:44869 #containers=1 available=<memory:6144, vCores:7> used=<memory:2048, vCores:1> with event: FINISHED
2017-03-23 20:49:35,930 INFO org.apache.hadoop.yarn.server.resourcemanager.rmcontainer.RMContainerImpl: container_1490313515759_0008_01_000005 Container Transitioned from NEW to ALLOCATED
2017-03-23 20:49:35,930 INFO org.apache.hadoop.yarn.server.resourcemanager.RMAuditLogger: USER=root	OPERATION=AM Allocated Container	TARGET=SchedulerApp	RESULT=SUCCESS	APPID=application_1490313515759_0008	CONTAINERID=container_1490313515759_0008_01_000005
2017-03-23 20:49:35,930 INFO org.apache.hadoop.yarn.server.resourcemanager.scheduler.SchedulerNode: Assigned container container_1490313515759_0008_01_000005 of capacity <memory:1024, vCores:1> on host 240008d2487e:44869, which has 2 containers, <memory:3072, vCores:2> used and <memory:5120, vCores:6> available after allocation
2017-03-23 20:49:35,930 INFO org.apache.hadoop.yarn.server.resourcemanager.scheduler.capacity.LeafQueue: assignedContainer application attempt=appattempt_1490313515759_0008_000001 container=Container: [ContainerId: container_1490313515759_0008_01_000005, NodeId: 240008d2487e:44869, NodeHttpAddress: 240008d2487e:8042, Resource: <memory:1024, vCores:1>, Priority: 10, Token: null, ] queue=default: capacity=1.0, absoluteCapacity=1.0, usedResources=<memory:2048, vCores:1>, usedCapacity=0.25, absoluteUsedCapacity=0.25, numApps=1, numContainers=1 clusterResource=<memory:8192, vCores:8>
2017-03-23 20:49:35,930 INFO org.apache.hadoop.yarn.server.resourcemanager.scheduler.capacity.ParentQueue: Re-sorting assigned queue: root.default stats: default: capacity=1.0, absoluteCapacity=1.0, usedResources=<memory:3072, vCores:2>, usedCapacity=0.375, absoluteUsedCapacity=0.375, numApps=1, numContainers=2
2017-03-23 20:49:35,930 INFO org.apache.hadoop.yarn.server.resourcemanager.scheduler.capacity.ParentQueue: assignedContainer queue=root usedCapacity=0.375 absoluteUsedCapacity=0.375 used=<memory:3072, vCores:2> cluster=<memory:8192, vCores:8>
2017-03-23 20:49:36,764 INFO org.apache.hadoop.yarn.server.resourcemanager.rmcontainer.RMContainerImpl: container_1490313515759_0008_01_000005 Container Transitioned from ALLOCATED to ACQUIRED
2017-03-23 20:49:36,933 INFO org.apache.hadoop.yarn.server.resourcemanager.rmcontainer.RMContainerImpl: container_1490313515759_0008_01_000005 Container Transitioned from ACQUIRED to RUNNING
2017-03-23 20:49:37,768 INFO org.apache.hadoop.yarn.server.resourcemanager.scheduler.AppSchedulingInfo: checking for deactivate of application :application_1490313515759_0008
2017-03-23 20:49:57,602 INFO org.apache.hadoop.yarn.server.resourcemanager.rmcontainer.RMContainerImpl: container_1490313515759_0008_01_000005 Container Transitioned from RUNNING to COMPLETED
2017-03-23 20:49:57,602 INFO org.apache.hadoop.yarn.server.resourcemanager.scheduler.common.fica.FiCaSchedulerApp: Completed container: container_1490313515759_0008_01_000005 in state: COMPLETED event:FINISHED
2017-03-23 20:49:57,602 INFO org.apache.hadoop.yarn.server.resourcemanager.RMAuditLogger: USER=root	OPERATION=AM Released Container	TARGET=SchedulerApp	RESULT=SUCCESS	APPID=application_1490313515759_0008	CONTAINERID=container_1490313515759_0008_01_000005
2017-03-23 20:49:57,603 INFO org.apache.hadoop.yarn.server.resourcemanager.scheduler.SchedulerNode: Released container container_1490313515759_0008_01_000005 of capacity <memory:1024, vCores:1> on host 240008d2487e:44869, which currently has 1 containers, <memory:2048, vCores:1> used and <memory:6144, vCores:7> available, release resources=true
2017-03-23 20:49:57,603 INFO org.apache.hadoop.yarn.server.resourcemanager.scheduler.capacity.LeafQueue: default used=<memory:2048, vCores:1> numContainers=1 user=root user-resources=<memory:2048, vCores:1>
2017-03-23 20:49:57,603 INFO org.apache.hadoop.yarn.server.resourcemanager.scheduler.capacity.LeafQueue: completedContainer container=Container: [ContainerId: container_1490313515759_0008_01_000005, NodeId: 240008d2487e:44869, NodeHttpAddress: 240008d2487e:8042, Resource: <memory:1024, vCores:1>, Priority: 10, Token: Token { kind: ContainerToken, service: 172.18.0.2:44869 }, ] queue=default: capacity=1.0, absoluteCapacity=1.0, usedResources=<memory:2048, vCores:1>, usedCapacity=0.25, absoluteUsedCapacity=0.25, numApps=1, numContainers=1 cluster=<memory:8192, vCores:8>
2017-03-23 20:49:57,603 INFO org.apache.hadoop.yarn.server.resourcemanager.scheduler.capacity.ParentQueue: completedContainer queue=root usedCapacity=0.25 absoluteUsedCapacity=0.25 used=<memory:2048, vCores:1> cluster=<memory:8192, vCores:8>
2017-03-23 20:49:57,603 INFO org.apache.hadoop.yarn.server.resourcemanager.scheduler.capacity.ParentQueue: Re-sorting completed queue: root.default stats: default: capacity=1.0, absoluteCapacity=1.0, usedResources=<memory:2048, vCores:1>, usedCapacity=0.25, absoluteUsedCapacity=0.25, numApps=1, numContainers=1
2017-03-23 20:49:57,604 INFO org.apache.hadoop.yarn.server.resourcemanager.scheduler.capacity.CapacityScheduler: Application attempt appattempt_1490313515759_0008_000001 released container container_1490313515759_0008_01_000005 on node: host: 240008d2487e:44869 #containers=1 available=<memory:6144, vCores:7> used=<memory:2048, vCores:1> with event: FINISHED
2017-03-23 20:49:58,609 INFO org.apache.hadoop.yarn.server.resourcemanager.rmcontainer.RMContainerImpl: container_1490313515759_0008_01_000006 Container Transitioned from NEW to ALLOCATED
2017-03-23 20:49:58,610 INFO org.apache.hadoop.yarn.server.resourcemanager.RMAuditLogger: USER=root	OPERATION=AM Allocated Container	TARGET=SchedulerApp	RESULT=SUCCESS	APPID=application_1490313515759_0008	CONTAINERID=container_1490313515759_0008_01_000006
2017-03-23 20:49:58,610 INFO org.apache.hadoop.yarn.server.resourcemanager.scheduler.SchedulerNode: Assigned container container_1490313515759_0008_01_000006 of capacity <memory:1024, vCores:1> on host 240008d2487e:44869, which has 2 containers, <memory:3072, vCores:2> used and <memory:5120, vCores:6> available after allocation
2017-03-23 20:49:58,610 INFO org.apache.hadoop.yarn.server.resourcemanager.scheduler.capacity.LeafQueue: assignedContainer application attempt=appattempt_1490313515759_0008_000001 container=Container: [ContainerId: container_1490313515759_0008_01_000006, NodeId: 240008d2487e:44869, NodeHttpAddress: 240008d2487e:8042, Resource: <memory:1024, vCores:1>, Priority: 10, Token: null, ] queue=default: capacity=1.0, absoluteCapacity=1.0, usedResources=<memory:2048, vCores:1>, usedCapacity=0.25, absoluteUsedCapacity=0.25, numApps=1, numContainers=1 clusterResource=<memory:8192, vCores:8>
2017-03-23 20:49:58,611 INFO org.apache.hadoop.yarn.server.resourcemanager.scheduler.capacity.ParentQueue: Re-sorting assigned queue: root.default stats: default: capacity=1.0, absoluteCapacity=1.0, usedResources=<memory:3072, vCores:2>, usedCapacity=0.375, absoluteUsedCapacity=0.375, numApps=1, numContainers=2
2017-03-23 20:49:58,611 INFO org.apache.hadoop.yarn.server.resourcemanager.scheduler.capacity.ParentQueue: assignedContainer queue=root usedCapacity=0.375 absoluteUsedCapacity=0.375 used=<memory:3072, vCores:2> cluster=<memory:8192, vCores:8>
2017-03-23 20:49:58,833 INFO org.apache.hadoop.yarn.server.resourcemanager.rmcontainer.RMContainerImpl: container_1490313515759_0008_01_000006 Container Transitioned from ALLOCATED to ACQUIRED
2017-03-23 20:49:59,607 INFO org.apache.hadoop.yarn.server.resourcemanager.rmcontainer.RMContainerImpl: container_1490313515759_0008_01_000006 Container Transitioned from ACQUIRED to RUNNING
2017-03-23 20:49:59,838 INFO org.apache.hadoop.yarn.server.resourcemanager.scheduler.AppSchedulingInfo: checking for deactivate of application :application_1490313515759_0008
2017-03-23 20:50:19,889 INFO org.apache.hadoop.yarn.server.resourcemanager.rmcontainer.RMContainerImpl: container_1490313515759_0008_01_000006 Container Transitioned from RUNNING to COMPLETED
2017-03-23 20:50:19,889 INFO org.apache.hadoop.yarn.server.resourcemanager.scheduler.common.fica.FiCaSchedulerApp: Completed container: container_1490313515759_0008_01_000006 in state: COMPLETED event:FINISHED
2017-03-23 20:50:19,889 INFO org.apache.hadoop.yarn.server.resourcemanager.RMAuditLogger: USER=root	OPERATION=AM Released Container	TARGET=SchedulerApp	RESULT=SUCCESS	APPID=application_1490313515759_0008	CONTAINERID=container_1490313515759_0008_01_000006
2017-03-23 20:50:19,889 INFO org.apache.hadoop.yarn.server.resourcemanager.scheduler.SchedulerNode: Released container container_1490313515759_0008_01_000006 of capacity <memory:1024, vCores:1> on host 240008d2487e:44869, which currently has 1 containers, <memory:2048, vCores:1> used and <memory:6144, vCores:7> available, release resources=true
2017-03-23 20:50:19,889 INFO org.apache.hadoop.yarn.server.resourcemanager.scheduler.capacity.LeafQueue: default used=<memory:2048, vCores:1> numContainers=1 user=root user-resources=<memory:2048, vCores:1>
2017-03-23 20:50:19,890 INFO org.apache.hadoop.yarn.server.resourcemanager.scheduler.capacity.LeafQueue: completedContainer container=Container: [ContainerId: container_1490313515759_0008_01_000006, NodeId: 240008d2487e:44869, NodeHttpAddress: 240008d2487e:8042, Resource: <memory:1024, vCores:1>, Priority: 10, Token: Token { kind: ContainerToken, service: 172.18.0.2:44869 }, ] queue=default: capacity=1.0, absoluteCapacity=1.0, usedResources=<memory:2048, vCores:1>, usedCapacity=0.25, absoluteUsedCapacity=0.25, numApps=1, numContainers=1 cluster=<memory:8192, vCores:8>
2017-03-23 20:50:19,890 INFO org.apache.hadoop.yarn.server.resourcemanager.scheduler.capacity.ParentQueue: completedContainer queue=root usedCapacity=0.25 absoluteUsedCapacity=0.25 used=<memory:2048, vCores:1> cluster=<memory:8192, vCores:8>
2017-03-23 20:50:19,890 INFO org.apache.hadoop.yarn.server.resourcemanager.scheduler.capacity.ParentQueue: Re-sorting completed queue: root.default stats: default: capacity=1.0, absoluteCapacity=1.0, usedResources=<memory:2048, vCores:1>, usedCapacity=0.25, absoluteUsedCapacity=0.25, numApps=1, numContainers=1
2017-03-23 20:50:19,890 INFO org.apache.hadoop.yarn.server.resourcemanager.scheduler.capacity.CapacityScheduler: Application attempt appattempt_1490313515759_0008_000001 released container container_1490313515759_0008_01_000006 on node: host: 240008d2487e:44869 #containers=1 available=<memory:6144, vCores:7> used=<memory:2048, vCores:1> with event: FINISHED
2017-03-23 20:50:19,896 INFO org.apache.hadoop.yarn.server.resourcemanager.ApplicationMasterService: blacklist are updated in Scheduler.blacklistAdditions: [240008d2487e], blacklistRemovals: []
2017-03-23 20:50:20,901 INFO org.apache.hadoop.yarn.server.resourcemanager.ApplicationMasterService: blacklist are updated in Scheduler.blacklistAdditions: [], blacklistRemovals: [240008d2487e]
2017-03-23 20:50:21,895 INFO org.apache.hadoop.yarn.server.resourcemanager.rmcontainer.RMContainerImpl: container_1490313515759_0008_01_000007 Container Transitioned from NEW to ALLOCATED
2017-03-23 20:50:21,895 INFO org.apache.hadoop.yarn.server.resourcemanager.RMAuditLogger: USER=root	OPERATION=AM Allocated Container	TARGET=SchedulerApp	RESULT=SUCCESS	APPID=application_1490313515759_0008	CONTAINERID=container_1490313515759_0008_01_000007
2017-03-23 20:50:21,895 INFO org.apache.hadoop.yarn.server.resourcemanager.scheduler.SchedulerNode: Assigned container container_1490313515759_0008_01_000007 of capacity <memory:1024, vCores:1> on host 240008d2487e:44869, which has 2 containers, <memory:3072, vCores:2> used and <memory:5120, vCores:6> available after allocation
2017-03-23 20:50:21,895 INFO org.apache.hadoop.yarn.server.resourcemanager.scheduler.capacity.LeafQueue: assignedContainer application attempt=appattempt_1490313515759_0008_000001 container=Container: [ContainerId: container_1490313515759_0008_01_000007, NodeId: 240008d2487e:44869, NodeHttpAddress: 240008d2487e:8042, Resource: <memory:1024, vCores:1>, Priority: 10, Token: null, ] queue=default: capacity=1.0, absoluteCapacity=1.0, usedResources=<memory:2048, vCores:1>, usedCapacity=0.25, absoluteUsedCapacity=0.25, numApps=1, numContainers=1 clusterResource=<memory:8192, vCores:8>
2017-03-23 20:50:21,895 INFO org.apache.hadoop.yarn.server.resourcemanager.scheduler.capacity.ParentQueue: Re-sorting assigned queue: root.default stats: default: capacity=1.0, absoluteCapacity=1.0, usedResources=<memory:3072, vCores:2>, usedCapacity=0.375, absoluteUsedCapacity=0.375, numApps=1, numContainers=2
2017-03-23 20:50:21,896 INFO org.apache.hadoop.yarn.server.resourcemanager.scheduler.capacity.ParentQueue: assignedContainer queue=root usedCapacity=0.375 absoluteUsedCapacity=0.375 used=<memory:3072, vCores:2> cluster=<memory:8192, vCores:8>
2017-03-23 20:50:21,906 INFO org.apache.hadoop.yarn.server.resourcemanager.rmcontainer.RMContainerImpl: container_1490313515759_0008_01_000007 Container Transitioned from ALLOCATED to ACQUIRED
2017-03-23 20:50:22,897 INFO org.apache.hadoop.yarn.server.resourcemanager.rmcontainer.RMContainerImpl: container_1490313515759_0008_01_000007 Container Transitioned from ACQUIRED to RUNNING
2017-03-23 20:50:22,911 INFO org.apache.hadoop.yarn.server.resourcemanager.scheduler.AppSchedulingInfo: checking for deactivate of application :application_1490313515759_0008
2017-03-23 20:50:37,681 INFO org.apache.hadoop.yarn.server.resourcemanager.ClientRMService: Allocated new applicationId: 9
2017-03-23 20:50:39,085 INFO org.apache.hadoop.yarn.server.resourcemanager.ClientRMService: Application with id 9 submitted by user root
2017-03-23 20:50:39,086 INFO org.apache.hadoop.yarn.server.resourcemanager.RMAuditLogger: USER=root	IP=172.18.0.2	OPERATION=Submit Application Request	TARGET=ClientRMService	RESULT=SUCCESS	APPID=application_1490313515759_0009
2017-03-23 20:50:39,086 INFO org.apache.hadoop.yarn.server.resourcemanager.rmapp.RMAppImpl: Storing application with id application_1490313515759_0009
2017-03-23 20:50:39,086 INFO org.apache.hadoop.yarn.server.resourcemanager.rmapp.RMAppImpl: application_1490313515759_0009 State change from NEW to NEW_SAVING
2017-03-23 20:50:39,086 INFO org.apache.hadoop.yarn.server.resourcemanager.recovery.RMStateStore: Storing info for app: application_1490313515759_0009
2017-03-23 20:50:39,087 INFO org.apache.hadoop.yarn.server.resourcemanager.rmapp.RMAppImpl: application_1490313515759_0009 State change from NEW_SAVING to SUBMITTED
2017-03-23 20:50:39,087 INFO org.apache.hadoop.yarn.server.resourcemanager.scheduler.capacity.ParentQueue: Application added - appId: application_1490313515759_0009 user: root leaf-queue of parent: root #applications: 2
2017-03-23 20:50:39,087 INFO org.apache.hadoop.yarn.server.resourcemanager.scheduler.capacity.CapacityScheduler: Accepted application application_1490313515759_0009 from user: root, in queue: default
2017-03-23 20:50:39,088 INFO org.apache.hadoop.yarn.server.resourcemanager.rmapp.RMAppImpl: application_1490313515759_0009 State change from SUBMITTED to ACCEPTED
2017-03-23 20:50:39,088 INFO org.apache.hadoop.yarn.server.resourcemanager.ApplicationMasterService: Registering app attempt : appattempt_1490313515759_0009_000001
2017-03-23 20:50:39,088 INFO org.apache.hadoop.yarn.server.resourcemanager.rmapp.attempt.RMAppAttemptImpl: appattempt_1490313515759_0009_000001 State change from NEW to SUBMITTED
2017-03-23 20:50:39,088 INFO org.apache.hadoop.yarn.server.resourcemanager.scheduler.capacity.LeafQueue: not starting application as amIfStarted exceeds amLimit
2017-03-23 20:50:39,089 INFO org.apache.hadoop.yarn.server.resourcemanager.scheduler.capacity.LeafQueue: Application added - appId: application_1490313515759_0009 user: org.apache.hadoop.yarn.server.resourcemanager.scheduler.capacity.LeafQueue$User@4b1131e, leaf-queue: default #user-pending-applications: 1 #user-active-applications: 1 #queue-pending-applications: 1 #queue-active-applications: 1
2017-03-23 20:50:39,089 INFO org.apache.hadoop.yarn.server.resourcemanager.scheduler.capacity.CapacityScheduler: Added Application Attempt appattempt_1490313515759_0009_000001 to scheduler from user root in queue default
2017-03-23 20:50:39,089 INFO org.apache.hadoop.yarn.server.resourcemanager.rmapp.attempt.RMAppAttemptImpl: appattempt_1490313515759_0009_000001 State change from SUBMITTED to SCHEDULED
2017-03-23 20:50:42,383 INFO org.apache.hadoop.yarn.server.resourcemanager.rmapp.attempt.RMAppAttemptImpl: Updating application attempt appattempt_1490313515759_0008_000001 with final state: FINISHING, and exit status: -1000
2017-03-23 20:50:42,383 INFO org.apache.hadoop.yarn.server.resourcemanager.rmapp.attempt.RMAppAttemptImpl: appattempt_1490313515759_0008_000001 State change from RUNNING to FINAL_SAVING
2017-03-23 20:50:42,383 INFO org.apache.hadoop.yarn.server.resourcemanager.rmapp.RMAppImpl: Updating application application_1490313515759_0008 with final state: FINISHING
2017-03-23 20:50:42,384 INFO org.apache.hadoop.yarn.server.resourcemanager.rmapp.RMAppImpl: application_1490313515759_0008 State change from RUNNING to FINAL_SAVING
2017-03-23 20:50:42,384 INFO org.apache.hadoop.yarn.server.resourcemanager.recovery.RMStateStore: Updating info for app: application_1490313515759_0008
2017-03-23 20:50:42,384 INFO org.apache.hadoop.yarn.server.resourcemanager.rmapp.attempt.RMAppAttemptImpl: appattempt_1490313515759_0008_000001 State change from FINAL_SAVING to FINISHING
2017-03-23 20:50:42,384 INFO org.apache.hadoop.yarn.server.resourcemanager.rmapp.RMAppImpl: application_1490313515759_0008 State change from FINAL_SAVING to FINISHING
2017-03-23 20:50:43,090 INFO org.apache.hadoop.yarn.server.resourcemanager.rmcontainer.RMContainerImpl: container_1490313515759_0008_01_000007 Container Transitioned from RUNNING to COMPLETED
2017-03-23 20:50:43,090 INFO org.apache.hadoop.yarn.server.resourcemanager.scheduler.common.fica.FiCaSchedulerApp: Completed container: container_1490313515759_0008_01_000007 in state: COMPLETED event:FINISHED
2017-03-23 20:50:43,090 INFO org.apache.hadoop.yarn.server.resourcemanager.RMAuditLogger: USER=root	OPERATION=AM Released Container	TARGET=SchedulerApp	RESULT=SUCCESS	APPID=application_1490313515759_0008	CONTAINERID=container_1490313515759_0008_01_000007
2017-03-23 20:50:43,090 INFO org.apache.hadoop.yarn.server.resourcemanager.scheduler.SchedulerNode: Released container container_1490313515759_0008_01_000007 of capacity <memory:1024, vCores:1> on host 240008d2487e:44869, which currently has 1 containers, <memory:2048, vCores:1> used and <memory:6144, vCores:7> available, release resources=true
2017-03-23 20:50:43,090 INFO org.apache.hadoop.yarn.server.resourcemanager.scheduler.capacity.LeafQueue: default used=<memory:2048, vCores:1> numContainers=1 user=root user-resources=<memory:2048, vCores:1>
2017-03-23 20:50:43,091 INFO org.apache.hadoop.yarn.server.resourcemanager.scheduler.capacity.LeafQueue: completedContainer container=Container: [ContainerId: container_1490313515759_0008_01_000007, NodeId: 240008d2487e:44869, NodeHttpAddress: 240008d2487e:8042, Resource: <memory:1024, vCores:1>, Priority: 10, Token: Token { kind: ContainerToken, service: 172.18.0.2:44869 }, ] queue=default: capacity=1.0, absoluteCapacity=1.0, usedResources=<memory:2048, vCores:1>, usedCapacity=0.25, absoluteUsedCapacity=0.25, numApps=2, numContainers=1 cluster=<memory:8192, vCores:8>
2017-03-23 20:50:43,091 INFO org.apache.hadoop.yarn.server.resourcemanager.scheduler.capacity.ParentQueue: completedContainer queue=root usedCapacity=0.25 absoluteUsedCapacity=0.25 used=<memory:2048, vCores:1> cluster=<memory:8192, vCores:8>
2017-03-23 20:50:43,091 INFO org.apache.hadoop.yarn.server.resourcemanager.scheduler.capacity.ParentQueue: Re-sorting completed queue: root.default stats: default: capacity=1.0, absoluteCapacity=1.0, usedResources=<memory:2048, vCores:1>, usedCapacity=0.25, absoluteUsedCapacity=0.25, numApps=2, numContainers=1
2017-03-23 20:50:43,091 INFO org.apache.hadoop.yarn.server.resourcemanager.scheduler.capacity.CapacityScheduler: Application attempt appattempt_1490313515759_0008_000001 released container container_1490313515759_0008_01_000007 on node: host: 240008d2487e:44869 #containers=1 available=<memory:6144, vCores:7> used=<memory:2048, vCores:1> with event: FINISHED
2017-03-23 20:50:43,387 INFO org.apache.hadoop.yarn.server.resourcemanager.ApplicationMasterService: application_1490313515759_0008 unregistered successfully. 
2017-03-23 20:50:49,106 INFO org.apache.hadoop.yarn.server.resourcemanager.rmcontainer.RMContainerImpl: container_1490313515759_0008_01_000001 Container Transitioned from RUNNING to COMPLETED
2017-03-23 20:50:49,106 INFO org.apache.hadoop.yarn.server.resourcemanager.ApplicationMasterService: Unregistering app attempt : appattempt_1490313515759_0008_000001
2017-03-23 20:50:49,106 INFO org.apache.hadoop.yarn.server.resourcemanager.scheduler.common.fica.FiCaSchedulerApp: Completed container: container_1490313515759_0008_01_000001 in state: COMPLETED event:FINISHED
2017-03-23 20:50:49,106 INFO org.apache.hadoop.yarn.server.resourcemanager.security.AMRMTokenSecretManager: Application finished, removing password for appattempt_1490313515759_0008_000001
2017-03-23 20:50:49,106 INFO org.apache.hadoop.yarn.server.resourcemanager.RMAuditLogger: USER=root	OPERATION=AM Released Container	TARGET=SchedulerApp	RESULT=SUCCESS	APPID=application_1490313515759_0008	CONTAINERID=container_1490313515759_0008_01_000001
2017-03-23 20:50:49,106 INFO org.apache.hadoop.yarn.server.resourcemanager.rmapp.attempt.RMAppAttemptImpl: appattempt_1490313515759_0008_000001 State change from FINISHING to FINISHED
2017-03-23 20:50:49,106 INFO org.apache.hadoop.yarn.server.resourcemanager.scheduler.SchedulerNode: Released container container_1490313515759_0008_01_000001 of capacity <memory:2048, vCores:1> on host 240008d2487e:44869, which currently has 0 containers, <memory:0, vCores:0> used and <memory:8192, vCores:8> available, release resources=true
2017-03-23 20:50:49,106 INFO org.apache.hadoop.yarn.server.resourcemanager.rmapp.RMAppImpl: application_1490313515759_0008 State change from FINISHING to FINISHED
2017-03-23 20:50:49,106 INFO org.apache.hadoop.yarn.server.resourcemanager.scheduler.capacity.LeafQueue: default used=<memory:0, vCores:0> numContainers=0 user=root user-resources=<memory:0, vCores:0>
2017-03-23 20:50:49,106 INFO org.apache.hadoop.yarn.server.resourcemanager.RMAuditLogger: USER=root	OPERATION=Application Finished - Succeeded	TARGET=RMAppManager	RESULT=SUCCESS	APPID=application_1490313515759_0008
2017-03-23 20:50:49,106 INFO org.apache.hadoop.yarn.server.resourcemanager.scheduler.capacity.LeafQueue: completedContainer container=Container: [ContainerId: container_1490313515759_0008_01_000001, NodeId: 240008d2487e:44869, NodeHttpAddress: 240008d2487e:8042, Resource: <memory:2048, vCores:1>, Priority: 0, Token: Token { kind: ContainerToken, service: 172.18.0.2:44869 }, ] queue=default: capacity=1.0, absoluteCapacity=1.0, usedResources=<memory:0, vCores:0>, usedCapacity=0.0, absoluteUsedCapacity=0.0, numApps=2, numContainers=0 cluster=<memory:8192, vCores:8>
2017-03-23 20:50:49,106 INFO org.apache.hadoop.yarn.server.resourcemanager.scheduler.capacity.ParentQueue: completedContainer queue=root usedCapacity=0.0 absoluteUsedCapacity=0.0 used=<memory:0, vCores:0> cluster=<memory:8192, vCores:8>
2017-03-23 20:50:49,106 INFO org.apache.hadoop.yarn.server.resourcemanager.scheduler.capacity.ParentQueue: Re-sorting completed queue: root.default stats: default: capacity=1.0, absoluteCapacity=1.0, usedResources=<memory:0, vCores:0>, usedCapacity=0.0, absoluteUsedCapacity=0.0, numApps=2, numContainers=0
2017-03-23 20:50:49,107 INFO org.apache.hadoop.yarn.server.resourcemanager.scheduler.capacity.CapacityScheduler: Application attempt appattempt_1490313515759_0008_000001 released container container_1490313515759_0008_01_000001 on node: host: 240008d2487e:44869 #containers=0 available=<memory:8192, vCores:8> used=<memory:0, vCores:0> with event: FINISHED
2017-03-23 20:50:49,107 INFO org.apache.hadoop.yarn.server.resourcemanager.scheduler.capacity.CapacityScheduler: Application Attempt appattempt_1490313515759_0008_000001 is done. finalState=FINISHED
2017-03-23 20:50:49,107 INFO org.apache.hadoop.yarn.server.resourcemanager.RMAppManager$ApplicationSummary: appId=application_1490313515759_0008,name=streamjob6205821703508703659.jar,user=root,queue=default,state=FINISHED,trackingUrl=http://240008d2487e:8088/proxy/application_1490313515759_0008/,appMasterHost=240008d2487e,startTime=1490316529477,finishTime=1490316642383,finalStatus=FAILED,memorySeconds=360632,vcoreSeconds=229,preemptedAMContainers=0,preemptedNonAMContainers=0,preemptedResources=<memory:0\, vCores:0>,applicationType=MAPREDUCE
2017-03-23 20:50:49,107 INFO org.apache.hadoop.yarn.server.resourcemanager.scheduler.AppSchedulingInfo: Application application_1490313515759_0008 requests cleared
2017-03-23 20:50:49,108 INFO org.apache.hadoop.yarn.server.resourcemanager.amlauncher.AMLauncher: Cleaning master appattempt_1490313515759_0008_000001
2017-03-23 20:50:49,108 WARN org.apache.hadoop.yarn.server.resourcemanager.scheduler.capacity.LeafQueue: maximum-am-resource-percent is insufficient to start a single application in queue, it is likely set too low. skipping enforcement to allow at least one application to start
2017-03-23 20:50:49,108 WARN org.apache.hadoop.yarn.server.resourcemanager.scheduler.capacity.LeafQueue: maximum-am-resource-percent is insufficient to start a single application in queue for user, it is likely set too low. skipping enforcement to allow at least one application to start
2017-03-23 20:50:49,108 INFO org.apache.hadoop.yarn.server.resourcemanager.scheduler.capacity.LeafQueue: Application application_1490313515759_0009 from user: root activated in queue: default
2017-03-23 20:50:49,108 INFO org.apache.hadoop.yarn.server.resourcemanager.scheduler.capacity.LeafQueue: Application removed - appId: application_1490313515759_0008 user: root queue: default #user-pending-applications: 0 #user-active-applications: 1 #queue-pending-applications: 0 #queue-active-applications: 1
2017-03-23 20:50:49,108 INFO org.apache.hadoop.yarn.server.resourcemanager.scheduler.capacity.ParentQueue: Application removed - appId: application_1490313515759_0008 user: root leaf-queue of parent: root #applications: 1
2017-03-23 20:50:49,122 INFO org.apache.hadoop.yarn.server.resourcemanager.rmcontainer.RMContainerImpl: container_1490313515759_0009_01_000001 Container Transitioned from NEW to ALLOCATED
2017-03-23 20:50:49,123 INFO org.apache.hadoop.yarn.server.resourcemanager.RMAuditLogger: USER=root	OPERATION=AM Allocated Container	TARGET=SchedulerApp	RESULT=SUCCESS	APPID=application_1490313515759_0009	CONTAINERID=container_1490313515759_0009_01_000001
2017-03-23 20:50:49,123 INFO org.apache.hadoop.yarn.server.resourcemanager.scheduler.SchedulerNode: Assigned container container_1490313515759_0009_01_000001 of capacity <memory:2048, vCores:1> on host 240008d2487e:44869, which has 1 containers, <memory:2048, vCores:1> used and <memory:6144, vCores:7> available after allocation
2017-03-23 20:50:49,123 INFO org.apache.hadoop.yarn.server.resourcemanager.scheduler.capacity.LeafQueue: assignedContainer application attempt=appattempt_1490313515759_0009_000001 container=Container: [ContainerId: container_1490313515759_0009_01_000001, NodeId: 240008d2487e:44869, NodeHttpAddress: 240008d2487e:8042, Resource: <memory:2048, vCores:1>, Priority: 0, Token: null, ] queue=default: capacity=1.0, absoluteCapacity=1.0, usedResources=<memory:0, vCores:0>, usedCapacity=0.0, absoluteUsedCapacity=0.0, numApps=1, numContainers=0 clusterResource=<memory:8192, vCores:8>
2017-03-23 20:50:49,123 INFO org.apache.hadoop.yarn.server.resourcemanager.scheduler.capacity.ParentQueue: Re-sorting assigned queue: root.default stats: default: capacity=1.0, absoluteCapacity=1.0, usedResources=<memory:2048, vCores:1>, usedCapacity=0.25, absoluteUsedCapacity=0.25, numApps=1, numContainers=1
2017-03-23 20:50:49,123 INFO org.apache.hadoop.yarn.server.resourcemanager.scheduler.capacity.ParentQueue: assignedContainer queue=root usedCapacity=0.25 absoluteUsedCapacity=0.25 used=<memory:2048, vCores:1> cluster=<memory:8192, vCores:8>
2017-03-23 20:50:49,125 INFO org.apache.hadoop.yarn.server.resourcemanager.security.NMTokenSecretManagerInRM: Sending NMToken for nodeId : 240008d2487e:44869 for container : container_1490313515759_0009_01_000001
2017-03-23 20:50:49,127 INFO org.apache.hadoop.yarn.server.resourcemanager.rmcontainer.RMContainerImpl: container_1490313515759_0009_01_000001 Container Transitioned from ALLOCATED to ACQUIRED
2017-03-23 20:50:49,127 INFO org.apache.hadoop.yarn.server.resourcemanager.security.NMTokenSecretManagerInRM: Clear node set for appattempt_1490313515759_0009_000001
2017-03-23 20:50:49,127 INFO org.apache.hadoop.yarn.server.resourcemanager.rmapp.attempt.RMAppAttemptImpl: Storing attempt: AppId: application_1490313515759_0009 AttemptId: appattempt_1490313515759_0009_000001 MasterContainer: Container: [ContainerId: container_1490313515759_0009_01_000001, NodeId: 240008d2487e:44869, NodeHttpAddress: 240008d2487e:8042, Resource: <memory:2048, vCores:1>, Priority: 0, Token: Token { kind: ContainerToken, service: 172.18.0.2:44869 }, ]
2017-03-23 20:50:49,127 INFO org.apache.hadoop.yarn.server.resourcemanager.rmapp.attempt.RMAppAttemptImpl: appattempt_1490313515759_0009_000001 State change from SCHEDULED to ALLOCATED_SAVING
2017-03-23 20:50:49,128 INFO org.apache.hadoop.yarn.server.resourcemanager.rmapp.attempt.RMAppAttemptImpl: appattempt_1490313515759_0009_000001 State change from ALLOCATED_SAVING to ALLOCATED
2017-03-23 20:50:49,128 INFO org.apache.hadoop.yarn.server.resourcemanager.amlauncher.AMLauncher: Launching masterappattempt_1490313515759_0009_000001
2017-03-23 20:50:49,130 INFO org.apache.hadoop.yarn.server.resourcemanager.amlauncher.AMLauncher: Setting up container Container: [ContainerId: container_1490313515759_0009_01_000001, NodeId: 240008d2487e:44869, NodeHttpAddress: 240008d2487e:8042, Resource: <memory:2048, vCores:1>, Priority: 0, Token: Token { kind: ContainerToken, service: 172.18.0.2:44869 }, ] for AM appattempt_1490313515759_0009_000001
2017-03-23 20:50:49,130 INFO org.apache.hadoop.yarn.server.resourcemanager.amlauncher.AMLauncher: Command to launch container container_1490313515759_0009_01_000001 : $JAVA_HOME/bin/java -Dlog4j.configuration=container-log4j.properties -Dyarn.app.container.log.dir=<LOG_DIR> -Dyarn.app.container.log.filesize=0 -Dhadoop.root.logger=INFO,CLA -Dhadoop.root.logfile=syslog  -Xmx1024m org.apache.hadoop.mapreduce.v2.app.MRAppMaster 1><LOG_DIR>/stdout 2><LOG_DIR>/stderr 
2017-03-23 20:50:49,131 INFO org.apache.hadoop.yarn.server.resourcemanager.security.AMRMTokenSecretManager: Create AMRMToken for ApplicationAttempt: appattempt_1490313515759_0009_000001
2017-03-23 20:50:49,131 INFO org.apache.hadoop.yarn.server.resourcemanager.security.AMRMTokenSecretManager: Creating password for appattempt_1490313515759_0009_000001
2017-03-23 20:50:49,143 INFO org.apache.hadoop.yarn.server.resourcemanager.amlauncher.AMLauncher: Done launching container Container: [ContainerId: container_1490313515759_0009_01_000001, NodeId: 240008d2487e:44869, NodeHttpAddress: 240008d2487e:8042, Resource: <memory:2048, vCores:1>, Priority: 0, Token: Token { kind: ContainerToken, service: 172.18.0.2:44869 }, ] for AM appattempt_1490313515759_0009_000001
2017-03-23 20:50:49,143 INFO org.apache.hadoop.yarn.server.resourcemanager.rmapp.attempt.RMAppAttemptImpl: appattempt_1490313515759_0009_000001 State change from ALLOCATED to LAUNCHED
2017-03-23 20:50:50,129 INFO org.apache.hadoop.yarn.server.resourcemanager.rmcontainer.RMContainerImpl: container_1490313515759_0009_01_000001 Container Transitioned from ACQUIRED to RUNNING
2017-03-23 20:50:50,129 INFO org.apache.hadoop.yarn.server.resourcemanager.scheduler.capacity.CapacityScheduler: Null container completed...
2017-03-23 20:50:54,335 INFO SecurityLogger.org.apache.hadoop.ipc.Server: Auth successful for appattempt_1490313515759_0009_000001 (auth:SIMPLE)
2017-03-23 20:50:54,341 INFO org.apache.hadoop.yarn.server.resourcemanager.ApplicationMasterService: AM registration appattempt_1490313515759_0009_000001
2017-03-23 20:50:54,341 INFO org.apache.hadoop.yarn.server.resourcemanager.RMAuditLogger: USER=root	IP=172.18.0.2	OPERATION=Register App Master	TARGET=ApplicationMasterService	RESULT=SUCCESS	APPID=application_1490313515759_0009	APPATTEMPTID=appattempt_1490313515759_0009_000001
2017-03-23 20:50:54,341 INFO org.apache.hadoop.yarn.server.resourcemanager.rmapp.attempt.RMAppAttemptImpl: appattempt_1490313515759_0009_000001 State change from LAUNCHED to RUNNING
2017-03-23 20:50:54,341 INFO org.apache.hadoop.yarn.server.resourcemanager.rmapp.RMAppImpl: application_1490313515759_0009 State change from ACCEPTED to RUNNING
2017-03-23 20:50:56,141 INFO org.apache.hadoop.yarn.server.resourcemanager.rmcontainer.RMContainerImpl: container_1490313515759_0009_01_000002 Container Transitioned from NEW to ALLOCATED
2017-03-23 20:50:56,142 INFO org.apache.hadoop.yarn.server.resourcemanager.RMAuditLogger: USER=root	OPERATION=AM Allocated Container	TARGET=SchedulerApp	RESULT=SUCCESS	APPID=application_1490313515759_0009	CONTAINERID=container_1490313515759_0009_01_000002
2017-03-23 20:50:56,142 INFO org.apache.hadoop.yarn.server.resourcemanager.scheduler.SchedulerNode: Assigned container container_1490313515759_0009_01_000002 of capacity <memory:1024, vCores:1> on host 240008d2487e:44869, which has 2 containers, <memory:3072, vCores:2> used and <memory:5120, vCores:6> available after allocation
2017-03-23 20:50:56,142 INFO org.apache.hadoop.yarn.server.resourcemanager.scheduler.capacity.LeafQueue: assignedContainer application attempt=appattempt_1490313515759_0009_000001 container=Container: [ContainerId: container_1490313515759_0009_01_000002, NodeId: 240008d2487e:44869, NodeHttpAddress: 240008d2487e:8042, Resource: <memory:1024, vCores:1>, Priority: 20, Token: null, ] queue=default: capacity=1.0, absoluteCapacity=1.0, usedResources=<memory:2048, vCores:1>, usedCapacity=0.25, absoluteUsedCapacity=0.25, numApps=1, numContainers=1 clusterResource=<memory:8192, vCores:8>
2017-03-23 20:50:56,142 INFO org.apache.hadoop.yarn.server.resourcemanager.scheduler.capacity.ParentQueue: Re-sorting assigned queue: root.default stats: default: capacity=1.0, absoluteCapacity=1.0, usedResources=<memory:3072, vCores:2>, usedCapacity=0.375, absoluteUsedCapacity=0.375, numApps=1, numContainers=2
2017-03-23 20:50:56,142 INFO org.apache.hadoop.yarn.server.resourcemanager.scheduler.capacity.ParentQueue: assignedContainer queue=root usedCapacity=0.375 absoluteUsedCapacity=0.375 used=<memory:3072, vCores:2> cluster=<memory:8192, vCores:8>
2017-03-23 20:50:56,143 INFO org.apache.hadoop.yarn.server.resourcemanager.rmcontainer.RMContainerImpl: container_1490313515759_0009_01_000003 Container Transitioned from NEW to ALLOCATED
2017-03-23 20:50:56,143 INFO org.apache.hadoop.yarn.server.resourcemanager.RMAuditLogger: USER=root	OPERATION=AM Allocated Container	TARGET=SchedulerApp	RESULT=SUCCESS	APPID=application_1490313515759_0009	CONTAINERID=container_1490313515759_0009_01_000003
2017-03-23 20:50:56,143 INFO org.apache.hadoop.yarn.server.resourcemanager.scheduler.SchedulerNode: Assigned container container_1490313515759_0009_01_000003 of capacity <memory:1024, vCores:1> on host 240008d2487e:44869, which has 3 containers, <memory:4096, vCores:3> used and <memory:4096, vCores:5> available after allocation
2017-03-23 20:50:56,143 INFO org.apache.hadoop.yarn.server.resourcemanager.scheduler.capacity.LeafQueue: assignedContainer application attempt=appattempt_1490313515759_0009_000001 container=Container: [ContainerId: container_1490313515759_0009_01_000003, NodeId: 240008d2487e:44869, NodeHttpAddress: 240008d2487e:8042, Resource: <memory:1024, vCores:1>, Priority: 20, Token: null, ] queue=default: capacity=1.0, absoluteCapacity=1.0, usedResources=<memory:3072, vCores:2>, usedCapacity=0.375, absoluteUsedCapacity=0.375, numApps=1, numContainers=2 clusterResource=<memory:8192, vCores:8>
2017-03-23 20:50:56,143 INFO org.apache.hadoop.yarn.server.resourcemanager.scheduler.capacity.ParentQueue: Re-sorting assigned queue: root.default stats: default: capacity=1.0, absoluteCapacity=1.0, usedResources=<memory:4096, vCores:3>, usedCapacity=0.5, absoluteUsedCapacity=0.5, numApps=1, numContainers=3
2017-03-23 20:50:56,143 INFO org.apache.hadoop.yarn.server.resourcemanager.scheduler.capacity.ParentQueue: assignedContainer queue=root usedCapacity=0.5 absoluteUsedCapacity=0.5 used=<memory:4096, vCores:3> cluster=<memory:8192, vCores:8>
2017-03-23 20:50:56,437 INFO org.apache.hadoop.yarn.server.resourcemanager.security.NMTokenSecretManagerInRM: Sending NMToken for nodeId : 240008d2487e:44869 for container : container_1490313515759_0009_01_000002
2017-03-23 20:50:56,440 INFO org.apache.hadoop.yarn.server.resourcemanager.rmcontainer.RMContainerImpl: container_1490313515759_0009_01_000002 Container Transitioned from ALLOCATED to ACQUIRED
2017-03-23 20:50:56,441 INFO org.apache.hadoop.yarn.server.resourcemanager.rmcontainer.RMContainerImpl: container_1490313515759_0009_01_000003 Container Transitioned from ALLOCATED to ACQUIRED
2017-03-23 20:50:57,145 INFO org.apache.hadoop.yarn.server.resourcemanager.rmcontainer.RMContainerImpl: container_1490313515759_0009_01_000002 Container Transitioned from ACQUIRED to RUNNING
2017-03-23 20:50:57,145 INFO org.apache.hadoop.yarn.server.resourcemanager.rmcontainer.RMContainerImpl: container_1490313515759_0009_01_000003 Container Transitioned from ACQUIRED to RUNNING
2017-03-23 20:50:57,458 INFO org.apache.hadoop.yarn.server.resourcemanager.scheduler.AppSchedulingInfo: checking for deactivate of application :application_1490313515759_0009
2017-03-23 20:51:10,797 INFO org.apache.hadoop.yarn.server.resourcemanager.rmcontainer.RMContainerImpl: container_1490313515759_0009_01_000002 Container Transitioned from RUNNING to COMPLETED
2017-03-23 20:51:10,798 INFO org.apache.hadoop.yarn.server.resourcemanager.scheduler.common.fica.FiCaSchedulerApp: Completed container: container_1490313515759_0009_01_000002 in state: COMPLETED event:FINISHED
2017-03-23 20:51:10,798 INFO org.apache.hadoop.yarn.server.resourcemanager.RMAuditLogger: USER=root	OPERATION=AM Released Container	TARGET=SchedulerApp	RESULT=SUCCESS	APPID=application_1490313515759_0009	CONTAINERID=container_1490313515759_0009_01_000002
2017-03-23 20:51:10,798 INFO org.apache.hadoop.yarn.server.resourcemanager.scheduler.SchedulerNode: Released container container_1490313515759_0009_01_000002 of capacity <memory:1024, vCores:1> on host 240008d2487e:44869, which currently has 2 containers, <memory:3072, vCores:2> used and <memory:5120, vCores:6> available, release resources=true
2017-03-23 20:51:10,798 INFO org.apache.hadoop.yarn.server.resourcemanager.scheduler.capacity.LeafQueue: default used=<memory:3072, vCores:2> numContainers=2 user=root user-resources=<memory:3072, vCores:2>
2017-03-23 20:51:10,798 INFO org.apache.hadoop.yarn.server.resourcemanager.scheduler.capacity.LeafQueue: completedContainer container=Container: [ContainerId: container_1490313515759_0009_01_000002, NodeId: 240008d2487e:44869, NodeHttpAddress: 240008d2487e:8042, Resource: <memory:1024, vCores:1>, Priority: 20, Token: Token { kind: ContainerToken, service: 172.18.0.2:44869 }, ] queue=default: capacity=1.0, absoluteCapacity=1.0, usedResources=<memory:3072, vCores:2>, usedCapacity=0.375, absoluteUsedCapacity=0.375, numApps=1, numContainers=2 cluster=<memory:8192, vCores:8>
2017-03-23 20:51:10,799 INFO org.apache.hadoop.yarn.server.resourcemanager.scheduler.capacity.ParentQueue: completedContainer queue=root usedCapacity=0.375 absoluteUsedCapacity=0.375 used=<memory:3072, vCores:2> cluster=<memory:8192, vCores:8>
2017-03-23 20:51:10,799 INFO org.apache.hadoop.yarn.server.resourcemanager.scheduler.capacity.ParentQueue: Re-sorting completed queue: root.default stats: default: capacity=1.0, absoluteCapacity=1.0, usedResources=<memory:3072, vCores:2>, usedCapacity=0.375, absoluteUsedCapacity=0.375, numApps=1, numContainers=2
2017-03-23 20:51:10,799 INFO org.apache.hadoop.yarn.server.resourcemanager.scheduler.capacity.CapacityScheduler: Application attempt appattempt_1490313515759_0009_000001 released container container_1490313515759_0009_01_000002 on node: host: 240008d2487e:44869 #containers=2 available=<memory:5120, vCores:6> used=<memory:3072, vCores:2> with event: FINISHED
2017-03-23 20:51:11,800 INFO org.apache.hadoop.yarn.server.resourcemanager.rmcontainer.RMContainerImpl: container_1490313515759_0009_01_000003 Container Transitioned from RUNNING to COMPLETED
2017-03-23 20:51:11,800 INFO org.apache.hadoop.yarn.server.resourcemanager.scheduler.common.fica.FiCaSchedulerApp: Completed container: container_1490313515759_0009_01_000003 in state: COMPLETED event:FINISHED
2017-03-23 20:51:11,800 INFO org.apache.hadoop.yarn.server.resourcemanager.RMAuditLogger: USER=root	OPERATION=AM Released Container	TARGET=SchedulerApp	RESULT=SUCCESS	APPID=application_1490313515759_0009	CONTAINERID=container_1490313515759_0009_01_000003
2017-03-23 20:51:11,800 INFO org.apache.hadoop.yarn.server.resourcemanager.scheduler.SchedulerNode: Released container container_1490313515759_0009_01_000003 of capacity <memory:1024, vCores:1> on host 240008d2487e:44869, which currently has 1 containers, <memory:2048, vCores:1> used and <memory:6144, vCores:7> available, release resources=true
2017-03-23 20:51:11,800 INFO org.apache.hadoop.yarn.server.resourcemanager.scheduler.capacity.LeafQueue: default used=<memory:2048, vCores:1> numContainers=1 user=root user-resources=<memory:2048, vCores:1>
2017-03-23 20:51:11,801 INFO org.apache.hadoop.yarn.server.resourcemanager.scheduler.capacity.LeafQueue: completedContainer container=Container: [ContainerId: container_1490313515759_0009_01_000003, NodeId: 240008d2487e:44869, NodeHttpAddress: 240008d2487e:8042, Resource: <memory:1024, vCores:1>, Priority: 20, Token: Token { kind: ContainerToken, service: 172.18.0.2:44869 }, ] queue=default: capacity=1.0, absoluteCapacity=1.0, usedResources=<memory:2048, vCores:1>, usedCapacity=0.25, absoluteUsedCapacity=0.25, numApps=1, numContainers=1 cluster=<memory:8192, vCores:8>
2017-03-23 20:51:11,801 INFO org.apache.hadoop.yarn.server.resourcemanager.scheduler.capacity.ParentQueue: completedContainer queue=root usedCapacity=0.25 absoluteUsedCapacity=0.25 used=<memory:2048, vCores:1> cluster=<memory:8192, vCores:8>
2017-03-23 20:51:11,801 INFO org.apache.hadoop.yarn.server.resourcemanager.scheduler.capacity.ParentQueue: Re-sorting completed queue: root.default stats: default: capacity=1.0, absoluteCapacity=1.0, usedResources=<memory:2048, vCores:1>, usedCapacity=0.25, absoluteUsedCapacity=0.25, numApps=1, numContainers=1
2017-03-23 20:51:11,801 INFO org.apache.hadoop.yarn.server.resourcemanager.scheduler.capacity.CapacityScheduler: Application attempt appattempt_1490313515759_0009_000001 released container container_1490313515759_0009_01_000003 on node: host: 240008d2487e:44869 #containers=1 available=<memory:6144, vCores:7> used=<memory:2048, vCores:1> with event: FINISHED
2017-03-23 20:51:11,802 INFO org.apache.hadoop.yarn.server.resourcemanager.rmcontainer.RMContainerImpl: container_1490313515759_0009_01_000004 Container Transitioned from NEW to ALLOCATED
2017-03-23 20:51:11,802 INFO org.apache.hadoop.yarn.server.resourcemanager.RMAuditLogger: USER=root	OPERATION=AM Allocated Container	TARGET=SchedulerApp	RESULT=SUCCESS	APPID=application_1490313515759_0009	CONTAINERID=container_1490313515759_0009_01_000004
2017-03-23 20:51:11,802 INFO org.apache.hadoop.yarn.server.resourcemanager.scheduler.SchedulerNode: Assigned container container_1490313515759_0009_01_000004 of capacity <memory:1024, vCores:1> on host 240008d2487e:44869, which has 2 containers, <memory:3072, vCores:2> used and <memory:5120, vCores:6> available after allocation
2017-03-23 20:51:11,802 INFO org.apache.hadoop.yarn.server.resourcemanager.scheduler.capacity.LeafQueue: assignedContainer application attempt=appattempt_1490313515759_0009_000001 container=Container: [ContainerId: container_1490313515759_0009_01_000004, NodeId: 240008d2487e:44869, NodeHttpAddress: 240008d2487e:8042, Resource: <memory:1024, vCores:1>, Priority: 10, Token: null, ] queue=default: capacity=1.0, absoluteCapacity=1.0, usedResources=<memory:2048, vCores:1>, usedCapacity=0.25, absoluteUsedCapacity=0.25, numApps=1, numContainers=1 clusterResource=<memory:8192, vCores:8>
2017-03-23 20:51:11,802 INFO org.apache.hadoop.yarn.server.resourcemanager.scheduler.capacity.ParentQueue: Re-sorting assigned queue: root.default stats: default: capacity=1.0, absoluteCapacity=1.0, usedResources=<memory:3072, vCores:2>, usedCapacity=0.375, absoluteUsedCapacity=0.375, numApps=1, numContainers=2
2017-03-23 20:51:11,802 INFO org.apache.hadoop.yarn.server.resourcemanager.scheduler.capacity.ParentQueue: assignedContainer queue=root usedCapacity=0.375 absoluteUsedCapacity=0.375 used=<memory:3072, vCores:2> cluster=<memory:8192, vCores:8>
2017-03-23 20:51:12,511 INFO org.apache.hadoop.yarn.server.resourcemanager.rmcontainer.RMContainerImpl: container_1490313515759_0009_01_000004 Container Transitioned from ALLOCATED to ACQUIRED
2017-03-23 20:51:12,802 INFO org.apache.hadoop.yarn.server.resourcemanager.rmcontainer.RMContainerImpl: container_1490313515759_0009_01_000004 Container Transitioned from ACQUIRED to RUNNING
2017-03-23 20:51:13,516 INFO org.apache.hadoop.yarn.server.resourcemanager.scheduler.AppSchedulingInfo: checking for deactivate of application :application_1490313515759_0009
2017-03-23 20:51:33,208 INFO org.apache.hadoop.yarn.server.resourcemanager.rmapp.attempt.RMAppAttemptImpl: Updating application attempt appattempt_1490313515759_0009_000001 with final state: FINISHING, and exit status: -1000
2017-03-23 20:51:33,208 INFO org.apache.hadoop.yarn.server.resourcemanager.rmapp.attempt.RMAppAttemptImpl: appattempt_1490313515759_0009_000001 State change from RUNNING to FINAL_SAVING
2017-03-23 20:51:33,208 INFO org.apache.hadoop.yarn.server.resourcemanager.rmapp.RMAppImpl: Updating application application_1490313515759_0009 with final state: FINISHING
2017-03-23 20:51:33,208 INFO org.apache.hadoop.yarn.server.resourcemanager.rmapp.RMAppImpl: application_1490313515759_0009 State change from RUNNING to FINAL_SAVING
2017-03-23 20:51:33,208 INFO org.apache.hadoop.yarn.server.resourcemanager.recovery.RMStateStore: Updating info for app: application_1490313515759_0009
2017-03-23 20:51:33,209 INFO org.apache.hadoop.yarn.server.resourcemanager.rmapp.attempt.RMAppAttemptImpl: appattempt_1490313515759_0009_000001 State change from FINAL_SAVING to FINISHING
2017-03-23 20:51:33,209 INFO org.apache.hadoop.yarn.server.resourcemanager.rmapp.RMAppImpl: application_1490313515759_0009 State change from FINAL_SAVING to FINISHING
2017-03-23 20:51:33,843 INFO org.apache.hadoop.yarn.server.resourcemanager.rmcontainer.RMContainerImpl: container_1490313515759_0009_01_000004 Container Transitioned from RUNNING to COMPLETED
2017-03-23 20:51:33,843 INFO org.apache.hadoop.yarn.server.resourcemanager.scheduler.common.fica.FiCaSchedulerApp: Completed container: container_1490313515759_0009_01_000004 in state: COMPLETED event:FINISHED
2017-03-23 20:51:33,843 INFO org.apache.hadoop.yarn.server.resourcemanager.RMAuditLogger: USER=root	OPERATION=AM Released Container	TARGET=SchedulerApp	RESULT=SUCCESS	APPID=application_1490313515759_0009	CONTAINERID=container_1490313515759_0009_01_000004
2017-03-23 20:51:33,844 INFO org.apache.hadoop.yarn.server.resourcemanager.scheduler.SchedulerNode: Released container container_1490313515759_0009_01_000004 of capacity <memory:1024, vCores:1> on host 240008d2487e:44869, which currently has 1 containers, <memory:2048, vCores:1> used and <memory:6144, vCores:7> available, release resources=true
2017-03-23 20:51:33,844 INFO org.apache.hadoop.yarn.server.resourcemanager.scheduler.capacity.LeafQueue: default used=<memory:2048, vCores:1> numContainers=1 user=root user-resources=<memory:2048, vCores:1>
2017-03-23 20:51:33,844 INFO org.apache.hadoop.yarn.server.resourcemanager.scheduler.capacity.LeafQueue: completedContainer container=Container: [ContainerId: container_1490313515759_0009_01_000004, NodeId: 240008d2487e:44869, NodeHttpAddress: 240008d2487e:8042, Resource: <memory:1024, vCores:1>, Priority: 10, Token: Token { kind: ContainerToken, service: 172.18.0.2:44869 }, ] queue=default: capacity=1.0, absoluteCapacity=1.0, usedResources=<memory:2048, vCores:1>, usedCapacity=0.25, absoluteUsedCapacity=0.25, numApps=1, numContainers=1 cluster=<memory:8192, vCores:8>
2017-03-23 20:51:33,844 INFO org.apache.hadoop.yarn.server.resourcemanager.scheduler.capacity.ParentQueue: completedContainer queue=root usedCapacity=0.25 absoluteUsedCapacity=0.25 used=<memory:2048, vCores:1> cluster=<memory:8192, vCores:8>
2017-03-23 20:51:33,844 INFO org.apache.hadoop.yarn.server.resourcemanager.scheduler.capacity.ParentQueue: Re-sorting completed queue: root.default stats: default: capacity=1.0, absoluteCapacity=1.0, usedResources=<memory:2048, vCores:1>, usedCapacity=0.25, absoluteUsedCapacity=0.25, numApps=1, numContainers=1
2017-03-23 20:51:33,844 INFO org.apache.hadoop.yarn.server.resourcemanager.scheduler.capacity.CapacityScheduler: Application attempt appattempt_1490313515759_0009_000001 released container container_1490313515759_0009_01_000004 on node: host: 240008d2487e:44869 #containers=1 available=<memory:6144, vCores:7> used=<memory:2048, vCores:1> with event: FINISHED
2017-03-23 20:51:34,211 INFO org.apache.hadoop.yarn.server.resourcemanager.ApplicationMasterService: application_1490313515759_0009 unregistered successfully. 
2017-03-23 20:51:39,859 INFO org.apache.hadoop.yarn.server.resourcemanager.rmcontainer.RMContainerImpl: container_1490313515759_0009_01_000001 Container Transitioned from RUNNING to COMPLETED
2017-03-23 20:51:39,860 INFO org.apache.hadoop.yarn.server.resourcemanager.ApplicationMasterService: Unregistering app attempt : appattempt_1490313515759_0009_000001
2017-03-23 20:51:39,860 INFO org.apache.hadoop.yarn.server.resourcemanager.scheduler.common.fica.FiCaSchedulerApp: Completed container: container_1490313515759_0009_01_000001 in state: COMPLETED event:FINISHED
2017-03-23 20:51:39,860 INFO org.apache.hadoop.yarn.server.resourcemanager.security.AMRMTokenSecretManager: Application finished, removing password for appattempt_1490313515759_0009_000001
2017-03-23 20:51:39,860 INFO org.apache.hadoop.yarn.server.resourcemanager.RMAuditLogger: USER=root	OPERATION=AM Released Container	TARGET=SchedulerApp	RESULT=SUCCESS	APPID=application_1490313515759_0009	CONTAINERID=container_1490313515759_0009_01_000001
2017-03-23 20:51:39,860 INFO org.apache.hadoop.yarn.server.resourcemanager.rmapp.attempt.RMAppAttemptImpl: appattempt_1490313515759_0009_000001 State change from FINISHING to FINISHED
2017-03-23 20:51:39,860 INFO org.apache.hadoop.yarn.server.resourcemanager.scheduler.SchedulerNode: Released container container_1490313515759_0009_01_000001 of capacity <memory:2048, vCores:1> on host 240008d2487e:44869, which currently has 0 containers, <memory:0, vCores:0> used and <memory:8192, vCores:8> available, release resources=true
2017-03-23 20:51:39,860 INFO org.apache.hadoop.yarn.server.resourcemanager.rmapp.RMAppImpl: application_1490313515759_0009 State change from FINISHING to FINISHED
2017-03-23 20:51:39,860 INFO org.apache.hadoop.yarn.server.resourcemanager.scheduler.capacity.LeafQueue: default used=<memory:0, vCores:0> numContainers=0 user=root user-resources=<memory:0, vCores:0>
2017-03-23 20:51:39,860 INFO org.apache.hadoop.yarn.server.resourcemanager.RMAuditLogger: USER=root	OPERATION=Application Finished - Succeeded	TARGET=RMAppManager	RESULT=SUCCESS	APPID=application_1490313515759_0009
2017-03-23 20:51:39,860 INFO org.apache.hadoop.yarn.server.resourcemanager.scheduler.capacity.LeafQueue: completedContainer container=Container: [ContainerId: container_1490313515759_0009_01_000001, NodeId: 240008d2487e:44869, NodeHttpAddress: 240008d2487e:8042, Resource: <memory:2048, vCores:1>, Priority: 0, Token: Token { kind: ContainerToken, service: 172.18.0.2:44869 }, ] queue=default: capacity=1.0, absoluteCapacity=1.0, usedResources=<memory:0, vCores:0>, usedCapacity=0.0, absoluteUsedCapacity=0.0, numApps=1, numContainers=0 cluster=<memory:8192, vCores:8>
2017-03-23 20:51:39,860 INFO org.apache.hadoop.yarn.server.resourcemanager.scheduler.capacity.ParentQueue: completedContainer queue=root usedCapacity=0.0 absoluteUsedCapacity=0.0 used=<memory:0, vCores:0> cluster=<memory:8192, vCores:8>
2017-03-23 20:51:39,860 INFO org.apache.hadoop.yarn.server.resourcemanager.scheduler.capacity.ParentQueue: Re-sorting completed queue: root.default stats: default: capacity=1.0, absoluteCapacity=1.0, usedResources=<memory:0, vCores:0>, usedCapacity=0.0, absoluteUsedCapacity=0.0, numApps=1, numContainers=0
2017-03-23 20:51:39,861 INFO org.apache.hadoop.yarn.server.resourcemanager.scheduler.capacity.CapacityScheduler: Application attempt appattempt_1490313515759_0009_000001 released container container_1490313515759_0009_01_000001 on node: host: 240008d2487e:44869 #containers=0 available=<memory:8192, vCores:8> used=<memory:0, vCores:0> with event: FINISHED
2017-03-23 20:51:39,861 INFO org.apache.hadoop.yarn.server.resourcemanager.scheduler.capacity.CapacityScheduler: Application Attempt appattempt_1490313515759_0009_000001 is done. finalState=FINISHED
2017-03-23 20:51:39,861 INFO org.apache.hadoop.yarn.server.resourcemanager.RMAppManager$ApplicationSummary: appId=application_1490313515759_0009,name=streamjob6901942578323226916.jar,user=root,queue=default,state=FINISHED,trackingUrl=http://240008d2487e:8088/proxy/application_1490313515759_0009/,appMasterHost=240008d2487e,startTime=1490316639085,finishTime=1490316693208,finalStatus=SUCCEEDED,memorySeconds=157518,vcoreSeconds=101,preemptedAMContainers=0,preemptedNonAMContainers=0,preemptedResources=<memory:0\, vCores:0>,applicationType=MAPREDUCE
2017-03-23 20:51:39,861 INFO org.apache.hadoop.yarn.server.resourcemanager.scheduler.AppSchedulingInfo: Application application_1490313515759_0009 requests cleared
2017-03-23 20:51:39,862 INFO org.apache.hadoop.yarn.server.resourcemanager.scheduler.capacity.LeafQueue: Application removed - appId: application_1490313515759_0009 user: root queue: default #user-pending-applications: 0 #user-active-applications: 0 #queue-pending-applications: 0 #queue-active-applications: 0
2017-03-23 20:51:39,862 INFO org.apache.hadoop.yarn.server.resourcemanager.amlauncher.AMLauncher: Cleaning master appattempt_1490313515759_0009_000001
2017-03-23 20:51:39,862 INFO org.apache.hadoop.yarn.server.resourcemanager.scheduler.capacity.ParentQueue: Application removed - appId: application_1490313515759_0009 user: root leaf-queue of parent: root #applications: 0
2017-03-23 20:51:40,879 INFO org.apache.hadoop.yarn.server.resourcemanager.scheduler.capacity.CapacityScheduler: Null container completed...
2017-03-23 20:52:55,210 INFO org.apache.hadoop.yarn.server.resourcemanager.ClientRMService: Allocated new applicationId: 10
2017-03-23 20:52:56,985 INFO org.apache.hadoop.yarn.server.resourcemanager.ClientRMService: Application with id 10 submitted by user root
2017-03-23 20:52:56,985 INFO org.apache.hadoop.yarn.server.resourcemanager.RMAuditLogger: USER=root	IP=172.18.0.2	OPERATION=Submit Application Request	TARGET=ClientRMService	RESULT=SUCCESS	APPID=application_1490313515759_0010
2017-03-23 20:52:56,986 INFO org.apache.hadoop.yarn.server.resourcemanager.rmapp.RMAppImpl: Storing application with id application_1490313515759_0010
2017-03-23 20:52:56,986 INFO org.apache.hadoop.yarn.server.resourcemanager.rmapp.RMAppImpl: application_1490313515759_0010 State change from NEW to NEW_SAVING
2017-03-23 20:52:56,986 INFO org.apache.hadoop.yarn.server.resourcemanager.recovery.RMStateStore: Storing info for app: application_1490313515759_0010
2017-03-23 20:52:56,986 INFO org.apache.hadoop.yarn.server.resourcemanager.rmapp.RMAppImpl: application_1490313515759_0010 State change from NEW_SAVING to SUBMITTED
2017-03-23 20:52:56,987 INFO org.apache.hadoop.yarn.server.resourcemanager.scheduler.capacity.ParentQueue: Application added - appId: application_1490313515759_0010 user: root leaf-queue of parent: root #applications: 1
2017-03-23 20:52:56,987 INFO org.apache.hadoop.yarn.server.resourcemanager.scheduler.capacity.CapacityScheduler: Accepted application application_1490313515759_0010 from user: root, in queue: default
2017-03-23 20:52:56,988 INFO org.apache.hadoop.yarn.server.resourcemanager.rmapp.RMAppImpl: application_1490313515759_0010 State change from SUBMITTED to ACCEPTED
2017-03-23 20:52:56,988 INFO org.apache.hadoop.yarn.server.resourcemanager.ApplicationMasterService: Registering app attempt : appattempt_1490313515759_0010_000001
2017-03-23 20:52:56,988 INFO org.apache.hadoop.yarn.server.resourcemanager.rmapp.attempt.RMAppAttemptImpl: appattempt_1490313515759_0010_000001 State change from NEW to SUBMITTED
2017-03-23 20:52:56,988 WARN org.apache.hadoop.yarn.server.resourcemanager.scheduler.capacity.LeafQueue: maximum-am-resource-percent is insufficient to start a single application in queue, it is likely set too low. skipping enforcement to allow at least one application to start
2017-03-23 20:52:56,988 WARN org.apache.hadoop.yarn.server.resourcemanager.scheduler.capacity.LeafQueue: maximum-am-resource-percent is insufficient to start a single application in queue for user, it is likely set too low. skipping enforcement to allow at least one application to start
2017-03-23 20:52:56,989 INFO org.apache.hadoop.yarn.server.resourcemanager.scheduler.capacity.LeafQueue: Application application_1490313515759_0010 from user: root activated in queue: default
2017-03-23 20:52:56,989 INFO org.apache.hadoop.yarn.server.resourcemanager.scheduler.capacity.LeafQueue: Application added - appId: application_1490313515759_0010 user: org.apache.hadoop.yarn.server.resourcemanager.scheduler.capacity.LeafQueue$User@f6cf123, leaf-queue: default #user-pending-applications: 0 #user-active-applications: 1 #queue-pending-applications: 0 #queue-active-applications: 1
2017-03-23 20:52:56,989 INFO org.apache.hadoop.yarn.server.resourcemanager.scheduler.capacity.CapacityScheduler: Added Application Attempt appattempt_1490313515759_0010_000001 to scheduler from user root in queue default
2017-03-23 20:52:56,990 INFO org.apache.hadoop.yarn.server.resourcemanager.rmapp.attempt.RMAppAttemptImpl: appattempt_1490313515759_0010_000001 State change from SUBMITTED to SCHEDULED
2017-03-23 20:52:57,062 INFO org.apache.hadoop.yarn.server.resourcemanager.rmcontainer.RMContainerImpl: container_1490313515759_0010_01_000001 Container Transitioned from NEW to ALLOCATED
2017-03-23 20:52:57,062 INFO org.apache.hadoop.yarn.server.resourcemanager.RMAuditLogger: USER=root	OPERATION=AM Allocated Container	TARGET=SchedulerApp	RESULT=SUCCESS	APPID=application_1490313515759_0010	CONTAINERID=container_1490313515759_0010_01_000001
2017-03-23 20:52:57,062 INFO org.apache.hadoop.yarn.server.resourcemanager.scheduler.SchedulerNode: Assigned container container_1490313515759_0010_01_000001 of capacity <memory:2048, vCores:1> on host 240008d2487e:44869, which has 1 containers, <memory:2048, vCores:1> used and <memory:6144, vCores:7> available after allocation
2017-03-23 20:52:57,062 INFO org.apache.hadoop.yarn.server.resourcemanager.scheduler.capacity.LeafQueue: assignedContainer application attempt=appattempt_1490313515759_0010_000001 container=Container: [ContainerId: container_1490313515759_0010_01_000001, NodeId: 240008d2487e:44869, NodeHttpAddress: 240008d2487e:8042, Resource: <memory:2048, vCores:1>, Priority: 0, Token: null, ] queue=default: capacity=1.0, absoluteCapacity=1.0, usedResources=<memory:0, vCores:0>, usedCapacity=0.0, absoluteUsedCapacity=0.0, numApps=1, numContainers=0 clusterResource=<memory:8192, vCores:8>
2017-03-23 20:52:57,063 INFO org.apache.hadoop.yarn.server.resourcemanager.scheduler.capacity.ParentQueue: Re-sorting assigned queue: root.default stats: default: capacity=1.0, absoluteCapacity=1.0, usedResources=<memory:2048, vCores:1>, usedCapacity=0.25, absoluteUsedCapacity=0.25, numApps=1, numContainers=1
2017-03-23 20:52:57,063 INFO org.apache.hadoop.yarn.server.resourcemanager.scheduler.capacity.ParentQueue: assignedContainer queue=root usedCapacity=0.25 absoluteUsedCapacity=0.25 used=<memory:2048, vCores:1> cluster=<memory:8192, vCores:8>
2017-03-23 20:52:57,064 INFO org.apache.hadoop.yarn.server.resourcemanager.security.NMTokenSecretManagerInRM: Sending NMToken for nodeId : 240008d2487e:44869 for container : container_1490313515759_0010_01_000001
2017-03-23 20:52:57,066 INFO org.apache.hadoop.yarn.server.resourcemanager.rmcontainer.RMContainerImpl: container_1490313515759_0010_01_000001 Container Transitioned from ALLOCATED to ACQUIRED
2017-03-23 20:52:57,066 INFO org.apache.hadoop.yarn.server.resourcemanager.security.NMTokenSecretManagerInRM: Clear node set for appattempt_1490313515759_0010_000001
2017-03-23 20:52:57,066 INFO org.apache.hadoop.yarn.server.resourcemanager.rmapp.attempt.RMAppAttemptImpl: Storing attempt: AppId: application_1490313515759_0010 AttemptId: appattempt_1490313515759_0010_000001 MasterContainer: Container: [ContainerId: container_1490313515759_0010_01_000001, NodeId: 240008d2487e:44869, NodeHttpAddress: 240008d2487e:8042, Resource: <memory:2048, vCores:1>, Priority: 0, Token: Token { kind: ContainerToken, service: 172.18.0.2:44869 }, ]
2017-03-23 20:52:57,066 INFO org.apache.hadoop.yarn.server.resourcemanager.rmapp.attempt.RMAppAttemptImpl: appattempt_1490313515759_0010_000001 State change from SCHEDULED to ALLOCATED_SAVING
2017-03-23 20:52:57,067 INFO org.apache.hadoop.yarn.server.resourcemanager.rmapp.attempt.RMAppAttemptImpl: appattempt_1490313515759_0010_000001 State change from ALLOCATED_SAVING to ALLOCATED
2017-03-23 20:52:57,067 INFO org.apache.hadoop.yarn.server.resourcemanager.amlauncher.AMLauncher: Launching masterappattempt_1490313515759_0010_000001
2017-03-23 20:52:57,070 INFO org.apache.hadoop.yarn.server.resourcemanager.amlauncher.AMLauncher: Setting up container Container: [ContainerId: container_1490313515759_0010_01_000001, NodeId: 240008d2487e:44869, NodeHttpAddress: 240008d2487e:8042, Resource: <memory:2048, vCores:1>, Priority: 0, Token: Token { kind: ContainerToken, service: 172.18.0.2:44869 }, ] for AM appattempt_1490313515759_0010_000001
2017-03-23 20:52:57,070 INFO org.apache.hadoop.yarn.server.resourcemanager.amlauncher.AMLauncher: Command to launch container container_1490313515759_0010_01_000001 : $JAVA_HOME/bin/java -Dlog4j.configuration=container-log4j.properties -Dyarn.app.container.log.dir=<LOG_DIR> -Dyarn.app.container.log.filesize=0 -Dhadoop.root.logger=INFO,CLA -Dhadoop.root.logfile=syslog  -Xmx1024m org.apache.hadoop.mapreduce.v2.app.MRAppMaster 1><LOG_DIR>/stdout 2><LOG_DIR>/stderr 
2017-03-23 20:52:57,071 INFO org.apache.hadoop.yarn.server.resourcemanager.security.AMRMTokenSecretManager: Create AMRMToken for ApplicationAttempt: appattempt_1490313515759_0010_000001
2017-03-23 20:52:57,071 INFO org.apache.hadoop.yarn.server.resourcemanager.security.AMRMTokenSecretManager: Creating password for appattempt_1490313515759_0010_000001
2017-03-23 20:52:57,082 INFO org.apache.hadoop.yarn.server.resourcemanager.amlauncher.AMLauncher: Done launching container Container: [ContainerId: container_1490313515759_0010_01_000001, NodeId: 240008d2487e:44869, NodeHttpAddress: 240008d2487e:8042, Resource: <memory:2048, vCores:1>, Priority: 0, Token: Token { kind: ContainerToken, service: 172.18.0.2:44869 }, ] for AM appattempt_1490313515759_0010_000001
2017-03-23 20:52:57,082 INFO org.apache.hadoop.yarn.server.resourcemanager.rmapp.attempt.RMAppAttemptImpl: appattempt_1490313515759_0010_000001 State change from ALLOCATED to LAUNCHED
2017-03-23 20:52:58,065 INFO org.apache.hadoop.yarn.server.resourcemanager.rmcontainer.RMContainerImpl: container_1490313515759_0010_01_000001 Container Transitioned from ACQUIRED to RUNNING
2017-03-23 20:53:02,000 INFO SecurityLogger.org.apache.hadoop.ipc.Server: Auth successful for appattempt_1490313515759_0010_000001 (auth:SIMPLE)
2017-03-23 20:53:02,004 INFO org.apache.hadoop.yarn.server.resourcemanager.ApplicationMasterService: AM registration appattempt_1490313515759_0010_000001
2017-03-23 20:53:02,005 INFO org.apache.hadoop.yarn.server.resourcemanager.RMAuditLogger: USER=root	IP=172.18.0.2	OPERATION=Register App Master	TARGET=ApplicationMasterService	RESULT=SUCCESS	APPID=application_1490313515759_0010	APPATTEMPTID=appattempt_1490313515759_0010_000001
2017-03-23 20:53:02,005 INFO org.apache.hadoop.yarn.server.resourcemanager.rmapp.attempt.RMAppAttemptImpl: appattempt_1490313515759_0010_000001 State change from LAUNCHED to RUNNING
2017-03-23 20:53:02,005 INFO org.apache.hadoop.yarn.server.resourcemanager.rmapp.RMAppImpl: application_1490313515759_0010 State change from ACCEPTED to RUNNING
2017-03-23 20:53:03,077 INFO org.apache.hadoop.yarn.server.resourcemanager.rmcontainer.RMContainerImpl: container_1490313515759_0010_01_000002 Container Transitioned from NEW to ALLOCATED
2017-03-23 20:53:03,077 INFO org.apache.hadoop.yarn.server.resourcemanager.RMAuditLogger: USER=root	OPERATION=AM Allocated Container	TARGET=SchedulerApp	RESULT=SUCCESS	APPID=application_1490313515759_0010	CONTAINERID=container_1490313515759_0010_01_000002
2017-03-23 20:53:03,077 INFO org.apache.hadoop.yarn.server.resourcemanager.scheduler.SchedulerNode: Assigned container container_1490313515759_0010_01_000002 of capacity <memory:1024, vCores:1> on host 240008d2487e:44869, which has 2 containers, <memory:3072, vCores:2> used and <memory:5120, vCores:6> available after allocation
2017-03-23 20:53:03,078 INFO org.apache.hadoop.yarn.server.resourcemanager.scheduler.capacity.LeafQueue: assignedContainer application attempt=appattempt_1490313515759_0010_000001 container=Container: [ContainerId: container_1490313515759_0010_01_000002, NodeId: 240008d2487e:44869, NodeHttpAddress: 240008d2487e:8042, Resource: <memory:1024, vCores:1>, Priority: 20, Token: null, ] queue=default: capacity=1.0, absoluteCapacity=1.0, usedResources=<memory:2048, vCores:1>, usedCapacity=0.25, absoluteUsedCapacity=0.25, numApps=1, numContainers=1 clusterResource=<memory:8192, vCores:8>
2017-03-23 20:53:03,078 INFO org.apache.hadoop.yarn.server.resourcemanager.scheduler.capacity.ParentQueue: Re-sorting assigned queue: root.default stats: default: capacity=1.0, absoluteCapacity=1.0, usedResources=<memory:3072, vCores:2>, usedCapacity=0.375, absoluteUsedCapacity=0.375, numApps=1, numContainers=2
2017-03-23 20:53:03,078 INFO org.apache.hadoop.yarn.server.resourcemanager.scheduler.capacity.ParentQueue: assignedContainer queue=root usedCapacity=0.375 absoluteUsedCapacity=0.375 used=<memory:3072, vCores:2> cluster=<memory:8192, vCores:8>
2017-03-23 20:53:03,078 INFO org.apache.hadoop.yarn.server.resourcemanager.rmcontainer.RMContainerImpl: container_1490313515759_0010_01_000003 Container Transitioned from NEW to ALLOCATED
2017-03-23 20:53:03,078 INFO org.apache.hadoop.yarn.server.resourcemanager.RMAuditLogger: USER=root	OPERATION=AM Allocated Container	TARGET=SchedulerApp	RESULT=SUCCESS	APPID=application_1490313515759_0010	CONTAINERID=container_1490313515759_0010_01_000003
2017-03-23 20:53:03,078 INFO org.apache.hadoop.yarn.server.resourcemanager.scheduler.SchedulerNode: Assigned container container_1490313515759_0010_01_000003 of capacity <memory:1024, vCores:1> on host 240008d2487e:44869, which has 3 containers, <memory:4096, vCores:3> used and <memory:4096, vCores:5> available after allocation
2017-03-23 20:53:03,079 INFO org.apache.hadoop.yarn.server.resourcemanager.scheduler.capacity.LeafQueue: assignedContainer application attempt=appattempt_1490313515759_0010_000001 container=Container: [ContainerId: container_1490313515759_0010_01_000003, NodeId: 240008d2487e:44869, NodeHttpAddress: 240008d2487e:8042, Resource: <memory:1024, vCores:1>, Priority: 20, Token: null, ] queue=default: capacity=1.0, absoluteCapacity=1.0, usedResources=<memory:3072, vCores:2>, usedCapacity=0.375, absoluteUsedCapacity=0.375, numApps=1, numContainers=2 clusterResource=<memory:8192, vCores:8>
2017-03-23 20:53:03,079 INFO org.apache.hadoop.yarn.server.resourcemanager.scheduler.capacity.ParentQueue: Re-sorting assigned queue: root.default stats: default: capacity=1.0, absoluteCapacity=1.0, usedResources=<memory:4096, vCores:3>, usedCapacity=0.5, absoluteUsedCapacity=0.5, numApps=1, numContainers=3
2017-03-23 20:53:03,079 INFO org.apache.hadoop.yarn.server.resourcemanager.scheduler.capacity.ParentQueue: assignedContainer queue=root usedCapacity=0.5 absoluteUsedCapacity=0.5 used=<memory:4096, vCores:3> cluster=<memory:8192, vCores:8>
2017-03-23 20:53:04,098 INFO org.apache.hadoop.yarn.server.resourcemanager.security.NMTokenSecretManagerInRM: Sending NMToken for nodeId : 240008d2487e:44869 for container : container_1490313515759_0010_01_000002
2017-03-23 20:53:04,102 INFO org.apache.hadoop.yarn.server.resourcemanager.rmcontainer.RMContainerImpl: container_1490313515759_0010_01_000002 Container Transitioned from ALLOCATED to ACQUIRED
2017-03-23 20:53:04,103 INFO org.apache.hadoop.yarn.server.resourcemanager.rmcontainer.RMContainerImpl: container_1490313515759_0010_01_000003 Container Transitioned from ALLOCATED to ACQUIRED
2017-03-23 20:53:05,082 INFO org.apache.hadoop.yarn.server.resourcemanager.rmcontainer.RMContainerImpl: container_1490313515759_0010_01_000002 Container Transitioned from ACQUIRED to RUNNING
2017-03-23 20:53:05,082 INFO org.apache.hadoop.yarn.server.resourcemanager.rmcontainer.RMContainerImpl: container_1490313515759_0010_01_000003 Container Transitioned from ACQUIRED to RUNNING
2017-03-23 20:53:05,119 INFO org.apache.hadoop.yarn.server.resourcemanager.scheduler.AppSchedulingInfo: checking for deactivate of application :application_1490313515759_0010
2017-03-23 20:53:18,830 INFO org.apache.hadoop.yarn.server.resourcemanager.rmcontainer.RMContainerImpl: container_1490313515759_0010_01_000003 Container Transitioned from RUNNING to COMPLETED
2017-03-23 20:53:18,830 INFO org.apache.hadoop.yarn.server.resourcemanager.scheduler.common.fica.FiCaSchedulerApp: Completed container: container_1490313515759_0010_01_000003 in state: COMPLETED event:FINISHED
2017-03-23 20:53:18,830 INFO org.apache.hadoop.yarn.server.resourcemanager.RMAuditLogger: USER=root	OPERATION=AM Released Container	TARGET=SchedulerApp	RESULT=SUCCESS	APPID=application_1490313515759_0010	CONTAINERID=container_1490313515759_0010_01_000003
2017-03-23 20:53:18,830 INFO org.apache.hadoop.yarn.server.resourcemanager.scheduler.SchedulerNode: Released container container_1490313515759_0010_01_000003 of capacity <memory:1024, vCores:1> on host 240008d2487e:44869, which currently has 2 containers, <memory:3072, vCores:2> used and <memory:5120, vCores:6> available, release resources=true
2017-03-23 20:53:18,830 INFO org.apache.hadoop.yarn.server.resourcemanager.scheduler.capacity.LeafQueue: default used=<memory:3072, vCores:2> numContainers=2 user=root user-resources=<memory:3072, vCores:2>
2017-03-23 20:53:18,831 INFO org.apache.hadoop.yarn.server.resourcemanager.scheduler.capacity.LeafQueue: completedContainer container=Container: [ContainerId: container_1490313515759_0010_01_000003, NodeId: 240008d2487e:44869, NodeHttpAddress: 240008d2487e:8042, Resource: <memory:1024, vCores:1>, Priority: 20, Token: Token { kind: ContainerToken, service: 172.18.0.2:44869 }, ] queue=default: capacity=1.0, absoluteCapacity=1.0, usedResources=<memory:3072, vCores:2>, usedCapacity=0.375, absoluteUsedCapacity=0.375, numApps=1, numContainers=2 cluster=<memory:8192, vCores:8>
2017-03-23 20:53:18,831 INFO org.apache.hadoop.yarn.server.resourcemanager.scheduler.capacity.ParentQueue: completedContainer queue=root usedCapacity=0.375 absoluteUsedCapacity=0.375 used=<memory:3072, vCores:2> cluster=<memory:8192, vCores:8>
2017-03-23 20:53:18,831 INFO org.apache.hadoop.yarn.server.resourcemanager.scheduler.capacity.ParentQueue: Re-sorting completed queue: root.default stats: default: capacity=1.0, absoluteCapacity=1.0, usedResources=<memory:3072, vCores:2>, usedCapacity=0.375, absoluteUsedCapacity=0.375, numApps=1, numContainers=2
2017-03-23 20:53:18,831 INFO org.apache.hadoop.yarn.server.resourcemanager.scheduler.capacity.CapacityScheduler: Application attempt appattempt_1490313515759_0010_000001 released container container_1490313515759_0010_01_000003 on node: host: 240008d2487e:44869 #containers=2 available=<memory:5120, vCores:6> used=<memory:3072, vCores:2> with event: FINISHED
2017-03-23 20:53:18,831 INFO org.apache.hadoop.yarn.server.resourcemanager.rmcontainer.RMContainerImpl: container_1490313515759_0010_01_000002 Container Transitioned from RUNNING to COMPLETED
2017-03-23 20:53:18,832 INFO org.apache.hadoop.yarn.server.resourcemanager.scheduler.common.fica.FiCaSchedulerApp: Completed container: container_1490313515759_0010_01_000002 in state: COMPLETED event:FINISHED
2017-03-23 20:53:18,832 INFO org.apache.hadoop.yarn.server.resourcemanager.RMAuditLogger: USER=root	OPERATION=AM Released Container	TARGET=SchedulerApp	RESULT=SUCCESS	APPID=application_1490313515759_0010	CONTAINERID=container_1490313515759_0010_01_000002
2017-03-23 20:53:18,832 INFO org.apache.hadoop.yarn.server.resourcemanager.scheduler.SchedulerNode: Released container container_1490313515759_0010_01_000002 of capacity <memory:1024, vCores:1> on host 240008d2487e:44869, which currently has 1 containers, <memory:2048, vCores:1> used and <memory:6144, vCores:7> available, release resources=true
2017-03-23 20:53:18,832 INFO org.apache.hadoop.yarn.server.resourcemanager.scheduler.capacity.LeafQueue: default used=<memory:2048, vCores:1> numContainers=1 user=root user-resources=<memory:2048, vCores:1>
2017-03-23 20:53:18,832 INFO org.apache.hadoop.yarn.server.resourcemanager.scheduler.capacity.LeafQueue: completedContainer container=Container: [ContainerId: container_1490313515759_0010_01_000002, NodeId: 240008d2487e:44869, NodeHttpAddress: 240008d2487e:8042, Resource: <memory:1024, vCores:1>, Priority: 20, Token: Token { kind: ContainerToken, service: 172.18.0.2:44869 }, ] queue=default: capacity=1.0, absoluteCapacity=1.0, usedResources=<memory:2048, vCores:1>, usedCapacity=0.25, absoluteUsedCapacity=0.25, numApps=1, numContainers=1 cluster=<memory:8192, vCores:8>
2017-03-23 20:53:18,832 INFO org.apache.hadoop.yarn.server.resourcemanager.scheduler.capacity.ParentQueue: completedContainer queue=root usedCapacity=0.25 absoluteUsedCapacity=0.25 used=<memory:2048, vCores:1> cluster=<memory:8192, vCores:8>
2017-03-23 20:53:18,832 INFO org.apache.hadoop.yarn.server.resourcemanager.scheduler.capacity.ParentQueue: Re-sorting completed queue: root.default stats: default: capacity=1.0, absoluteCapacity=1.0, usedResources=<memory:2048, vCores:1>, usedCapacity=0.25, absoluteUsedCapacity=0.25, numApps=1, numContainers=1
2017-03-23 20:53:18,833 INFO org.apache.hadoop.yarn.server.resourcemanager.scheduler.capacity.CapacityScheduler: Application attempt appattempt_1490313515759_0010_000001 released container container_1490313515759_0010_01_000002 on node: host: 240008d2487e:44869 #containers=1 available=<memory:6144, vCores:7> used=<memory:2048, vCores:1> with event: FINISHED
2017-03-23 20:53:19,837 INFO org.apache.hadoop.yarn.server.resourcemanager.rmcontainer.RMContainerImpl: container_1490313515759_0010_01_000004 Container Transitioned from NEW to ALLOCATED
2017-03-23 20:53:19,837 INFO org.apache.hadoop.yarn.server.resourcemanager.RMAuditLogger: USER=root	OPERATION=AM Allocated Container	TARGET=SchedulerApp	RESULT=SUCCESS	APPID=application_1490313515759_0010	CONTAINERID=container_1490313515759_0010_01_000004
2017-03-23 20:53:19,837 INFO org.apache.hadoop.yarn.server.resourcemanager.scheduler.SchedulerNode: Assigned container container_1490313515759_0010_01_000004 of capacity <memory:1024, vCores:1> on host 240008d2487e:44869, which has 2 containers, <memory:3072, vCores:2> used and <memory:5120, vCores:6> available after allocation
2017-03-23 20:53:19,837 INFO org.apache.hadoop.yarn.server.resourcemanager.scheduler.capacity.LeafQueue: assignedContainer application attempt=appattempt_1490313515759_0010_000001 container=Container: [ContainerId: container_1490313515759_0010_01_000004, NodeId: 240008d2487e:44869, NodeHttpAddress: 240008d2487e:8042, Resource: <memory:1024, vCores:1>, Priority: 10, Token: null, ] queue=default: capacity=1.0, absoluteCapacity=1.0, usedResources=<memory:2048, vCores:1>, usedCapacity=0.25, absoluteUsedCapacity=0.25, numApps=1, numContainers=1 clusterResource=<memory:8192, vCores:8>
2017-03-23 20:53:19,838 INFO org.apache.hadoop.yarn.server.resourcemanager.scheduler.capacity.ParentQueue: Re-sorting assigned queue: root.default stats: default: capacity=1.0, absoluteCapacity=1.0, usedResources=<memory:3072, vCores:2>, usedCapacity=0.375, absoluteUsedCapacity=0.375, numApps=1, numContainers=2
2017-03-23 20:53:19,838 INFO org.apache.hadoop.yarn.server.resourcemanager.scheduler.capacity.ParentQueue: assignedContainer queue=root usedCapacity=0.375 absoluteUsedCapacity=0.375 used=<memory:3072, vCores:2> cluster=<memory:8192, vCores:8>
2017-03-23 20:53:20,173 INFO org.apache.hadoop.yarn.server.resourcemanager.rmcontainer.RMContainerImpl: container_1490313515759_0010_01_000004 Container Transitioned from ALLOCATED to ACQUIRED
2017-03-23 20:53:20,836 INFO org.apache.hadoop.yarn.server.resourcemanager.rmcontainer.RMContainerImpl: container_1490313515759_0010_01_000004 Container Transitioned from ACQUIRED to RUNNING
2017-03-23 20:53:21,179 INFO org.apache.hadoop.yarn.server.resourcemanager.scheduler.AppSchedulingInfo: checking for deactivate of application :application_1490313515759_0010
2017-03-23 20:53:42,469 INFO org.apache.hadoop.yarn.server.resourcemanager.rmapp.attempt.RMAppAttemptImpl: Updating application attempt appattempt_1490313515759_0010_000001 with final state: FINISHING, and exit status: -1000
2017-03-23 20:53:42,469 INFO org.apache.hadoop.yarn.server.resourcemanager.rmapp.attempt.RMAppAttemptImpl: appattempt_1490313515759_0010_000001 State change from RUNNING to FINAL_SAVING
2017-03-23 20:53:42,469 INFO org.apache.hadoop.yarn.server.resourcemanager.rmapp.RMAppImpl: Updating application application_1490313515759_0010 with final state: FINISHING
2017-03-23 20:53:42,469 INFO org.apache.hadoop.yarn.server.resourcemanager.rmapp.RMAppImpl: application_1490313515759_0010 State change from RUNNING to FINAL_SAVING
2017-03-23 20:53:42,469 INFO org.apache.hadoop.yarn.server.resourcemanager.recovery.RMStateStore: Updating info for app: application_1490313515759_0010
2017-03-23 20:53:42,469 INFO org.apache.hadoop.yarn.server.resourcemanager.rmapp.attempt.RMAppAttemptImpl: appattempt_1490313515759_0010_000001 State change from FINAL_SAVING to FINISHING
2017-03-23 20:53:42,469 INFO org.apache.hadoop.yarn.server.resourcemanager.rmapp.RMAppImpl: application_1490313515759_0010 State change from FINAL_SAVING to FINISHING
2017-03-23 20:53:42,719 INFO org.apache.hadoop.yarn.server.resourcemanager.rmcontainer.RMContainerImpl: container_1490313515759_0010_01_000004 Container Transitioned from RUNNING to COMPLETED
2017-03-23 20:53:42,719 INFO org.apache.hadoop.yarn.server.resourcemanager.scheduler.common.fica.FiCaSchedulerApp: Completed container: container_1490313515759_0010_01_000004 in state: COMPLETED event:FINISHED
2017-03-23 20:53:42,719 INFO org.apache.hadoop.yarn.server.resourcemanager.RMAuditLogger: USER=root	OPERATION=AM Released Container	TARGET=SchedulerApp	RESULT=SUCCESS	APPID=application_1490313515759_0010	CONTAINERID=container_1490313515759_0010_01_000004
2017-03-23 20:53:42,719 INFO org.apache.hadoop.yarn.server.resourcemanager.scheduler.SchedulerNode: Released container container_1490313515759_0010_01_000004 of capacity <memory:1024, vCores:1> on host 240008d2487e:44869, which currently has 1 containers, <memory:2048, vCores:1> used and <memory:6144, vCores:7> available, release resources=true
2017-03-23 20:53:42,719 INFO org.apache.hadoop.yarn.server.resourcemanager.scheduler.capacity.LeafQueue: default used=<memory:2048, vCores:1> numContainers=1 user=root user-resources=<memory:2048, vCores:1>
2017-03-23 20:53:42,720 INFO org.apache.hadoop.yarn.server.resourcemanager.scheduler.capacity.LeafQueue: completedContainer container=Container: [ContainerId: container_1490313515759_0010_01_000004, NodeId: 240008d2487e:44869, NodeHttpAddress: 240008d2487e:8042, Resource: <memory:1024, vCores:1>, Priority: 10, Token: Token { kind: ContainerToken, service: 172.18.0.2:44869 }, ] queue=default: capacity=1.0, absoluteCapacity=1.0, usedResources=<memory:2048, vCores:1>, usedCapacity=0.25, absoluteUsedCapacity=0.25, numApps=1, numContainers=1 cluster=<memory:8192, vCores:8>
2017-03-23 20:53:42,720 INFO org.apache.hadoop.yarn.server.resourcemanager.scheduler.capacity.ParentQueue: completedContainer queue=root usedCapacity=0.25 absoluteUsedCapacity=0.25 used=<memory:2048, vCores:1> cluster=<memory:8192, vCores:8>
2017-03-23 20:53:42,720 INFO org.apache.hadoop.yarn.server.resourcemanager.scheduler.capacity.ParentQueue: Re-sorting completed queue: root.default stats: default: capacity=1.0, absoluteCapacity=1.0, usedResources=<memory:2048, vCores:1>, usedCapacity=0.25, absoluteUsedCapacity=0.25, numApps=1, numContainers=1
2017-03-23 20:53:42,720 INFO org.apache.hadoop.yarn.server.resourcemanager.scheduler.capacity.CapacityScheduler: Application attempt appattempt_1490313515759_0010_000001 released container container_1490313515759_0010_01_000004 on node: host: 240008d2487e:44869 #containers=1 available=<memory:6144, vCores:7> used=<memory:2048, vCores:1> with event: FINISHED
2017-03-23 20:53:43,472 INFO org.apache.hadoop.yarn.server.resourcemanager.ApplicationMasterService: application_1490313515759_0010 unregistered successfully. 
2017-03-23 20:53:48,737 INFO org.apache.hadoop.yarn.server.resourcemanager.rmcontainer.RMContainerImpl: container_1490313515759_0010_01_000001 Container Transitioned from RUNNING to COMPLETED
2017-03-23 20:53:48,737 INFO org.apache.hadoop.yarn.server.resourcemanager.ApplicationMasterService: Unregistering app attempt : appattempt_1490313515759_0010_000001
2017-03-23 20:53:48,737 INFO org.apache.hadoop.yarn.server.resourcemanager.scheduler.common.fica.FiCaSchedulerApp: Completed container: container_1490313515759_0010_01_000001 in state: COMPLETED event:FINISHED
2017-03-23 20:53:48,737 INFO org.apache.hadoop.yarn.server.resourcemanager.security.AMRMTokenSecretManager: Application finished, removing password for appattempt_1490313515759_0010_000001
2017-03-23 20:53:48,737 INFO org.apache.hadoop.yarn.server.resourcemanager.RMAuditLogger: USER=root	OPERATION=AM Released Container	TARGET=SchedulerApp	RESULT=SUCCESS	APPID=application_1490313515759_0010	CONTAINERID=container_1490313515759_0010_01_000001
2017-03-23 20:53:48,737 INFO org.apache.hadoop.yarn.server.resourcemanager.rmapp.attempt.RMAppAttemptImpl: appattempt_1490313515759_0010_000001 State change from FINISHING to FINISHED
2017-03-23 20:53:48,737 INFO org.apache.hadoop.yarn.server.resourcemanager.scheduler.SchedulerNode: Released container container_1490313515759_0010_01_000001 of capacity <memory:2048, vCores:1> on host 240008d2487e:44869, which currently has 0 containers, <memory:0, vCores:0> used and <memory:8192, vCores:8> available, release resources=true
2017-03-23 20:53:48,737 INFO org.apache.hadoop.yarn.server.resourcemanager.rmapp.RMAppImpl: application_1490313515759_0010 State change from FINISHING to FINISHED
2017-03-23 20:53:48,738 INFO org.apache.hadoop.yarn.server.resourcemanager.scheduler.capacity.LeafQueue: default used=<memory:0, vCores:0> numContainers=0 user=root user-resources=<memory:0, vCores:0>
2017-03-23 20:53:48,738 INFO org.apache.hadoop.yarn.server.resourcemanager.RMAuditLogger: USER=root	OPERATION=Application Finished - Succeeded	TARGET=RMAppManager	RESULT=SUCCESS	APPID=application_1490313515759_0010
2017-03-23 20:53:48,738 INFO org.apache.hadoop.yarn.server.resourcemanager.scheduler.capacity.LeafQueue: completedContainer container=Container: [ContainerId: container_1490313515759_0010_01_000001, NodeId: 240008d2487e:44869, NodeHttpAddress: 240008d2487e:8042, Resource: <memory:2048, vCores:1>, Priority: 0, Token: Token { kind: ContainerToken, service: 172.18.0.2:44869 }, ] queue=default: capacity=1.0, absoluteCapacity=1.0, usedResources=<memory:0, vCores:0>, usedCapacity=0.0, absoluteUsedCapacity=0.0, numApps=1, numContainers=0 cluster=<memory:8192, vCores:8>
2017-03-23 20:53:48,738 INFO org.apache.hadoop.yarn.server.resourcemanager.scheduler.capacity.ParentQueue: completedContainer queue=root usedCapacity=0.0 absoluteUsedCapacity=0.0 used=<memory:0, vCores:0> cluster=<memory:8192, vCores:8>
2017-03-23 20:53:48,738 INFO org.apache.hadoop.yarn.server.resourcemanager.scheduler.capacity.ParentQueue: Re-sorting completed queue: root.default stats: default: capacity=1.0, absoluteCapacity=1.0, usedResources=<memory:0, vCores:0>, usedCapacity=0.0, absoluteUsedCapacity=0.0, numApps=1, numContainers=0
2017-03-23 20:53:48,738 INFO org.apache.hadoop.yarn.server.resourcemanager.scheduler.capacity.CapacityScheduler: Application attempt appattempt_1490313515759_0010_000001 released container container_1490313515759_0010_01_000001 on node: host: 240008d2487e:44869 #containers=0 available=<memory:8192, vCores:8> used=<memory:0, vCores:0> with event: FINISHED
2017-03-23 20:53:48,738 INFO org.apache.hadoop.yarn.server.resourcemanager.amlauncher.AMLauncher: Cleaning master appattempt_1490313515759_0010_000001
2017-03-23 20:53:48,739 INFO org.apache.hadoop.yarn.server.resourcemanager.RMAppManager$ApplicationSummary: appId=application_1490313515759_0010,name=streamjob4758402324940257177.jar,user=root,queue=default,state=FINISHED,trackingUrl=http://240008d2487e:8088/proxy/application_1490313515759_0010/,appMasterHost=240008d2487e,startTime=1490316776985,finishTime=1490316822469,finalStatus=SUCCEEDED,memorySeconds=161523,vcoreSeconds=103,preemptedAMContainers=0,preemptedNonAMContainers=0,preemptedResources=<memory:0\, vCores:0>,applicationType=MAPREDUCE
2017-03-23 20:53:48,738 INFO org.apache.hadoop.yarn.server.resourcemanager.scheduler.capacity.CapacityScheduler: Application Attempt appattempt_1490313515759_0010_000001 is done. finalState=FINISHED
2017-03-23 20:53:48,739 INFO org.apache.hadoop.yarn.server.resourcemanager.scheduler.AppSchedulingInfo: Application application_1490313515759_0010 requests cleared
2017-03-23 20:53:48,739 INFO org.apache.hadoop.yarn.server.resourcemanager.scheduler.capacity.LeafQueue: Application removed - appId: application_1490313515759_0010 user: root queue: default #user-pending-applications: 0 #user-active-applications: 0 #queue-pending-applications: 0 #queue-active-applications: 0
2017-03-23 20:53:48,739 INFO org.apache.hadoop.yarn.server.resourcemanager.scheduler.capacity.ParentQueue: Application removed - appId: application_1490313515759_0010 user: root leaf-queue of parent: root #applications: 0
2017-03-23 20:53:49,757 INFO org.apache.hadoop.yarn.server.resourcemanager.scheduler.capacity.CapacityScheduler: Null container completed...
